import crafttweaker.world.IFacing;
import crafttweaker.block.IBlock;
import crafttweaker.block.IBlockState;
import crafttweaker.item.IIngredient;
import crafttweaker.item.IItemStack;
import mods.gregtech.multiblock.Builder;
import mods.gregtech.multiblock.FactoryBlockPattern;
import mods.gregtech.multiblock.IBlockMatcher;
import mods.gregtech.multiblock.MultiblockAbility;
import mods.gregtech.multiblock.RelativeDirection;
import mods.gregtech.multiblock.FactoryMultiblockShapeInfo;
import mods.gregtech.multiblock.IBlockInfo;
import mods.gregtech.multiblock.IBlockWorldState;
import mods.gregtech.multiblock.Multiblock;
import mods.gregtech.recipe.RecipeMap;
import mods.gregtech.MetaTileEntities;
import mods.gregtech.recipe.FactoryRecipeMap;
import mods.gregtech.render.ITextureArea;
import mods.gregtech.render.MoveType;
import mods.gregtech.render.ICubeRenderer;
import mods.gregtech.render.Textures;
import crafttweaker.oredict.IOreDict;
import crafttweaker.oredict.IOreDictEntry;


var loc = "miracle_top";
var meta = 10048;
val miracle_top = Builder.start(loc, meta)
    .withPattern(
            FactoryBlockPattern.start(RelativeDirection.RIGHT, RelativeDirection.BACK, RelativeDirection.UP)
                .aisle(
                    "~~~~~~~~~~~~~~~~~~~~~",
                    "~~~~~~~~~CCC~~~~~~~~~",
                    "~~~~~~~~~~~~~~~~~~~~~",
                    "~~~~~~~~~~~~~~~~~~~~~",
                    "~~~~~~~~~~~~~~~~~~~~~",
                    "~~~~~~~~~~~~~~~~~~~~~",
                    "~~~~~~~~~~~~~~~~~~~~~",
                    "~~~~~~~~~~~~~~~~~~~~~",
                    "~~~~~~~~~~~~~~~~~~~~~",
                    "~~~~~~~~~CCC~~~~~~~~~",
                    "~~~~~~~~~~~~~~~~~~~~~",
                    "~~~~~~~~~~~~~~~~~~~~~",
                    "~~~~~~~~~~~~~~~~~~~~~",
                    "~~~~~~~~~~~~~~~~~~~~~",
                    "~~~~~~~~~~~~~~~~~~~~~",
                    "~~~~~~~~~~~~~~~~~~~~~",
                    "~~~~~~~~~~~~~~~~~~~~~",
                    "~~~~~~~~~CCC~~~~~~~~~",
                    "~~~~~~~~~~~~~~~~~~~~~",
                    "~~~~~~~~~~~~~~~~~~~~~",
                    "~~~~~~~~~~~~~~~~~~~~~",
                    "~~~~~~~~~~~~~~~~~~~~~",
                    "~~~~~~~~~~~~~~~~~~~~~",
                    "~~~~~~~~~~~~~~~~~~~~~",
                    "~~~~~~~~~~~~~~~~~~~~~",
                    "~~~~~~~~~CCC~~~~~~~~~",
                    "~~~~~~~~~~~~~~~~~~~~~")
                .aisle(
                    "~~~~~~~~~CCC~~~~~~~~~",
                    "~~~~~~~CCQQQCC~~~~~~~",
                    "~~~~~~~~~CCC~~~~~~~~~",
                    "~~~~~~~~~~~~~~~~~~~~~",
                    "~~~~~~~~~~~~~~~~~~~~~",
                    "~~~~~~~~~~~~~~~~~~~~~",
                    "~~~~~~~~~~~~~~~~~~~~~",
                    "~~~~~~~~~~~~~~~~~~~~~",
                    "~~~~~~~~~CCC~~~~~~~~~",
                    "~~~~~~~CCQQQCC~~~~~~~",
                    "~~~~~~~~~CCC~~~~~~~~~",
                    "~~~~~~~~~~~~~~~~~~~~~",
                    "~~~~~~~~~~~~~~~~~~~~~",
                    "~~~~~~~~~~~~~~~~~~~~~",
                    "~~~~~~~~~~~~~~~~~~~~~",
                    "~~~~~~~~~~~~~~~~~~~~~",
                    "~~~~~~~~~CCC~~~~~~~~~",
                    "~~~~~~~CCQQQCC~~~~~~~",
                    "~~~~~~~~~CCC~~~~~~~~~",
                    "~~~~~~~~~~~~~~~~~~~~~",
                    "~~~~~~~~~~~~~~~~~~~~~",
                    "~~~~~~~~~~~~~~~~~~~~~",
                    "~~~~~~~~~~~~~~~~~~~~~",
                    "~~~~~~~~~~~~~~~~~~~~~",
                    "~~~~~~~~~CCC~~~~~~~~~",
                    "~~~~~~~CCQQQCC~~~~~~~",
                    "~~~~~~~~~CCC~~~~~~~~~")
                .aisle(
                    "~~~~~~~CC~~~CC~~~~~~~",
                    "~~~~~~CQQGGGQQC~~~~~~",
                    "~~~~~~~CC~~~CC~~~~~~~",
                    "~~~~~~~~~~~~~~~~~~~~~",
                    "~~~~~~~~~~~~~~~~~~~~~",
                    "~~~~~~~~~~~~~~~~~~~~~",
                    "~~~~~~~~~~~~~~~~~~~~~",
                    "~~~~~~~~~~~~~~~~~~~~~",
                    "~~~~~~~CC~~~CC~~~~~~~",
                    "~~~~~~CQQGGGQQC~~~~~~",
                    "~~~~~~~CC~~~CC~~~~~~~",
                    "~~~~~~~~~~~~~~~~~~~~~",
                    "~~~~~~~~~~~~~~~~~~~~~",
                    "~~~~~~~~~~~~~~~~~~~~~",
                    "~~~~~~~~~~~~~~~~~~~~~",
                    "~~~~~~~~~~~~~~~~~~~~~",
                    "~~~~~~~CC~~~CC~~~~~~~",
                    "~~~~~~CQQGGGQQC~~~~~~",
                    "~~~~~~~CC~~~CC~~~~~~~",
                    "~~~~~~~~~~~~~~~~~~~~~",
                    "~~~~~~~~~~~~~~~~~~~~~",
                    "~~~~~~~~~~~~~~~~~~~~~",
                    "~~~~~~~~~~~~~~~~~~~~~",
                    "~~~~~~~~~~~~~~~~~~~~~",
                    "~~~~~~~CC~~~CC~~~~~~~",
                    "~~~~~~CQQGGGQQC~~~~~~",
                    "~~~~~~~CC~~~CC~~~~~~~")
                .aisle(
                    "~~~~~~~~~~~~~~~~~~~~~",
                    "~~~~~~~GG~~~GG~~~~~~~",
                    "~~~~~~~~~~~~~~~~~~~~~",
                    "~~~~~~~~~~~~~~~~~~~~~",
                    "~~~~~~~~~~~~~~~~~~~~~",
                    "~~~~~~~~~~~~~~~~~~~~~",
                    "~~~~~~~~~~~~~~~~~~~~~",
                    "~~~~~~~~~~~~~~~~~~~~~",
                    "~~~~~~~~~~~~~~~~~~~~~",
                    "~~~~~~~GG~~~GG~~~~~~~",
                    "~~~~~~~~~~~~~~~~~~~~~",
                    "~~~~~~~~~~~~~~~~~~~~~",
                    "~~~~~~~~~~~~~~~~~~~~~",
                    "~~~~~~~~~~~~~~~~~~~~~",
                    "~~~~~~~~~~~~~~~~~~~~~",
                    "~~~~~~~~~~~~~~~~~~~~~",
                    "~~~~~~~~~~~~~~~~~~~~~",
                    "~~~~~~~GG~~~GG~~~~~~~",
                    "~~~~~~~~~~~~~~~~~~~~~",
                    "~~~~~~~~~~~~~~~~~~~~~",
                    "~~~~~~~~~~~~~~~~~~~~~",
                    "~~~~~~~~~~~~~~~~~~~~~",
                    "~~~~~~~~~~~~~~~~~~~~~",
                    "~~~~~~~~~~~~~~~~~~~~~",
                    "~~~~~~~~~~~~~~~~~~~~~",
                    "~~~~~~~GG~~~GG~~~~~~~",
                    "~~~~~~~~~~~~~~~~~~~~~")
                .aisle(
                    "~~~~~~~~~~~~~~~~~~~~~",
                    "~~~~~~~~~~~~~~~~~~~~~",
                    "~~~~~~~~~~~~~~~~~~~~~",
                    "~~~~~~~~~~~~~~~~~~~~~",
                    "~~~~~~~~~~~~~~~~~~~~~",
                    "~~~~~~~~~~~~~~~~~~~~~",
                    "~~~~~~~~~~~~~~~~~~~~~",
                    "~~~~~~~~~~~~~~~~~~~~~",
                    "~~~~~~~~~~~~~~~~~~~~~",
                    "~~~~~~~~~~~~~~~~~~~~~",
                    "~~~~~~~~~~~~~~~~~~~~~",
                    "~~~~~~~~~~~~~~~~~~~~~",
                    "~~~~~~~~~~~~~~~~~~~~~",
                    "~~~~~~~~~~~~~~~~~~~~~",
                    "~~~~~~~~~~~~~~~~~~~~~",
                    "~~~~~~~~~~~~~~~~~~~~~",
                    "~~~~~~~~~~~~~~~~~~~~~",
                    "~~~~~~~~~~~~~~~~~~~~~",
                    "~~~~~~~~~~~~~~~~~~~~~",
                    "~~~~~~~~~~~~~~~~~~~~~",
                    "~~~~~~~~~~~~~~~~~~~~~",
                    "~~~~~~~~~~~~~~~~~~~~~",
                    "~~~~~~~~~~~~~~~~~~~~~",
                    "~~~~~~~~~~~~~~~~~~~~~",
                    "~~~~~~~~~~~~~~~~~~~~~",
                    "~~~~~~~~~~~~~~~~~~~~~",
                    "~~~~~~~~~~~~~~~~~~~~~")
                .aisle(
                    "~~~~~~~~~~~~~~~~~~~~~",
                    "~~~~~~~~~~~~~~~~~~~~~",
                    "~~~~~~~~~~~~~~~~~~~~~",
                    "~~~~~~~~~~~~~~~~~~~~~",
                    "~~~~~~~~~~~~~~~~~~~~~",
                    "~~~~~~~~~~~~~~~~~~~~~",
                    "~~~~~~~~~~~~~~~~~~~~~",
                    "~~~~~~~~~~~~~~~~~~~~~",
                    "~~~~~~~~~~~~~~~~~~~~~",
                    "~~~~~~~~~~~~~~~~~~~~~",
                    "~~~~~~~~~~~~~~~~~~~~~",
                    "~~~~~~~~~~~~~~~~~~~~~",
                    "~~~~~~~~~~~~~~~~~~~~~",
                    "~~~~~~~~~~~~~~~~~~~~~",
                    "~~~~~~~~~~~~~~~~~~~~~",
                    "~~~~~~~~~~~~~~~~~~~~~",
                    "~~~~~~~~~~~~~~~~~~~~~",
                    "~~~~~~~~~~~~~~~~~~~~~",
                    "~~~~~~~~~~~~~~~~~~~~~",
                    "~~~~~~~~~~~~~~~~~~~~~",
                    "~~~~~~~~~~~~~~~~~~~~~",
                    "~~~~~~~~~~~~~~~~~~~~~",
                    "~~~~~~~~~~~~~~~~~~~~~",
                    "~~~~~~~~~~~~~~~~~~~~~",
                    "~~~~~~~~~~~~~~~~~~~~~",
                    "~~~~~~~~~~~~~~~~~~~~~",
                    "~~~~~~~~~~~~~~~~~~~~~")
                .aisle(
                    "~~~~~~~~~~~~~~~~~~~~~",
                    "~~C~~~~~~~~~~~~~~~C~~",
                    "~~~~~~~~~~~~~~~~~~~~~",
                    "~~~~~~~~~~~~~~~~~~~~~",
                    "~~~~~~~~~~~~~~~~~~~~~",
                    "~~~~~~~~~~~~~~~~~~~~~",
                    "~~~~~~~~~~~~~~~~~~~~~",
                    "~~~~~~~~~~~~~~~~~~~~~",
                    "~~~~~~~~~~~~~~~~~~~~~",
                    "~~C~~~~~~~~~~~~~~~C~~",
                    "~~~~~~~~~~~~~~~~~~~~~",
                    "~~~~~~~~~~~~~~~~~~~~~",
                    "~~~~~~~~~~~~~~~~~~~~~",
                    "~~~~~~~~~~~~~~~~~~~~~",
                    "~~~~~~~~~~~~~~~~~~~~~",
                    "~~~~~~~~~~~~~~~~~~~~~",
                    "~~~~~~~~~~~~~~~~~~~~~",
                    "~~C~~~~~~~~~~~~~~~C~~",
                    "~~~~~~~~~~~~~~~~~~~~~",
                    "~~~~~~~~~~~~~~~~~~~~~",
                    "~~~~~~~~~~~~~~~~~~~~~",
                    "~~~~~~~~~~~~~~~~~~~~~",
                    "~~~~~~~~~~~~~~~~~~~~~",
                    "~~~~~~~~~~~~~~~~~~~~~",
                    "~~~~~~~~~~~~~~~~~~~~~",
                    "~~C~~~~~~~~~~~~~~~C~~",
                    "~~~~~~~~~~~~~~~~~~~~~")
                .aisle(
                    "~~C~~~~~~~~~~~~~~~C~~",
                    "~CQG~~~~~~~~~~~~~GQC~",
                    "~~C~~~~~~~~~~~~~~~C~~",
                    "~~~~~~~~~~~~~~~~~~~~~",
                    "~~~~~~~~~~~~~~~~~~~~~",
                    "~~~~~~~~~~~~~~~~~~~~~",
                    "~~~~~~~~~~~~~~~~~~~~~",
                    "~~~~~~~~~~~~~~~~~~~~~",
                    "~~C~~~~~~~~~~~~~~~C~~",
                    "~CQG~~~~~~~~~~~~~GQC~",
                    "~~C~~~~~~~~~~~~~~~C~~",
                    "~~~~~~~~~~~~~~~~~~~~~",
                    "~~~~~~~~~~~~~~~~~~~~~",
                    "~~~~~~~~~~~~~~~~~~~~~",
                    "~~~~~~~~~~~~~~~~~~~~~",
                    "~~~~~~~~~~~~~~~~~~~~~",
                    "~~C~~~~~~~~~~~~~~~C~~",
                    "~CQG~~~~~~~~~~~~~GQC~",
                    "~~C~~~~~~~~~~~~~~~C~~",
                    "~~~~~~~~~~~~~~~~~~~~~",
                    "~~~~~~~~~~~~~~~~~~~~~",
                    "~~~~~~~~~~~~~~~~~~~~~",
                    "~~~~~~~~~~~~~~~~~~~~~",
                    "~~~~~~~~~~~~~~~~~~~~~",
                    "~~C~~~~~~~~~~~~~~~C~~",
                    "~CQG~~~~~~~~~~~~~GQC~",
                    "~~C~~~~~~~~~~~~~~~C~~")
                .aisle(
                    "~~C~~~~~~CCC~~~~~~C~~",
                    "~CQG~~~~~GGG~~~~~GQC~",
                    "~~C~~~~~~CCC~~~~~~C~~",
                    "~~~~~~~~~~~~~~~~~~~~~",
                    "~~~~~~~~~~~~~~~~~~~~~",
                    "~~~~~~~~~~~~~~~~~~~~~",
                    "~~~~~~~~~~~~~~~~~~~~~",
                    "~~~~~~~~~~~~~~~~~~~~~",
                    "~~C~~~~~~CCC~~~~~~C~~",
                    "~CQG~~~~~GGG~~~~~GQC~",
                    "~~C~~~~~~CCC~~~~~~C~~",
                    "~~~~~~~~~~~~~~~~~~~~~",
                    "~~~~~~~~~~~~~~~~~~~~~",
                    "~~~~~~~~~~~~~~~~~~~~~",
                    "~~~~~~~~~~~~~~~~~~~~~",
                    "~~~~~~~~~~~~~~~~~~~~~",
                    "~~C~~~~~~CCC~~~~~~C~~",
                    "~CQG~~~~~GGG~~~~~GQC~",
                    "~~C~~~~~~CCC~~~~~~C~~",
                    "~~~~~~~~~~~~~~~~~~~~~",
                    "~~~~~~~~~~~~~~~~~~~~~",
                    "~~~~~~~~~~~~~~~~~~~~~",
                    "~~~~~~~~~~~~~~~~~~~~~",
                    "~~~~~~~~~~~~~~~~~~~~~",
                    "~~C~~~~~~CCC~~~~~~C~~",
                    "~CQG~~~~~GGG~~~~~GQC~",
                    "~~C~~~~~~CCC~~~~~~C~~")
                .aisle(
                    "~C~~~~~~CCCCC~~~~~~C~",
                    "CQG~~~~~GQQQG~~~~~GQC",
                    "~C~~~~~~CCCCC~~~~~~C~",
                    "~~~~~~~~~GGG~~~~~~~~~",
                    "~~~~~~~~~GGG~~~~~~~~~",
                    "~~~~~~~~~GGG~~~~~~~~~",
                    "~~~~~~~~~GGG~~~~~~~~~",
                    "~~~~~~~~~GGG~~~~~~~~~",
                    "~C~~~~~~CCCCC~~~~~~C~",
                    "CQG~~~~~GQQQG~~~~~GQC",
                    "~C~~~~~~CCCCC~~~~~~C~",
                    "~~~~~~~~~GGG~~~~~~~~~",
                    "~~~~~~~~~GGG~~~~~~~~~",
                    "~~~~~~~~~GGG~~~~~~~~~",
                    "~~~~~~~~~GGG~~~~~~~~~",
                    "~~~~~~~~~GGG~~~~~~~~~",
                    "~C~~~~~~CCCCC~~~~~~C~",
                    "CQG~~~~~GQQQG~~~~~GQC",
                    "~C~~~~~~CCCCC~~~~~~C~",
                    "~~~~~~~~~GGG~~~~~~~~~",
                    "~~~~~~~~~GGG~~~~~~~~~",
                    "~~~~~~~~~GGG~~~~~~~~~",
                    "~~~~~~~~~GGG~~~~~~~~~",
                    "~~~~~~~~~GGG~~~~~~~~~",
                    "~C~~~~~~CCCCC~~~~~~C~",
                    "CQG~~~~~GQQQG~~~~~GQC",
                    "~C~~~~~~CCCCC~~~~~~C~")
                .aisle(
                    "~C~~~~~~CCCCC~~~~~~C~",
                    "CQG~~~~~GQTQG~~~~~GQC",
                    "~C~~~~~~CCTCC~~~~~~C~",
                    "~~~~~~~~~GTG~~~~~~~~~",
                    "~~~~~~~~~GTG~~~~~~~~~",
                    "~~~~~~~~~GTG~~~~~~~~~",
                    "~~~~~~~~~GTG~~~~~~~~~",
                    "~~~~~~~~~GTG~~~~~~~~~",
                    "~C~~~~~~CCTCC~~~~~~C~",
                    "CQG~~~~~GQTQG~~~~~GQC",
                    "~C~~~~~~CCTCC~~~~~~C~",
                    "~~~~~~~~~GTG~~~~~~~~~",
                    "~~~~~~~~~GTG~~~~~~~~~",
                    "~~~~~~~~~GTG~~~~~~~~~",
                    "~~~~~~~~~GTG~~~~~~~~~",
                    "~~~~~~~~~GTG~~~~~~~~~",
                    "~C~~~~~~CCTCC~~~~~~C~",
                    "CQG~~~~~GQTQG~~~~~GQC",
                    "~C~~~~~~CCTCC~~~~~~C~",
                    "~~~~~~~~~GTG~~~~~~~~~",
                    "~~~~~~~~~GTG~~~~~~~~~",
                    "~~~~~~~~~GTG~~~~~~~~~",
                    "~~~~~~~~~GTG~~~~~~~~~",
                    "~~~~~~~~~GTG~~~~~~~~~",
                    "~C~~~~~~CCTCC~~~~~~C~",
                    "CQG~~~~~GQTQG~~~~~GQC",
                    "~C~~~~~~CCSCC~~~~~~C~")
                .aisle(
                    "~C~~~~~~CCCCC~~~~~~C~",
                    "CQG~~~~~GQQQG~~~~~GQC",
                    "~C~~~~~~CCCCC~~~~~~C~",
                    "~~~~~~~~~GGG~~~~~~~~~",
                    "~~~~~~~~~GGG~~~~~~~~~",
                    "~~~~~~~~~GGG~~~~~~~~~",
                    "~~~~~~~~~GGG~~~~~~~~~",
                    "~~~~~~~~~GGG~~~~~~~~~",
                    "~C~~~~~~CCCCC~~~~~~C~",
                    "CQG~~~~~GQQQG~~~~~GQC",
                    "~C~~~~~~CCCCC~~~~~~C~",
                    "~~~~~~~~~GGG~~~~~~~~~",
                    "~~~~~~~~~GGG~~~~~~~~~",
                    "~~~~~~~~~GGG~~~~~~~~~",
                    "~~~~~~~~~GGG~~~~~~~~~",
                    "~~~~~~~~~GGG~~~~~~~~~",
                    "~C~~~~~~CCCCC~~~~~~C~",
                    "CQG~~~~~GQQQG~~~~~GQC",
                    "~C~~~~~~CCCCC~~~~~~C~",
                    "~~~~~~~~~GGG~~~~~~~~~",
                    "~~~~~~~~~GGG~~~~~~~~~",
                    "~~~~~~~~~GGG~~~~~~~~~",
                    "~~~~~~~~~GGG~~~~~~~~~",
                    "~~~~~~~~~GGG~~~~~~~~~",
                    "~C~~~~~~CCCCC~~~~~~C~",
                    "CQG~~~~~GQQQG~~~~~GQC",
                    "~C~~~~~~CCCCC~~~~~~C~")
                .aisle(
                    "~~C~~~~~~CCC~~~~~~C~~",
                    "~CQG~~~~~GGG~~~~~GQC~",
                    "~~C~~~~~~CCC~~~~~~C~~",
                    "~~~~~~~~~~~~~~~~~~~~~",
                    "~~~~~~~~~~~~~~~~~~~~~",
                    "~~~~~~~~~~~~~~~~~~~~~",
                    "~~~~~~~~~~~~~~~~~~~~~",
                    "~~~~~~~~~~~~~~~~~~~~~",
                    "~~C~~~~~~CCC~~~~~~C~~",
                    "~CQG~~~~~GGG~~~~~GQC~",
                    "~~C~~~~~~CCC~~~~~~C~~",
                    "~~~~~~~~~~~~~~~~~~~~~",
                    "~~~~~~~~~~~~~~~~~~~~~",
                    "~~~~~~~~~~~~~~~~~~~~~",
                    "~~~~~~~~~~~~~~~~~~~~~",
                    "~~~~~~~~~~~~~~~~~~~~~",
                    "~~C~~~~~~CCC~~~~~~C~~",
                    "~CQG~~~~~GGG~~~~~GQC~",
                    "~~C~~~~~~CCC~~~~~~C~~",
                    "~~~~~~~~~~~~~~~~~~~~~",
                    "~~~~~~~~~~~~~~~~~~~~~",
                    "~~~~~~~~~~~~~~~~~~~~~",
                    "~~~~~~~~~~~~~~~~~~~~~",
                    "~~~~~~~~~~~~~~~~~~~~~",
                    "~~C~~~~~~CCC~~~~~~C~~",
                    "~CQG~~~~~GGG~~~~~GQC~",
                    "~~C~~~~~~CCC~~~~~~C~~")
                .aisle(
                    "~~C~~~~~~~~~~~~~~~C~~",
                    "~CQG~~~~~~~~~~~~~GQC~",
                    "~~C~~~~~~~~~~~~~~~C~~",
                    "~~~~~~~~~~~~~~~~~~~~~",
                    "~~~~~~~~~~~~~~~~~~~~~",
                    "~~~~~~~~~~~~~~~~~~~~~",
                    "~~~~~~~~~~~~~~~~~~~~~",
                    "~~~~~~~~~~~~~~~~~~~~~",
                    "~~C~~~~~~~~~~~~~~~C~~",
                    "~CQG~~~~~~~~~~~~~GQC~",
                    "~~C~~~~~~~~~~~~~~~C~~",
                    "~~~~~~~~~~~~~~~~~~~~~",
                    "~~~~~~~~~~~~~~~~~~~~~",
                    "~~~~~~~~~~~~~~~~~~~~~",
                    "~~~~~~~~~~~~~~~~~~~~~",
                    "~~~~~~~~~~~~~~~~~~~~~",
                    "~~C~~~~~~~~~~~~~~~C~~",
                    "~CQG~~~~~~~~~~~~~GQC~",
                    "~~C~~~~~~~~~~~~~~~C~~",
                    "~~~~~~~~~~~~~~~~~~~~~",
                    "~~~~~~~~~~~~~~~~~~~~~",
                    "~~~~~~~~~~~~~~~~~~~~~",
                    "~~~~~~~~~~~~~~~~~~~~~",
                    "~~~~~~~~~~~~~~~~~~~~~",
                    "~~C~~~~~~~~~~~~~~~C~~",
                    "~CQG~~~~~~~~~~~~~GQC~",
                    "~~C~~~~~~~~~~~~~~~C~~")
                .aisle(
                    "~~~~~~~~~~~~~~~~~~~~~",
                    "~~C~~~~~~~~~~~~~~~C~~",
                    "~~~~~~~~~~~~~~~~~~~~~",
                    "~~~~~~~~~~~~~~~~~~~~~",
                    "~~~~~~~~~~~~~~~~~~~~~",
                    "~~~~~~~~~~~~~~~~~~~~~",
                    "~~~~~~~~~~~~~~~~~~~~~",
                    "~~~~~~~~~~~~~~~~~~~~~",
                    "~~~~~~~~~~~~~~~~~~~~~",
                    "~~C~~~~~~~~~~~~~~~C~~",
                    "~~~~~~~~~~~~~~~~~~~~~",
                    "~~~~~~~~~~~~~~~~~~~~~",
                    "~~~~~~~~~~~~~~~~~~~~~",
                    "~~~~~~~~~~~~~~~~~~~~~",
                    "~~~~~~~~~~~~~~~~~~~~~",
                    "~~~~~~~~~~~~~~~~~~~~~",
                    "~~~~~~~~~~~~~~~~~~~~~",
                    "~~C~~~~~~~~~~~~~~~C~~",
                    "~~~~~~~~~~~~~~~~~~~~~",
                    "~~~~~~~~~~~~~~~~~~~~~",
                    "~~~~~~~~~~~~~~~~~~~~~",
                    "~~~~~~~~~~~~~~~~~~~~~",
                    "~~~~~~~~~~~~~~~~~~~~~",
                    "~~~~~~~~~~~~~~~~~~~~~",
                    "~~~~~~~~~~~~~~~~~~~~~",
                    "~~C~~~~~~~~~~~~~~~C~~",
                    "~~~~~~~~~~~~~~~~~~~~~")
                .aisle(
                    "~~~~~~~~~~~~~~~~~~~~~",
                    "~~~~~~~~~~~~~~~~~~~~~",
                    "~~~~~~~~~~~~~~~~~~~~~",
                    "~~~~~~~~~~~~~~~~~~~~~",
                    "~~~~~~~~~~~~~~~~~~~~~",
                    "~~~~~~~~~~~~~~~~~~~~~",
                    "~~~~~~~~~~~~~~~~~~~~~",
                    "~~~~~~~~~~~~~~~~~~~~~",
                    "~~~~~~~~~~~~~~~~~~~~~",
                    "~~~~~~~~~~~~~~~~~~~~~",
                    "~~~~~~~~~~~~~~~~~~~~~",
                    "~~~~~~~~~~~~~~~~~~~~~",
                    "~~~~~~~~~~~~~~~~~~~~~",
                    "~~~~~~~~~~~~~~~~~~~~~",
                    "~~~~~~~~~~~~~~~~~~~~~",
                    "~~~~~~~~~~~~~~~~~~~~~",
                    "~~~~~~~~~~~~~~~~~~~~~",
                    "~~~~~~~~~~~~~~~~~~~~~",
                    "~~~~~~~~~~~~~~~~~~~~~",
                    "~~~~~~~~~~~~~~~~~~~~~",
                    "~~~~~~~~~~~~~~~~~~~~~",
                    "~~~~~~~~~~~~~~~~~~~~~",
                    "~~~~~~~~~~~~~~~~~~~~~",
                    "~~~~~~~~~~~~~~~~~~~~~",
                    "~~~~~~~~~~~~~~~~~~~~~",
                    "~~~~~~~~~~~~~~~~~~~~~",
                    "~~~~~~~~~~~~~~~~~~~~~")
                .aisle(
                    "~~~~~~~~~~~~~~~~~~~~~",
                    "~~~~~~~~~~~~~~~~~~~~~",
                    "~~~~~~~~~~~~~~~~~~~~~",
                    "~~~~~~~~~~~~~~~~~~~~~",
                    "~~~~~~~~~~~~~~~~~~~~~",
                    "~~~~~~~~~~~~~~~~~~~~~",
                    "~~~~~~~~~~~~~~~~~~~~~",
                    "~~~~~~~~~~~~~~~~~~~~~",
                    "~~~~~~~~~~~~~~~~~~~~~",
                    "~~~~~~~~~~~~~~~~~~~~~",
                    "~~~~~~~~~~~~~~~~~~~~~",
                    "~~~~~~~~~~~~~~~~~~~~~",
                    "~~~~~~~~~~~~~~~~~~~~~",
                    "~~~~~~~~~~~~~~~~~~~~~",
                    "~~~~~~~~~~~~~~~~~~~~~",
                    "~~~~~~~~~~~~~~~~~~~~~",
                    "~~~~~~~~~~~~~~~~~~~~~",
                    "~~~~~~~~~~~~~~~~~~~~~",
                    "~~~~~~~~~~~~~~~~~~~~~",
                    "~~~~~~~~~~~~~~~~~~~~~",
                    "~~~~~~~~~~~~~~~~~~~~~",
                    "~~~~~~~~~~~~~~~~~~~~~",
                    "~~~~~~~~~~~~~~~~~~~~~",
                    "~~~~~~~~~~~~~~~~~~~~~",
                    "~~~~~~~~~~~~~~~~~~~~~",
                    "~~~~~~~~~~~~~~~~~~~~~",
                    "~~~~~~~~~~~~~~~~~~~~~")
                .aisle(
                    "~~~~~~~~~~~~~~~~~~~~~",
                    "~~~~~~~GG~~~GG~~~~~~~",
                    "~~~~~~~~~~~~~~~~~~~~~",
                    "~~~~~~~~~~~~~~~~~~~~~",
                    "~~~~~~~~~~~~~~~~~~~~~",
                    "~~~~~~~~~~~~~~~~~~~~~",
                    "~~~~~~~~~~~~~~~~~~~~~",
                    "~~~~~~~~~~~~~~~~~~~~~",
                    "~~~~~~~~~~~~~~~~~~~~~",
                    "~~~~~~~GG~~~GG~~~~~~~",
                    "~~~~~~~~~~~~~~~~~~~~~",
                    "~~~~~~~~~~~~~~~~~~~~~",
                    "~~~~~~~~~~~~~~~~~~~~~",
                    "~~~~~~~~~~~~~~~~~~~~~",
                    "~~~~~~~~~~~~~~~~~~~~~",
                    "~~~~~~~~~~~~~~~~~~~~~",
                    "~~~~~~~~~~~~~~~~~~~~~",
                    "~~~~~~~GG~~~GG~~~~~~~",
                    "~~~~~~~~~~~~~~~~~~~~~",
                    "~~~~~~~~~~~~~~~~~~~~~",
                    "~~~~~~~~~~~~~~~~~~~~~",
                    "~~~~~~~~~~~~~~~~~~~~~",
                    "~~~~~~~~~~~~~~~~~~~~~",
                    "~~~~~~~~~~~~~~~~~~~~~",
                    "~~~~~~~~~~~~~~~~~~~~~",
                    "~~~~~~~GG~~~GG~~~~~~~",
                    "~~~~~~~~~~~~~~~~~~~~~")
                .aisle(
                    "~~~~~~~CC~~~CC~~~~~~~",
                    "~~~~~~CQQGGGQQC~~~~~~",
                    "~~~~~~~CC~~~CC~~~~~~~",
                    "~~~~~~~~~~~~~~~~~~~~~",
                    "~~~~~~~~~~~~~~~~~~~~~",
                    "~~~~~~~~~~~~~~~~~~~~~",
                    "~~~~~~~~~~~~~~~~~~~~~",
                    "~~~~~~~~~~~~~~~~~~~~~",
                    "~~~~~~~CC~~~CC~~~~~~~",
                    "~~~~~~CQQGGGQQC~~~~~~",
                    "~~~~~~~CC~~~CC~~~~~~~",
                    "~~~~~~~~~~~~~~~~~~~~~",
                    "~~~~~~~~~~~~~~~~~~~~~",
                    "~~~~~~~~~~~~~~~~~~~~~",
                    "~~~~~~~~~~~~~~~~~~~~~",
                    "~~~~~~~~~~~~~~~~~~~~~",
                    "~~~~~~~CC~~~CC~~~~~~~",
                    "~~~~~~CQQGGGQQC~~~~~~",
                    "~~~~~~~CC~~~CC~~~~~~~",
                    "~~~~~~~~~~~~~~~~~~~~~",
                    "~~~~~~~~~~~~~~~~~~~~~",
                    "~~~~~~~~~~~~~~~~~~~~~",
                    "~~~~~~~~~~~~~~~~~~~~~",
                    "~~~~~~~~~~~~~~~~~~~~~",
                    "~~~~~~~CC~~~CC~~~~~~~",
                    "~~~~~~CQQGGGQQC~~~~~~",
                    "~~~~~~~CC~~~CC~~~~~~~")
                .aisle(
                    "~~~~~~~~~CCC~~~~~~~~~",
                    "~~~~~~~CCQQQCC~~~~~~~",
                    "~~~~~~~~~CCC~~~~~~~~~",
                    "~~~~~~~~~~~~~~~~~~~~~",
                    "~~~~~~~~~~~~~~~~~~~~~",
                    "~~~~~~~~~~~~~~~~~~~~~",
                    "~~~~~~~~~~~~~~~~~~~~~",
                    "~~~~~~~~~~~~~~~~~~~~~",
                    "~~~~~~~~~CCC~~~~~~~~~",
                    "~~~~~~~CCQQQCC~~~~~~~",
                    "~~~~~~~~~CCC~~~~~~~~~",
                    "~~~~~~~~~~~~~~~~~~~~~",
                    "~~~~~~~~~~~~~~~~~~~~~",
                    "~~~~~~~~~~~~~~~~~~~~~",
                    "~~~~~~~~~~~~~~~~~~~~~",
                    "~~~~~~~~~~~~~~~~~~~~~",
                    "~~~~~~~~~CCC~~~~~~~~~",
                    "~~~~~~~CCQQQCC~~~~~~~",
                    "~~~~~~~~~CCC~~~~~~~~~",
                    "~~~~~~~~~~~~~~~~~~~~~",
                    "~~~~~~~~~~~~~~~~~~~~~",
                    "~~~~~~~~~~~~~~~~~~~~~",
                    "~~~~~~~~~~~~~~~~~~~~~",
                    "~~~~~~~~~~~~~~~~~~~~~",
                    "~~~~~~~~~CCC~~~~~~~~~",
                    "~~~~~~~CCQQQCC~~~~~~~",
                    "~~~~~~~~~CCC~~~~~~~~~")
                .aisle(
                    "~~~~~~~~~~~~~~~~~~~~~",
                    "~~~~~~~~~CCC~~~~~~~~~",
                    "~~~~~~~~~~~~~~~~~~~~~",
                    "~~~~~~~~~~~~~~~~~~~~~",
                    "~~~~~~~~~~~~~~~~~~~~~",
                    "~~~~~~~~~~~~~~~~~~~~~",
                    "~~~~~~~~~~~~~~~~~~~~~",
                    "~~~~~~~~~~~~~~~~~~~~~",
                    "~~~~~~~~~~~~~~~~~~~~~",
                    "~~~~~~~~~CCC~~~~~~~~~",
                    "~~~~~~~~~~~~~~~~~~~~~",
                    "~~~~~~~~~~~~~~~~~~~~~",
                    "~~~~~~~~~~~~~~~~~~~~~",
                    "~~~~~~~~~~~~~~~~~~~~~",
                    "~~~~~~~~~~~~~~~~~~~~~",
                    "~~~~~~~~~~~~~~~~~~~~~",
                    "~~~~~~~~~~~~~~~~~~~~~",
                    "~~~~~~~~~CCC~~~~~~~~~",
                    "~~~~~~~~~~~~~~~~~~~~~",
                    "~~~~~~~~~~~~~~~~~~~~~",
                    "~~~~~~~~~~~~~~~~~~~~~",
                    "~~~~~~~~~~~~~~~~~~~~~",
                    "~~~~~~~~~~~~~~~~~~~~~",
                    "~~~~~~~~~~~~~~~~~~~~~",
                    "~~~~~~~~~~~~~~~~~~~~~",
                    "~~~~~~~~~CCC~~~~~~~~~",
                    "~~~~~~~~~~~~~~~~~~~~~")
                .where("S", IBlockMatcher.controller(loc))
                .where("~", IBlockMatcher.ANY)
                .whereOr("C", 
                <metastate:contenttweaker:quantumcasing>,
                    IBlockMatcher.abilityPartPredicate(
                        MultiblockAbility.IMPORT_FLUIDS,
                        MultiblockAbility.IMPORT_ITEMS,
                        MultiblockAbility.INPUT_ENERGY,
                        MultiblockAbility.EXPORT_FLUIDS,
                        MultiblockAbility.EXPORT_ITEMS
                ))
                .where("Q", <metastate:contenttweaker:coil>)
                .where("G", <metastate:contenttweaker:quantumglass>)
                .where("T", <metastate:contenttweaker:quantumcomputercasing>)
                .build())
        .addDesign(
                FactoryMultiblockShapeInfo.start()
                .aisle("                           ","                           ","                           ","                           ","                           ","                           ","                           ","                           "," C       C       C       C "," C       C       C       C "," C       C       C       C ","                           ","                           ","                           ","                           ","                           ","                           ","                           ","                           ")
                .aisle("                           ","                           ","                           ","                           ","                           ","                           "," C       C       C       C "," C       C       C       C ","CQC     CQC     CQC     CQC","CQC     CQC     CQC     CQC","CQC     CQC     CQC     CQC"," C       C       C       C "," C       C       C       C ","                           ","                           ","                           ","                           ","                           ","                           ")
                .aisle("                           ","                           ","                           ","                           ","                           "," C       C       C       C ","CQC     CQC     CQC     CQC","CQC     CQC     CQC     CQC"," G       G       G       G "," G       G       G       G "," G       G       G       G ","CQC     CQC     CQC     CQC","CQC     CQC     CQC     CQC"," C       C       C       C ","                           ","                           ","                           ","                           ","                           ")
                .aisle("                           ","                           ","                           ","                           ","                           ","                           "," G       G       G       G "," G       G       G       G ","                           ","                           ","                           "," G       G       G       G "," G       G       G       G ","                           ","                           ","                           ","                           ","                           ","                           ")
                .aisle("                           ","                           ","                           ","                           ","                           ","                           ","                           ","                           ","                           ","                           ","                           ","                           ","                           ","                           ","                           ","                           ","                           ","                           ","                           ")
                .aisle("                           ","                           "," C       C       C       C ","                           ","                           ","                           ","                           ","                           ","                           ","                           ","                           ","                           ","                           ","                           ","                           ","                           "," C       C       C       C ","                           ","                           ")
                .aisle("                           "," C       C       C       C ","CQC     CQC     CQC     CQC"," G       G       G       G ","                           ","                           ","                           ","                           ","                           ","                           ","                           ","                           ","                           ","                           ","                           "," G       G       G       G ","CQC     CQC     CQC     CQC"," C       C       C       C ","                           ")
                .aisle("                           "," C       C       C       C ","CQC     CQC     CQC     CQC"," G       G       G       G ","                           ","                           ","                           ","CGC     CGC     CGC     CGC","CGC     CGC     CGC     CGC","CGC     CGC     CGC     CGC","CGC     CGC     CGC     CGC","CGC     CGC     CGC     CGC","                           ","                           ","                           "," G       G       G       G ","CQC     CQC     CQC     CQC"," C       C       C       C ","                           ")
                .aisle(" C       C       C       C ","CQC     CQC     CQC     CQC"," G       G       G       G ","                           ","                           ","                           ","                           ","CGC     CGC     CGC     CGC","CQCGGGGGCQCGGGGGCQCGGGGGCQC","CQCGGGGGCQCGGGGGCQCGGGGGCQC","CQCGGGGGCQCGGGGGCQCGGGGGCQC","CGC     CGC     CGC     CGC","                           ","                           ","                           ","                           "," G       G       G       G ","CQC     CQC     CQC     CQC"," C       C       C       C ")
                .aisle(" C       C       C       C ","CQC     CQC     CQC     CQC"," G       G       G       G ","                           ","                           ","                           ","                           ","CGC     CGC     CGC     CGC","CQCGGGGGCQCGGGGGCQCGGGGGCQC","STTTTTTTTTTTTTTTTTTTTTTTTTE","CQCGGGGGCQCGGGGGCQCGGGGGCQC","CGC     CGC     CGC     CGC","                           ","                           ","                           ","                           "," G       G       G       G ","CQC     CQC     CQC     CQC"," C       C       C       C ")
                .aisle(" C       C       C       C ","CQC     CQC     CQC     CQC"," G       G       G       G ","                           ","                           ","                           ","                           ","CGC     CGC     CGC     CGC","CQCGGGGGCQCGGGGGCQCGGGGGCQC","CQCGGGGGCQCGGGGGCQCGGGGGCQC","CQCGGGGGCQCGGGGGCQCGGGGGCQC","CGC     CGC     CGC     CGC","                           ","                           ","                           ","                           "," G       G       G       G ","CQC     CQC     CQC     CQC"," C       C       C       C ")
                .aisle("                           "," C       C       C       C ","CQC     CQC     CQC     CQC"," G       G       G       G ","                           ","                           ","                           ","CGC     CGC     CGC     CGC","CGC     CGC     CGC     CGC","CGC     CGC     CGC     CGC","CGC     CGC     CGC     CGC","CGC     CGC     CGC     CGC","                           ","                           ","                           "," G       G       G       G ","CQC     CQC     CQC     CQC"," C       C       C       C ","                           ")
                .aisle("                           "," C       C       C       C ","CQC     CQC     CQC     CQC"," G       G       G       G ","                           ","                           ","                           ","                           ","                           ","                           ","                           ","                           ","                           ","                           ","                           "," G       G       G       G ","CQC     CQC     CQC     CQC"," C       C       C       C ","                           ")
                .aisle("                           ","                           "," C       C       C       C ","                           ","                           ","                           ","                           ","                           ","                           ","                           ","                           ","                           ","                           ","                           ","                           ","                           "," C       C       C       C ","                           ","                           ")
                .aisle("                           ","                           ","                           ","                           ","                           ","                           ","                           ","                           ","                           ","                           ","                           ","                           ","                           ","                           ","                           ","                           ","                           ","                           ","                           ")
                .aisle("                           ","                           ","                           ","                           ","                           ","                           "," G       G       G       G "," G       G       G       G ","                           ","                           ","                           "," G       G       G       G "," G       G       G       G ","                           ","                           ","                           ","                           ","                           ","                           ")
                .aisle("                           ","                           ","                           ","                           ","                           "," C       C       C       C ","CQC     CQC     CQC     CQC","CQC     CQC     CQC     CQC"," G       G       G       G "," G       G       G       G "," G       G       G       G ","CQC     CQC     CQC     CQC","CQC     CQC     CQC     CQC"," C       C       C       C ","                           ","                           ","                           ","                           ","                           ")
                .aisle("                           ","                           ","                           ","                           ","                           ","                           "," C       C       C       C "," C       C       C       C ","CQC     CQC     CQC     CQC","CQC     CQC     CQC     CQC","CQC     CQC     CQC     CQC"," C       C       C       C "," C       C       C       C ","                           ","                           ","                           ","                           ","                           ","                           ")
                .aisle("                           ","                           ","                           ","                           ","                           ","                           ","                           ","                           "," C       C       C       C "," C       C       C       C "," C       C       C       C ","                           ","                           ","                           ","                           ","                           ","                           ","                           ","                           ")

                .where("C", <metastate:contenttweaker:quantumcasing>)
                .where("G", <metastate:contenttweaker:quantumglass>)
                .where("S", IBlockInfo.controller(loc))
                .where("Q", <metastate:contenttweaker:coil>)
                .where("T", <metastate:contenttweaker:quantumcomputercasing>)
                .where("L", MetaTileEntities.FLUID_IMPORT_HATCH[1], IFacing.south())
                .where("X", MetaTileEntities.FLUID_EXPORT_HATCH[1], IFacing.north())
                .where("E", MetaTileEntities.ENERGY_INPUT_HATCH[4], IFacing.east())
                .build())
.withRecipeMap(
        FactoryRecipeMap.start(loc)
                        .maxInputs(9)
                        .maxFluidInputs(3)
                        .maxOutputs(1)
                        .build())
.withTexture(ICubeRenderer.sided("contenttweaker:blocks/quantumcasing"))
.withZoom(0.3f)
.buildAndRegister() as Multiblock;




#Refined
miracle_top.recipeMap.recipeBuilder()
    .inputs(<gregtech:meta_item_2:16189>*32,<gtadditions:ga_meta_item:32031>*4,<gregtech:meta_item_2:32486>*4)
    .fluidInputs(<liquid:soldering_alloy>*288)
    .outputs(<gtadditions:ga_meta_item:32203>*32)
    .duration(400)
    .EUt(800000)
    .buildAndRegister();

miracle_top.recipeMap.recipeBuilder()
    .inputs(<gtadditions:ga_meta_item:32203>*16,<gtadditions:ga_meta_item:32031>*16,<gregtech:meta_item_1:12183>*8,<gtadditions:ga_meta_item:32242>*16,<gtadditions:ga_meta_item:32240>*16,<gtadditions:ga_meta_item:32241>*16)
    .fluidInputs(<liquid:soldering_alloy>*288)
    .outputs(<gtadditions:ga_meta_item:32204>*32)
    .duration(400)
    .EUt(800000)
    .buildAndRegister();

miracle_top.recipeMap.recipeBuilder()
    .inputs(<gtadditions:ga_meta_item:32204>*64,<gtadditions:ga_meta_item:32241>*32,<gtadditions:ga_meta_item:32240>*32,<gtadditions:ga_meta_item:32031>*16,<gregtech:cable:970>*16,<gregtech:meta_item_2:32485>*16)
    .fluidInputs(<liquid:soldering_alloy>*288)
    .outputs(<gtadditions:ga_meta_item:32205>*32)
    .duration(400)
    .EUt(800000)
    .buildAndRegister();

miracle_top.recipeMap.recipeBuilder()
    .inputs(<gtadditions:ga_meta_item:32205>*32,<gtadditions:ga_meta_item:32243>*16,<gtadditions:ga_meta_item:32240>*32,<gtadditions:ga_meta_item:32241>*64,<gregtech:frame_stainless_steel>*32,<gregtech:meta_item_2:32485>*32)
    .fluidInputs(<liquid:soldering_alloy>*288)
    .outputs(<gtadditions:ga_meta_item:32206>*32)
    .duration(400)
    .EUt(800000)
    .buildAndRegister();

#Micro
#Nano
#Quantum
#Crystal
#Wetware
#Bioware
#Optical
#Exotic
#Cosmic
#Supra-Casual
#Nano Circuit
#Pico Circuit
#Quantum Circuit