import crafttweaker.world.IFacing;
import crafttweaker.block.IBlock;
import crafttweaker.block.IBlockState;
import crafttweaker.item.IIngredient;
import crafttweaker.item.IItemStack;
import mods.gregtech.multiblock.Builder;
import mods.gregtech.multiblock.FactoryBlockPattern;
import mods.gregtech.multiblock.IBlockMatcher;
import mods.gregtech.multiblock.MultiblockAbility;
import mods.gregtech.multiblock.RelativeDirection;
import mods.gregtech.multiblock.FactoryMultiblockShapeInfo;
import mods.gregtech.multiblock.IBlockInfo;
import mods.gregtech.multiblock.IBlockWorldState;
import mods.gregtech.multiblock.Multiblock;
import mods.gregtech.recipe.RecipeMap;
import mods.gregtech.MetaTileEntities;
import mods.gregtech.recipe.FactoryRecipeMap;
import mods.gregtech.render.ITextureArea;
import mods.gregtech.render.MoveType;
import mods.gregtech.render.ICubeRenderer;
import mods.gregtech.render.Textures;
import crafttweaker.oredict.IOreDict;
import crafttweaker.oredict.IOreDictEntry;


var loc = "miracle_top";
var meta = 10048;
val miracle_top = Builder.start(loc, meta)
    .withPattern(
            FactoryBlockPattern.start(RelativeDirection.RIGHT, RelativeDirection.BACK, RelativeDirection.UP)
                .aisle(
                    "~~~~~~~~~~~~~~~~~~~~~",
                    "~~~~~~~~~CCC~~~~~~~~~",
                    "~~~~~~~~~~~~~~~~~~~~~",
                    "~~~~~~~~~~~~~~~~~~~~~",
                    "~~~~~~~~~~~~~~~~~~~~~",
                    "~~~~~~~~~~~~~~~~~~~~~",
                    "~~~~~~~~~~~~~~~~~~~~~",
                    "~~~~~~~~~~~~~~~~~~~~~",
                    "~~~~~~~~~~~~~~~~~~~~~",
                    "~~~~~~~~~CCC~~~~~~~~~",
                    "~~~~~~~~~~~~~~~~~~~~~",
                    "~~~~~~~~~~~~~~~~~~~~~",
                    "~~~~~~~~~~~~~~~~~~~~~",
                    "~~~~~~~~~~~~~~~~~~~~~",
                    "~~~~~~~~~~~~~~~~~~~~~",
                    "~~~~~~~~~~~~~~~~~~~~~",
                    "~~~~~~~~~~~~~~~~~~~~~",
                    "~~~~~~~~~CCC~~~~~~~~~",
                    "~~~~~~~~~~~~~~~~~~~~~",
                    "~~~~~~~~~~~~~~~~~~~~~",
                    "~~~~~~~~~~~~~~~~~~~~~",
                    "~~~~~~~~~~~~~~~~~~~~~",
                    "~~~~~~~~~~~~~~~~~~~~~",
                    "~~~~~~~~~~~~~~~~~~~~~",
                    "~~~~~~~~~~~~~~~~~~~~~",
                    "~~~~~~~~~CCC~~~~~~~~~",
                    "~~~~~~~~~~~~~~~~~~~~~")
                .aisle(
                    "~~~~~~~~~CCC~~~~~~~~~",
                    "~~~~~~~CCQQQCC~~~~~~~",
                    "~~~~~~~~~CCC~~~~~~~~~",
                    "~~~~~~~~~~~~~~~~~~~~~",
                    "~~~~~~~~~~~~~~~~~~~~~",
                    "~~~~~~~~~~~~~~~~~~~~~",
                    "~~~~~~~~~~~~~~~~~~~~~",
                    "~~~~~~~~~~~~~~~~~~~~~",
                    "~~~~~~~~~CCC~~~~~~~~~",
                    "~~~~~~~CCQQQCC~~~~~~~",
                    "~~~~~~~~~CCC~~~~~~~~~",
                    "~~~~~~~~~~~~~~~~~~~~~",
                    "~~~~~~~~~~~~~~~~~~~~~",
                    "~~~~~~~~~~~~~~~~~~~~~",
                    "~~~~~~~~~~~~~~~~~~~~~",
                    "~~~~~~~~~~~~~~~~~~~~~",
                    "~~~~~~~~~CCC~~~~~~~~~",
                    "~~~~~~~CCQQQCC~~~~~~~",
                    "~~~~~~~~~CCC~~~~~~~~~",
                    "~~~~~~~~~~~~~~~~~~~~~",
                    "~~~~~~~~~~~~~~~~~~~~~",
                    "~~~~~~~~~~~~~~~~~~~~~",
                    "~~~~~~~~~~~~~~~~~~~~~",
                    "~~~~~~~~~~~~~~~~~~~~~",
                    "~~~~~~~~~CCC~~~~~~~~~",
                    "~~~~~~~CCQQQCC~~~~~~~",
                    "~~~~~~~~~CCC~~~~~~~~~")
                .aisle(
                    "~~~~~~~CC~~~CC~~~~~~~",
                    "~~~~~~CQQGGGQQC~~~~~~",
                    "~~~~~~~CC~~~CC~~~~~~~",
                    "~~~~~~~~~~~~~~~~~~~~~",
                    "~~~~~~~~~~~~~~~~~~~~~",
                    "~~~~~~~~~~~~~~~~~~~~~",
                    "~~~~~~~~~~~~~~~~~~~~~",
                    "~~~~~~~~~~~~~~~~~~~~~",
                    "~~~~~~~CC~~~CC~~~~~~~",
                    "~~~~~~CQQGGGQQC~~~~~~",
                    "~~~~~~~CC~~~CC~~~~~~~",
                    "~~~~~~~~~~~~~~~~~~~~~",
                    "~~~~~~~~~~~~~~~~~~~~~",
                    "~~~~~~~~~~~~~~~~~~~~~",
                    "~~~~~~~~~~~~~~~~~~~~~",
                    "~~~~~~~~~~~~~~~~~~~~~",
                    "~~~~~~~CC~~~CC~~~~~~~",
                    "~~~~~~CQQGGGQQC~~~~~~",
                    "~~~~~~~CC~~~CC~~~~~~~",
                    "~~~~~~~~~~~~~~~~~~~~~",
                    "~~~~~~~~~~~~~~~~~~~~~",
                    "~~~~~~~~~~~~~~~~~~~~~",
                    "~~~~~~~~~~~~~~~~~~~~~",
                    "~~~~~~~~~~~~~~~~~~~~~",
                    "~~~~~~~CC~~~CC~~~~~~~",
                    "~~~~~~CQQGGGQQC~~~~~~",
                    "~~~~~~~CC~~~CC~~~~~~~")
                .aisle(
                    "~~~~~~~~~~~~~~~~~~~~~",
                    "~~~~~~~GG~~~~GG~~~~~~",
                    "~~~~~~~~~~~~~~~~~~~~~",
                    "~~~~~~~~~~~~~~~~~~~~~",
                    "~~~~~~~~~~~~~~~~~~~~~",
                    "~~~~~~~~~~~~~~~~~~~~~",
                    "~~~~~~~~~~~~~~~~~~~~~",
                    "~~~~~~~~~~~~~~~~~~~~~",
                    "~~~~~~~~~~~~~~~~~~~~~",
                    "~~~~~~~GG~~~~GG~~~~~~",
                    "~~~~~~~~~~~~~~~~~~~~~",
                    "~~~~~~~~~~~~~~~~~~~~~",
                    "~~~~~~~~~~~~~~~~~~~~~",
                    "~~~~~~~~~~~~~~~~~~~~~",
                    "~~~~~~~~~~~~~~~~~~~~~",
                    "~~~~~~~~~~~~~~~~~~~~~",
                    "~~~~~~~~~~~~~~~~~~~~~",
                    "~~~~~~~GG~~~~GG~~~~~~",
                    "~~~~~~~~~~~~~~~~~~~~~",
                    "~~~~~~~~~~~~~~~~~~~~~",
                    "~~~~~~~~~~~~~~~~~~~~~",
                    "~~~~~~~~~~~~~~~~~~~~~",
                    "~~~~~~~~~~~~~~~~~~~~~",
                    "~~~~~~~~~~~~~~~~~~~~~",
                    "~~~~~~~~~~~~~~~~~~~~~",
                    "~~~~~~~GG~~~~GG~~~~~~",
                    "~~~~~~~~~~~~~~~~~~~~~")
                .aisle(
                    "~~~~~~~~~~~~~~~~~~~~~",
                    "~~~~~~~~~~~~~~~~~~~~~",
                    "~~~~~~~~~~~~~~~~~~~~~",
                    "~~~~~~~~~~~~~~~~~~~~~",
                    "~~~~~~~~~~~~~~~~~~~~~",
                    "~~~~~~~~~~~~~~~~~~~~~",
                    "~~~~~~~~~~~~~~~~~~~~~",
                    "~~~~~~~~~~~~~~~~~~~~~",
                    "~~~~~~~~~~~~~~~~~~~~~",
                    "~~~~~~~~~~~~~~~~~~~~~",
                    "~~~~~~~~~~~~~~~~~~~~~",
                    "~~~~~~~~~~~~~~~~~~~~~",
                    "~~~~~~~~~~~~~~~~~~~~~",
                    "~~~~~~~~~~~~~~~~~~~~~",
                    "~~~~~~~~~~~~~~~~~~~~~",
                    "~~~~~~~~~~~~~~~~~~~~~",
                    "~~~~~~~~~~~~~~~~~~~~~",
                    "~~~~~~~~~~~~~~~~~~~~~",
                    "~~~~~~~~~~~~~~~~~~~~~",
                    "~~~~~~~~~~~~~~~~~~~~~",
                    "~~~~~~~~~~~~~~~~~~~~~",
                    "~~~~~~~~~~~~~~~~~~~~~",
                    "~~~~~~~~~~~~~~~~~~~~~",
                    "~~~~~~~~~~~~~~~~~~~~~",
                    "~~~~~~~~~~~~~~~~~~~~~",
                    "~~~~~~~~~~~~~~~~~~~~~",
                    "~~~~~~~~~~~~~~~~~~~~~")
                .aisle(
                    "~~~~~~~~~~~~~~~~~~~~~",
                    "~~~~~~~~~~~~~~~~~~~~~",
                    "~~~~~~~~~~~~~~~~~~~~~",
                    "~~~~~~~~~~~~~~~~~~~~~",
                    "~~~~~~~~~~~~~~~~~~~~~",
                    "~~~~~~~~~~~~~~~~~~~~~",
                    "~~~~~~~~~~~~~~~~~~~~~",
                    "~~~~~~~~~~~~~~~~~~~~~",
                    "~~~~~~~~~~~~~~~~~~~~~",
                    "~~~~~~~~~~~~~~~~~~~~~",
                    "~~~~~~~~~~~~~~~~~~~~~",
                    "~~~~~~~~~~~~~~~~~~~~~",
                    "~~~~~~~~~~~~~~~~~~~~~",
                    "~~~~~~~~~~~~~~~~~~~~~",
                    "~~~~~~~~~~~~~~~~~~~~~",
                    "~~~~~~~~~~~~~~~~~~~~~",
                    "~~~~~~~~~~~~~~~~~~~~~",
                    "~~~~~~~~~~~~~~~~~~~~~",
                    "~~~~~~~~~~~~~~~~~~~~~",
                    "~~~~~~~~~~~~~~~~~~~~~",
                    "~~~~~~~~~~~~~~~~~~~~~",
                    "~~~~~~~~~~~~~~~~~~~~~",
                    "~~~~~~~~~~~~~~~~~~~~~",
                    "~~~~~~~~~~~~~~~~~~~~~",
                    "~~~~~~~~~~~~~~~~~~~~~",
                    "~~~~~~~~~~~~~~~~~~~~~",
                    "~~~~~~~~~~~~~~~~~~~~~")
                .aisle(
                    "~~~~~~~~~~~~~~~~~~~~~",
                    "~~C~~~~~~~~~~~~~~~C~~",
                    "~~~~~~~~~~~~~~~~~~~~~",
                    "~~~~~~~~~~~~~~~~~~~~~",
                    "~~~~~~~~~~~~~~~~~~~~~",
                    "~~~~~~~~~~~~~~~~~~~~~",
                    "~~~~~~~~~~~~~~~~~~~~~",
                    "~~~~~~~~~~~~~~~~~~~~~",
                    "~~~~~~~~~~~~~~~~~~~~~",
                    "~~C~~~~~~~~~~~~~~~C~~",
                    "~~~~~~~~~~~~~~~~~~~~~",
                    "~~~~~~~~~~~~~~~~~~~~~",
                    "~~~~~~~~~~~~~~~~~~~~~",
                    "~~~~~~~~~~~~~~~~~~~~~",
                    "~~~~~~~~~~~~~~~~~~~~~",
                    "~~~~~~~~~~~~~~~~~~~~~",
                    "~~~~~~~~~~~~~~~~~~~~~",
                    "~~C~~~~~~~~~~~~~~~C~~",
                    "~~~~~~~~~~~~~~~~~~~~~",
                    "~~~~~~~~~~~~~~~~~~~~~",
                    "~~~~~~~~~~~~~~~~~~~~~",
                    "~~~~~~~~~~~~~~~~~~~~~",
                    "~~~~~~~~~~~~~~~~~~~~~",
                    "~~~~~~~~~~~~~~~~~~~~~",
                    "~~~~~~~~~~~~~~~~~~~~~",
                    "~~C~~~~~~~~~~~~~~~C~~",
                    "~~~~~~~~~~~~~~~~~~~~~")
                .aisle(
                    "~~C~~~~~~~~~~~~~~~C~~",
                    "~CQG~~~~~~~~~~~~~GQC~",
                    "~~C~~~~~~~~~~~~~~~C~~",
                    "~~~~~~~~~~~~~~~~~~~~~",
                    "~~~~~~~~~~~~~~~~~~~~~",
                    "~~~~~~~~~~~~~~~~~~~~~",
                    "~~~~~~~~~~~~~~~~~~~~~",
                    "~~~~~~~~~~~~~~~~~~~~~",
                    "~~C~~~~~~~~~~~~~~~C~~",
                    "~CQG~~~~~~~~~~~~~GQC~",
                    "~~C~~~~~~~~~~~~~~~C~~",
                    "~~~~~~~~~~~~~~~~~~~~~",
                    "~~~~~~~~~~~~~~~~~~~~~",
                    "~~~~~~~~~~~~~~~~~~~~~",
                    "~~~~~~~~~~~~~~~~~~~~~",
                    "~~~~~~~~~~~~~~~~~~~~~",
                    "~~C~~~~~~~~~~~~~~~C~~",
                    "~CQG~~~~~~~~~~~~~GQC~",
                    "~~C~~~~~~~~~~~~~~~C~~",
                    "~~~~~~~~~~~~~~~~~~~~~",
                    "~~~~~~~~~~~~~~~~~~~~~",
                    "~~~~~~~~~~~~~~~~~~~~~",
                    "~~~~~~~~~~~~~~~~~~~~~",
                    "~~~~~~~~~~~~~~~~~~~~~",
                    "~~C~~~~~~~~~~~~~~~C~~",
                    "~CQG~~~~~~~~~~~~~GQC~",
                    "~~C~~~~~~~~~~~~~~~C~~")
                .aisle(
                    "~~C~~~~~~CCC~~~~~~C~~",
                    "~CQG~~~~~GGG~~~~~GQC~",
                    "~~C~~~~~~CCC~~~~~~C~~",
                    "~~~~~~~~~~~~~~~~~~~~~",
                    "~~~~~~~~~~~~~~~~~~~~~",
                    "~~~~~~~~~~~~~~~~~~~~~",
                    "~~~~~~~~~~~~~~~~~~~~~",
                    "~~~~~~~~~~~~~~~~~~~~~",
                    "~~C~~~~~~CCC~~~~~~C~~",
                    "~CQG~~~~~GGG~~~~~GQC~",
                    "~~C~~~~~~CCC~~~~~~C~~",
                    "~~~~~~~~~~~~~~~~~~~~~",
                    "~~~~~~~~~~~~~~~~~~~~~",
                    "~~~~~~~~~~~~~~~~~~~~~",
                    "~~~~~~~~~~~~~~~~~~~~~",
                    "~~~~~~~~~~~~~~~~~~~~~",
                    "~~C~~~~~~CCC~~~~~~C~~",
                    "~CQG~~~~~GGG~~~~~GQC~",
                    "~~C~~~~~~CCC~~~~~~C~~",
                    "~~~~~~~~~~~~~~~~~~~~~",
                    "~~~~~~~~~~~~~~~~~~~~~",
                    "~~~~~~~~~~~~~~~~~~~~~",
                    "~~~~~~~~~~~~~~~~~~~~~",
                    "~~~~~~~~~~~~~~~~~~~~~",
                    "~~C~~~~~~CCC~~~~~~C~~",
                    "~CQG~~~~~GGG~~~~~GQC~",
                    "~~C~~~~~~CCC~~~~~~C~~")
                .aisle(
                    "~C~~~~~~CCCCC~~~~~~C~",
                    "CQG~~~~~GMMMG~~~~~GQC",
                    "~C~~~~~~CCCCC~~~~~~C~",
                    "~~~~~~~~~GGG~~~~~~~~~",
                    "~~~~~~~~~GGG~~~~~~~~~",
                    "~~~~~~~~~GGG~~~~~~~~~",
                    "~~~~~~~~~GGG~~~~~~~~~",
                    "~~~~~~~~~GGG~~~~~~~~~",
                    "~C~~~~~~CCCCC~~~~~~C~",
                    "CQG~~~~~GMMMG~~~~~GQC",
                    "~C~~~~~~CCCCC~~~~~~C~",
                    "~~~~~~~~~GGG~~~~~~~~~",
                    "~~~~~~~~~GGG~~~~~~~~~",
                    "~~~~~~~~~GGG~~~~~~~~~",
                    "~~~~~~~~~GGG~~~~~~~~~",
                    "~~~~~~~~~GGG~~~~~~~~~",
                    "~C~~~~~~CCCCC~~~~~~C~",
                    "CQG~~~~~GMMMG~~~~~GQC",
                    "~C~~~~~~CCCCC~~~~~~C~",
                    "~~~~~~~~~GGG~~~~~~~~~",
                    "~~~~~~~~~GGG~~~~~~~~~",
                    "~~~~~~~~~GGG~~~~~~~~~",
                    "~~~~~~~~~GGG~~~~~~~~~",
                    "~~~~~~~~~GGG~~~~~~~~~",
                    "~C~~~~~~CCCCC~~~~~~C~",
                    "CQG~~~~~GMMMG~~~~~GQC",
                    "~C~~~~~~CCCCC~~~~~~C~")
                .aisle(
                    "~C~~~~~~CCCCC~~~~~~C~",
                    "CQG~~~~~GMTMG~~~~~GQC",
                    "~C~~~~~~CCTCC~~~~~~C~",
                    "~~~~~~~~~GTG~~~~~~~~~",
                    "~~~~~~~~~GTG~~~~~~~~~",
                    "~~~~~~~~~GTG~~~~~~~~~",
                    "~~~~~~~~~GTG~~~~~~~~~",
                    "~~~~~~~~~GTG~~~~~~~~~",
                    "~C~~~~~~CCTCC~~~~~~C~",
                    "CQG~~~~~GMTMG~~~~~GQC",
                    "~C~~~~~~CCTCC~~~~~~C~",
                    "~~~~~~~~~GTG~~~~~~~~~",
                    "~~~~~~~~~GTG~~~~~~~~~",
                    "~~~~~~~~~GTG~~~~~~~~~",
                    "~~~~~~~~~GTG~~~~~~~~~",
                    "~~~~~~~~~GTG~~~~~~~~~",
                    "~C~~~~~~CCTCC~~~~~~C~",
                    "CQG~~~~~GMTMG~~~~~GQC",
                    "~C~~~~~~CCTCC~~~~~~C~",
                    "~~~~~~~~~GTG~~~~~~~~~",
                    "~~~~~~~~~GTG~~~~~~~~~",
                    "~~~~~~~~~GTG~~~~~~~~~",
                    "~~~~~~~~~GTG~~~~~~~~~",
                    "~~~~~~~~~GTG~~~~~~~~~",
                    "~C~~~~~~CCTCC~~~~~~C~",
                    "CQG~~~~~GMTMG~~~~~GQC",
                    "~C~~~~~~CCSCC~~~~~~C~")
                .aisle(
                    "~C~~~~~~CCCCC~~~~~~C~",
                    "CQG~~~~~GMMMG~~~~~GQC",
                    "~C~~~~~~CCCCC~~~~~~C~",
                    "~~~~~~~~~GGG~~~~~~~~~",
                    "~~~~~~~~~GGG~~~~~~~~~",
                    "~~~~~~~~~GGG~~~~~~~~~",
                    "~~~~~~~~~GGG~~~~~~~~~",
                    "~~~~~~~~~GGG~~~~~~~~~",
                    "~C~~~~~~CCCCC~~~~~~C~",
                    "CQG~~~~~GMMMG~~~~~GQC",
                    "~C~~~~~~CCCCC~~~~~~C~",
                    "~~~~~~~~~GGG~~~~~~~~~",
                    "~~~~~~~~~GGG~~~~~~~~~",
                    "~~~~~~~~~GGG~~~~~~~~~",
                    "~~~~~~~~~GGG~~~~~~~~~",
                    "~~~~~~~~~GGG~~~~~~~~~",
                    "~C~~~~~~CCCCC~~~~~~C~",
                    "CQG~~~~~GMMMG~~~~~GQC",
                    "~C~~~~~~CCCCC~~~~~~C~",
                    "~~~~~~~~~GGG~~~~~~~~~",
                    "~~~~~~~~~GGG~~~~~~~~~",
                    "~~~~~~~~~GGG~~~~~~~~~",
                    "~~~~~~~~~GGG~~~~~~~~~",
                    "~~~~~~~~~GGG~~~~~~~~~",
                    "~C~~~~~~CCCCC~~~~~~C~",
                    "CQG~~~~~GMMMG~~~~~GQC",
                    "~C~~~~~~CCCCC~~~~~~C~")
                .aisle(
                    "~~C~~~~~~CCC~~~~~~C~~",
                    "~CQG~~~~~GGG~~~~~GQC~",
                    "~~C~~~~~~CCC~~~~~~C~~",
                    "~~~~~~~~~~~~~~~~~~~~~",
                    "~~~~~~~~~~~~~~~~~~~~~",
                    "~~~~~~~~~~~~~~~~~~~~~",
                    "~~~~~~~~~~~~~~~~~~~~~",
                    "~~~~~~~~~~~~~~~~~~~~~",
                    "~~C~~~~~~CCC~~~~~~C~~",
                    "~CQG~~~~~GGG~~~~~GQC~",
                    "~~C~~~~~~CCC~~~~~~C~~",
                    "~~~~~~~~~~~~~~~~~~~~~",
                    "~~~~~~~~~~~~~~~~~~~~~",
                    "~~~~~~~~~~~~~~~~~~~~~",
                    "~~~~~~~~~~~~~~~~~~~~~",
                    "~~~~~~~~~~~~~~~~~~~~~",
                    "~~C~~~~~~CCC~~~~~~C~~",
                    "~CQG~~~~~GGG~~~~~GQC~",
                    "~~C~~~~~~CCC~~~~~~C~~",
                    "~~~~~~~~~~~~~~~~~~~~~",
                    "~~~~~~~~~~~~~~~~~~~~~",
                    "~~~~~~~~~~~~~~~~~~~~~",
                    "~~~~~~~~~~~~~~~~~~~~~",
                    "~~~~~~~~~~~~~~~~~~~~~",
                    "~~C~~~~~~CCC~~~~~~C~~",
                    "~CQG~~~~~GGG~~~~~GQC~",
                    "~~C~~~~~~CCC~~~~~~C~~")
                .aisle(
                    "~~C~~~~~~~~~~~~~~~C~~",
                    "~CQG~~~~~~~~~~~~~GQC~",
                    "~~C~~~~~~~~~~~~~~~C~~",
                    "~~~~~~~~~~~~~~~~~~~~~",
                    "~~~~~~~~~~~~~~~~~~~~~",
                    "~~~~~~~~~~~~~~~~~~~~~",
                    "~~~~~~~~~~~~~~~~~~~~~",
                    "~~~~~~~~~~~~~~~~~~~~~",
                    "~~C~~~~~~~~~~~~~~~C~~",
                    "~CQG~~~~~~~~~~~~~GQC~",
                    "~~C~~~~~~~~~~~~~~~C~~",
                    "~~~~~~~~~~~~~~~~~~~~~",
                    "~~~~~~~~~~~~~~~~~~~~~",
                    "~~~~~~~~~~~~~~~~~~~~~",
                    "~~~~~~~~~~~~~~~~~~~~~",
                    "~~~~~~~~~~~~~~~~~~~~~",
                    "~~C~~~~~~~~~~~~~~~C~~",
                    "~CQG~~~~~~~~~~~~~GQC~",
                    "~~C~~~~~~~~~~~~~~~C~~",
                    "~~~~~~~~~~~~~~~~~~~~~",
                    "~~~~~~~~~~~~~~~~~~~~~",
                    "~~~~~~~~~~~~~~~~~~~~~",
                    "~~~~~~~~~~~~~~~~~~~~~",
                    "~~~~~~~~~~~~~~~~~~~~~",
                    "~~C~~~~~~~~~~~~~~~C~~",
                    "~CQG~~~~~~~~~~~~~GQC~",
                    "~~C~~~~~~~~~~~~~~~C~~")
                .aisle(
                    "~~~~~~~~~~~~~~~~~~~~~",
                    "~~~~~~~~~~~~~~~~~~~~~",
                    "~~~~~~~~~~~~~~~~~~~~~",
                    "~~~~~~~~~~~~~~~~~~~~~",
                    "~~~~~~~~~~~~~~~~~~~~~",
                    "~~~~~~~~~~~~~~~~~~~~~",
                    "~~~~~~~~~~~~~~~~~~~~~",
                    "~~~~~~~~~~~~~~~~~~~~~",
                    "~~~~~~~~~~~~~~~~~~~~~",
                    "~~~~~~~~~~~~~~~~~~~~~",
                    "~~~~~~~~~~~~~~~~~~~~~",
                    "~~~~~~~~~~~~~~~~~~~~~",
                    "~~~~~~~~~~~~~~~~~~~~~",
                    "~~~~~~~~~~~~~~~~~~~~~",
                    "~~~~~~~~~~~~~~~~~~~~~",
                    "~~~~~~~~~~~~~~~~~~~~~",
                    "~~~~~~~~~~~~~~~~~~~~~",
                    "~~~~~~~~~~~~~~~~~~~~~",
                    "~~~~~~~~~~~~~~~~~~~~~",
                    "~~~~~~~~~~~~~~~~~~~~~",
                    "~~~~~~~~~~~~~~~~~~~~~",
                    "~~~~~~~~~~~~~~~~~~~~~",
                    "~~~~~~~~~~~~~~~~~~~~~",
                    "~~~~~~~~~~~~~~~~~~~~~",
                    "~~~~~~~~~~~~~~~~~~~~~",
                    "~~~~~~~~~~~~~~~~~~~~~",
                    "~~~~~~~~~~~~~~~~~~~~~")
                .aisle(
                    "~~~~~~~~~~~~~~~~~~~~~",
                    "~~~~~~~~~~~~~~~~~~~~~",
                    "~~~~~~~~~~~~~~~~~~~~~",
                    "~~~~~~~~~~~~~~~~~~~~~",
                    "~~~~~~~~~~~~~~~~~~~~~",
                    "~~~~~~~~~~~~~~~~~~~~~",
                    "~~~~~~~~~~~~~~~~~~~~~",
                    "~~~~~~~~~~~~~~~~~~~~~",
                    "~~~~~~~~~~~~~~~~~~~~~",
                    "~~~~~~~~~~~~~~~~~~~~~",
                    "~~~~~~~~~~~~~~~~~~~~~",
                    "~~~~~~~~~~~~~~~~~~~~~",
                    "~~~~~~~~~~~~~~~~~~~~~",
                    "~~~~~~~~~~~~~~~~~~~~~",
                    "~~~~~~~~~~~~~~~~~~~~~",
                    "~~~~~~~~~~~~~~~~~~~~~",
                    "~~~~~~~~~~~~~~~~~~~~~",
                    "~~~~~~~~~~~~~~~~~~~~~",
                    "~~~~~~~~~~~~~~~~~~~~~",
                    "~~~~~~~~~~~~~~~~~~~~~",
                    "~~~~~~~~~~~~~~~~~~~~~",
                    "~~~~~~~~~~~~~~~~~~~~~",
                    "~~~~~~~~~~~~~~~~~~~~~",
                    "~~~~~~~~~~~~~~~~~~~~~",
                    "~~~~~~~~~~~~~~~~~~~~~",
                    "~~~~~~~~~~~~~~~~~~~~~",
                    "~~~~~~~~~~~~~~~~~~~~~")
                .aisle(
                    "~~~~~~~~~~~~~~~~~~~~~",
                    "~~~~~~~GG~~~~GG~~~~~~",
                    "~~~~~~~~~~~~~~~~~~~~~",
                    "~~~~~~~~~~~~~~~~~~~~~",
                    "~~~~~~~~~~~~~~~~~~~~~",
                    "~~~~~~~~~~~~~~~~~~~~~",
                    "~~~~~~~~~~~~~~~~~~~~~",
                    "~~~~~~~~~~~~~~~~~~~~~",
                    "~~~~~~~~~~~~~~~~~~~~~",
                    "~~~~~~~GG~~~~GG~~~~~~",
                    "~~~~~~~~~~~~~~~~~~~~~",
                    "~~~~~~~~~~~~~~~~~~~~~",
                    "~~~~~~~~~~~~~~~~~~~~~",
                    "~~~~~~~~~~~~~~~~~~~~~",
                    "~~~~~~~~~~~~~~~~~~~~~",
                    "~~~~~~~~~~~~~~~~~~~~~",
                    "~~~~~~~~~~~~~~~~~~~~~",
                    "~~~~~~~GG~~~~GG~~~~~~",
                    "~~~~~~~~~~~~~~~~~~~~~",
                    "~~~~~~~~~~~~~~~~~~~~~",
                    "~~~~~~~~~~~~~~~~~~~~~",
                    "~~~~~~~~~~~~~~~~~~~~~",
                    "~~~~~~~~~~~~~~~~~~~~~",
                    "~~~~~~~~~~~~~~~~~~~~~",
                    "~~~~~~~~~~~~~~~~~~~~~",
                    "~~~~~~~GG~~~~GG~~~~~~",
                    "~~~~~~~~~~~~~~~~~~~~~")
                .aisle(
                    "~~~~~~~CC~~~CC~~~~~~~",
                    "~~~~~~CQQGGGQQC~~~~~~",
                    "~~~~~~~CC~~~CC~~~~~~~",
                    "~~~~~~~~~~~~~~~~~~~~~",
                    "~~~~~~~~~~~~~~~~~~~~~",
                    "~~~~~~~~~~~~~~~~~~~~~",
                    "~~~~~~~~~~~~~~~~~~~~~",
                    "~~~~~~~~~~~~~~~~~~~~~",
                    "~~~~~~~CC~~~CC~~~~~~~",
                    "~~~~~~CQQGGGQQC~~~~~~",
                    "~~~~~~~CC~~~CC~~~~~~~",
                    "~~~~~~~~~~~~~~~~~~~~~",
                    "~~~~~~~~~~~~~~~~~~~~~",
                    "~~~~~~~~~~~~~~~~~~~~~",
                    "~~~~~~~~~~~~~~~~~~~~~",
                    "~~~~~~~~~~~~~~~~~~~~~",
                    "~~~~~~~CC~~~CC~~~~~~~",
                    "~~~~~~CQQGGGQQC~~~~~~",
                    "~~~~~~~CC~~~CC~~~~~~~",
                    "~~~~~~~~~~~~~~~~~~~~~",
                    "~~~~~~~~~~~~~~~~~~~~~",
                    "~~~~~~~~~~~~~~~~~~~~~",
                    "~~~~~~~~~~~~~~~~~~~~~",
                    "~~~~~~~~~~~~~~~~~~~~~",
                    "~~~~~~~CC~~~CC~~~~~~~",
                    "~~~~~~CQQGGGQQC~~~~~~",
                    "~~~~~~~CC~~~CC~~~~~~~")
                .aisle(
                    "~~~~~~~~~CCC~~~~~~~~~",
                    "~~~~~~~CCQQQCC~~~~~~~",
                    "~~~~~~~~~CCC~~~~~~~~~",
                    "~~~~~~~~~~~~~~~~~~~~~",
                    "~~~~~~~~~~~~~~~~~~~~~",
                    "~~~~~~~~~~~~~~~~~~~~~",
                    "~~~~~~~~~~~~~~~~~~~~~",
                    "~~~~~~~~~~~~~~~~~~~~~",
                    "~~~~~~~~~CCC~~~~~~~~~",
                    "~~~~~~~CCQQQCC~~~~~~~",
                    "~~~~~~~~~CCC~~~~~~~~~",
                    "~~~~~~~~~~~~~~~~~~~~~",
                    "~~~~~~~~~~~~~~~~~~~~~",
                    "~~~~~~~~~~~~~~~~~~~~~",
                    "~~~~~~~~~~~~~~~~~~~~~",
                    "~~~~~~~~~~~~~~~~~~~~~",
                    "~~~~~~~~~CCC~~~~~~~~~",
                    "~~~~~~~CCQQQCC~~~~~~~",
                    "~~~~~~~~~CCC~~~~~~~~~",
                    "~~~~~~~~~~~~~~~~~~~~~",
                    "~~~~~~~~~~~~~~~~~~~~~",
                    "~~~~~~~~~~~~~~~~~~~~~",
                    "~~~~~~~~~~~~~~~~~~~~~",
                    "~~~~~~~~~~~~~~~~~~~~~",
                    "~~~~~~~~~CCC~~~~~~~~~",
                    "~~~~~~~CCQQQCC~~~~~~~",
                    "~~~~~~~~~CCC~~~~~~~~~")
                .aisle(
                    "~~~~~~~~~~~~~~~~~~~~~",
                    "~~~~~~~~~CCC~~~~~~~~~",
                    "~~~~~~~~~~~~~~~~~~~~~",
                    "~~~~~~~~~~~~~~~~~~~~~",
                    "~~~~~~~~~~~~~~~~~~~~~",
                    "~~~~~~~~~~~~~~~~~~~~~",
                    "~~~~~~~~~~~~~~~~~~~~~",
                    "~~~~~~~~~~~~~~~~~~~~~",
                    "~~~~~~~~~~~~~~~~~~~~~",
                    "~~~~~~~~~CCC~~~~~~~~~",
                    "~~~~~~~~~~~~~~~~~~~~~",
                    "~~~~~~~~~~~~~~~~~~~~~",
                    "~~~~~~~~~~~~~~~~~~~~~",
                    "~~~~~~~~~~~~~~~~~~~~~",
                    "~~~~~~~~~~~~~~~~~~~~~",
                    "~~~~~~~~~~~~~~~~~~~~~",
                    "~~~~~~~~~~~~~~~~~~~~~",
                    "~~~~~~~~~CCC~~~~~~~~~",
                    "~~~~~~~~~~~~~~~~~~~~~",
                    "~~~~~~~~~~~~~~~~~~~~~",
                    "~~~~~~~~~~~~~~~~~~~~~",
                    "~~~~~~~~~~~~~~~~~~~~~",
                    "~~~~~~~~~~~~~~~~~~~~~",
                    "~~~~~~~~~~~~~~~~~~~~~",
                    "~~~~~~~~~~~~~~~~~~~~~",
                    "~~~~~~~~~CCC~~~~~~~~~",
                    "~~~~~~~~~~~~~~~~~~~~~")
                .where("S", IBlockMatcher.controller(loc))
                .where("~", IBlockMatcher.ANY)
                .whereOr("C", 
                <metastate:contenttweaker:quantumcasing>,
                    IBlockMatcher.abilityPartPredicate(
                        MultiblockAbility.IMPORT_FLUIDS,
                        MultiblockAbility.IMPORT_ITEMS,
                        MultiblockAbility.INPUT_ENERGY,
                        MultiblockAbility.EXPORT_FLUIDS,
                        MultiblockAbility.EXPORT_ITEMS
                ))
                .where("M", <metastate:contenttweaker:coil>)
                .where("G", <metastate:contenttweaker:quantumglass>)
                .where("Q", <metastate:gtadditions:ga_fusion_casing:5>)
                .where("T", <metastate:contenttweaker:quantumcomputercasing>)
                .build())
        .addDesign(
                FactoryMultiblockShapeInfo.start()
                .aisle(                          
                    "                           ",
                    "                           ",
                    "                           ",
                    "                           ",
                    "                           ",
                    "                           ",
                    "                           ",
                    "                           ",
                    " C       C       C       C ",
                    " C       C       C       C ",
                    " C       C       C       C ",
                    "                           ",
                    "                           ",
                    "                           ",
                    "                           ",
                    "                           ",
                    "                           ",
                    "                           ",
                    "                           ")
                .aisle(                          
                    "                           ",
                    "                           ",
                    "                           ",
                    "                           ",
                    "                           ",
                    "                           ",
                    " C       C       C       C ",
                    " C       C       C       C ",
                    "CQC     CQC     CQC     CQC",
                    "CQC     CQC     CQC     CQC",
                    "CQC     CQC     CQC     CQC",
                    " C       C       C       C ",
                    " C       C       C       C ",
                    "                           ",
                    "                           ",
                    "                           ",
                    "                           ",
                    "                           ",
                    "                           ")
                .aisle(                          
                    "                           ",
                    "                           ",
                    "                           ",
                    "                           ",
                    "                           ",
                    " C       C       C       C ",
                    "CQC     CQC     CQC     CQC",
                    "CQC     CQC     CQC     CQC",
                    " G       G       G       G ",
                    " G       G       G       G ",
                    " G       G       G       G ",
                    "CQC     CQC     CQC     CQC",
                    "CQC     CQC     CQC     CQC",
                    " C       C       C       C ",
                    "                           ",
                    "                           ",
                    "                           ",
                    "                           ",
                    "                           ")
                .aisle(                          
                    "                           ",
                    "                           ",
                    "                           ",
                    "                           ",
                    "                           ",
                    "                           ",
                    " G       G       G       G ",
                    " G       G       G       G ",
                    "                           ",
                    "                           ",
                    "                           ",
                    " G       G       G       G ",
                    " G       G       G       G ",
                    "                           ",
                    "                           ",
                    "                           ",
                    "                           ",
                    "                           ",
                    "                           ")
                .aisle(                          
                    "                           ",
                    "                           ",
                    "                           ",
                    "                           ",
                    "                           ",
                    "                           ",
                    "                           ",
                    "                           ",
                    "                           ",
                    "                           ",
                    "                           ",
                    "                           ",
                    "                           ",
                    "                           ",
                    "                           ",
                    "                           ",
                    "                           ",
                    "                           ",
                    "                           ")
                .aisle(                          
                    "                           ",
                    "                           ",
                    "                           ",
                    "                           ",
                    "                           ",
                    "                           ",
                    "                           ",
                    "                           ",
                    "                           ",
                    "                           ",
                    "                           ",
                    "                           ",
                    "                           ",
                    "                           ",
                    "                           ",
                    "                           ",
                    "                           ",
                    "                           ",
                    "                           ")
                .aisle(                          
                    "                           ",
                    " C       C       C       C ",
                    "                           ",
                    "                           ",
                    "                           ",
                    "                           ",
                    "                           ",
                    "                           ",
                    "                           ",
                    "                           ",
                    "                           ",
                    "                           ",
                    "                           ",
                    "                           ",
                    "                           ",
                    " C       C       C       C ",
                    "                           ",
                    "                           ")
                .aisle(                          
                    "                           ",
                    " C       C       C       C ",
                    "CQC     CQC     CQC     CQC",
                    " G       G       G       G ",
                    "                           ",
                    "                           ",
                    "                           ",
                    "CGC     CGC     CGC     CGC",
                    "CMCGGGGGCMCGGGGGCMCGGGGGCMC",
                    "CMCGGGGGCMCGGGGGCMCGGGGGCMC",
                    "CMCGGGGGCMCGGGGGCMCGGGGGCMC",
                    "CGC     CGC     CGC     CGC",
                    "                           ",
                    "                           ",
                    " G       G       G       G ",
                    "CQC     CQC     CQC     CQC",
                    " C       C       C       C ",
                    "                           ")
                .aisle(                          
                    " C       C       C       C ",
                    "CQC     CQC     CQC     CQC",
                    " G       G       G       G ",
                    "                           ",
                    "                           ",
                    "                           ",
                    "                           ",
                    "CGC     CGC     CGC     CGC",
                    "CMCGGGGGCMCGGGGGCMCGGGGGCMC",
                    "CMCGGGGGCMCGGGGGCMCGGGGGCMC",
                    "CMCGGGGGCMCGGGGGCMCGGGGGCMC",
                    "CGC     CGC     CGC     CGC",
                    "                           ",
                    "                           ",
                    "                           ",
                    " G       G       G       G ",
                    "CQC     CQC     CQC     CQC",
                    " C       C       C       C ")
                .aisle(                          
                    " C       C       C       C ",
                    "CQC     CQC     CQC     CQC",
                    " G       G       G       G ",
                    "                           ",
                    "                           ",
                    "                           ",
                    "                           ",
                    "CGC     CGC     CGC     CGC",
                    "CMCGGGGGCMCGGGGGCMCGGGGGCMC",
                    "STTTTTTTTTTTTTTTTTTTTTTTTTE",
                    "CMCGGGGGCMCGGGGGCMCGGGGGCMC",
                    "CGC     CGC     CGC     CGC",
                    "                           ",
                    "                           ",
                    "                           ",
                    " G       G       G       G ",
                    "CQC     CQC     CQC     CQC",
                    " C       C       C       C ")
                .aisle(                          
                    " C       C       C       C ",
                    "CQC     CQC     CQC     CQC",
                    " G       G       G       G ",
                    "                           ",
                    "                           ",
                    "                           ",
                    "                           ",
                    "CGC     CGC     CGC     CGC",
                    "CMCGGGGGCMCGGGGGCMCGGGGGCMC",
                    "CMCGGGGGCMCGGGGGCMCGGGGGCMC",
                    "CMCGGGGGCMCGGGGGCMCGGGGGCMC",
                    "CGC     CGC     CGC     CGC",
                    "                           ",
                    "                           ",
                    "                           ",
                    " G       G       G       G ",
                    "CQC     CQC     CQC     CQC",
                    " C       C       C       C ")
                .aisle(                          
                    "                           ",
                    " C       C       C       C ",
                    "CQC     CQC     CQC     CQC",
                    " G       G       G       G ",
                    "                           ",
                    "                           ",
                    "                           ",
                    "CGC     CGC     CGC     CGC",
                    "CGC     CGC     CGC     CGC",
                    "CGC     CGC     CGC     CGC",
                    "CGC     CGC     CGC     CGC",
                    "CGC     CGC     CGC     CGC",
                    "                           ",
                    "                           ",
                    " G       G       G       G ",
                    "CQC     CQC     CQC     CQC",
                    " C       C       C       C ",
                    "                           ")
                .aisle(                          
                    "                           ",
                    " C       C       C       C ",
                    "                           ",
                    "                           ",
                    "                           ",
                    "                           ",
                    "                           ",
                    "                           ",
                    "                           ",
                    "                           ",
                    "                           ",
                    "                           ",
                    "                           ",
                    "                           ",
                    "                           ",
                    " C       C       C       C ",
                    "                           ",
                    "                           ")
                .aisle(                          
                    "                           ",
                    "                           ",
                    "                           ",
                    "                           ",
                    "                           ",
                    "                           ",
                    "                           ",
                    "                           ",
                    "                           ",
                    "                           ",
                    "                           ",
                    "                           ",
                    "                           ",
                    "                           ",
                    "                           ",
                    "                           ",
                    "                           ",
                    "                           ",
                    "                           ")
                .aisle(                          
                    "                           ",
                    "                           ",
                    "                           ",
                    "                           ",
                    "                           ",
                    "                           ",
                    "                           ",
                    "                           ",
                    "                           ",
                    "                           ",
                    "                           ",
                    "                           ",
                    "                           ",
                    "                           ",
                    "                           ",
                    "                           ",
                    "                           ",
                    "                           ",
                    "                           ")
                .aisle(                          
                    "                           ",
                    "                           ",
                    "                           ",
                    "                           ",
                    "                           ",
                    "                           ",
                    " G       G       G       G ",
                    " G       G       G       G ",
                    "                           ",
                    "                           ",
                    "                           ",
                    " G       G       G       G ",
                    " G       G       G       G ",
                    "                           ",
                    "                           ",
                    "                           ",
                    "                           ",
                    "                           ",
                    "                           ")
                .aisle(                          
                    "                           ",
                    "                           ",
                    "                           ",
                    "                           ",
                    "                           ",
                    " C       C       C       C ",
                    "CQC     CQC     CQC     CQC",
                    "CQC     CQC     CQC     CQC",
                    " G       G       G       G ",
                    " G       G       G       G ",
                    " G       G       G       G ",
                    "CQC     CQC     CQC     CQC",
                    "CQC     CQC     CQC     CQC",
                    " C       C       C       C ",
                    "                           ",
                    "                           ",
                    "                           ",
                    "                           ",
                    "                           ")
                .aisle(                          
                    "                           ",
                    "                           ",
                    "                           ",
                    "                           ",
                    "                           ",
                    "                           ",
                    " C       C       C       C ",
                    " C       C       C       C ",
                    "CQC     CQC     CQC     CQC",
                    "CQC     CQC     CQC     CQC",
                    "CQC     CQC     CQC     CQC",
                    " C       C       C       C ",
                    " C       C       C       C ",
                    "                           ",
                    "                           ",
                    "                           ",
                    "                           ",
                    "                           ",
                    "                           ")
                .aisle(                          
                    "                           ",
                    "                           ",
                    "                           ",
                    "                           ",
                    "                           ",
                    "                           ",
                    "                           ",
                    "                           ",
                    " C       C       C       C ",
                    " C       C       C       C ",
                    " C       C       C       C ",
                    "                           ",
                    "                           ",
                    "                           ",
                    "                           ",
                    "                           ",
                    "                           ",
                    "                           ",
                    "                           ")
                .where("C", <metastate:contenttweaker:quantumcasing>)
                .where("G", <metastate:contenttweaker:quantumglass>)
                .where("Q", <metastate:gtadditions:ga_fusion_casing:5>)
                .where("S", IBlockInfo.controller(loc))
                .where("Q", <metastate:contenttweaker:coil>)
                .where("T", <metastate:contenttweaker:quantumcomputercasing>)
                .where("L", MetaTileEntities.FLUID_IMPORT_HATCH[1], IFacing.south())
                .where("X", MetaTileEntities.FLUID_EXPORT_HATCH[1], IFacing.north())
                .where("E", MetaTileEntities.ENERGY_INPUT_HATCH[4], IFacing.east())
                .build())
.withRecipeMap(
        FactoryRecipeMap.start(loc)
                        .maxInputs(1)
                        .maxFluidInputs(1)
                        .maxFluidOutputs(1)
                        .maxOutputs(1)
                        .build())
.withTexture(ICubeRenderer.sided("contenttweaker:blocks/quantumcasing"))
.withZoom(0.3f)
.buildAndRegister() as Multiblock;

