import crafttweaker.world.IFacing;
import crafttweaker.block.IBlock;
import crafttweaker.block.IBlockState;
import crafttweaker.item.IIngredient;
import crafttweaker.item.IItemStack;
import mods.gregtech.multiblock.Builder;
import mods.gregtech.multiblock.FactoryBlockPattern;
import mods.gregtech.multiblock.IBlockMatcher;
import mods.gregtech.multiblock.MultiblockAbility;
import mods.gregtech.multiblock.RelativeDirection;
import mods.gregtech.multiblock.FactoryMultiblockShapeInfo;
import mods.gregtech.multiblock.IBlockInfo;
import mods.gregtech.multiblock.IBlockWorldState;
import mods.gregtech.multiblock.Multiblock;
import mods.gregtech.recipe.RecipeMap;
import mods.gregtech.MetaTileEntities;
import mods.gregtech.recipe.FactoryRecipeMap;
import mods.gregtech.render.ITextureArea;
import mods.gregtech.render.MoveType;
import mods.gregtech.render.ICubeRenderer;
import mods.gregtech.render.Textures;
import crafttweaker.oredict.IOreDict;
import crafttweaker.oredict.IOreDictEntry;


var loc = "space_elevator";
var meta = 10118;
val space_elevator = Builder.start(loc, meta)
    .withPattern(
            FactoryBlockPattern.start(RelativeDirection.RIGHT, RelativeDirection.BACK, RelativeDirection.UP)
                .aisle("~~~~~~~~~~~~~~~~~~~KKK~~~~~~~~~~~~~~~~~~~",
                       "~~~~~~~~~~~~~~~~~KKKKKKK~~~~~~~~~~~~~~~~~",
                       "~~~~~~~~~~~~~KKKKKKKKKKKKKKK~~~~~~~~~~~~~",
                       "~~~~~~~~~~~KKKKKKKKKKKKKKKKKKK~~~~~~~~~~~",
                       "~~~~~~~~~~KKKK~~~~~KKK~~~~~KKKK~~~~~~~~~~",
                       "~~~~~~~~KKKK~~~~~~~KKK~~~~~~~KKKK~~~~~~~~",
                       "~~~~~~~KKKK~~~~~~~~KKK~~~~~~~~KKKK~~~~~~~",
                       "~~~~~~KKKS~~~~~~~~~KKK~~~~~~~~~SKKK~~~~~~",
                       "~~~~~KKKSS~~~~~~~~~KKK~~~~~~~~~SSKKK~~~~~",
                       "~~~~~KKSSSS~~~~~~~~KKK~~~~~~~~SSSSKK~~~~~", 
                       "~~~~KKK~~SSS~~~~~~~KKK~~~~~~~SSS~~KKK~~~~", 
                       "~~~KKK~~~~SSS~~~~~KKKKK~~~~~SSS~~~~KKK~~~",
                       "~~~KK~~~~~~SSSSSKKKKKKKKKSSSSS~~~~~~KK~~~",
                       "~~KKK~~~~~~~SSKKKKNNNNNKKKKSS~~~~~~~KKK~~",
                       "~~KK~~~~~~~~SKKKNNNNNNNNNKKKS~~~~~~~~KK~~",
                       "~~KK~~~~~~~~SKKNNNNNNNNNNNKKS~~~~~~~~KK~~",
                       "~~KK~~~~~~~~KKNNNNNNNNNNNNNKK~~~~~~~~KK~~",
                       "~KKK~~~~~~~~KKNNNNNNNNNNNNNKK~~~~~~~~KKK~",
                       "~KKK~~~~~~~KKNNNNNNNNNNNNNNNKK~~~~~~~KKK~",
                       "KKKKKKKKKKKKKNNNNNNNNNNNNNNNKKKKKKKKKKKKK",
                       "KKKKKKKKKKKKKNNNNNNNNNNNNNNNKKKKKKKKKKKKK",
                       "KKKKKKKKKKKKKNNNNNNNNNNNNNNNKKKKKKKKKKKKK",
                       "~KKK~~~~~~~KKNNNNNNNNNNNNNNNKK~~~~~~~KKK~",
                       "~KKK~~~~~~~~KKNNNNNNNNNNNNNKK~~~~~~~~KKK~",
                       "~~KK~~~~~~~~KKNNNNNNNNNNNNNKK~~~~~~~~KK~~",
                       "~~KK~~~~~~~~SKKNNNNNNNNNNNKKS~~~~~~~~KK~~",
                       "~~KK~~~~~~~~SKKKNNNNNNNNNKKKS~~~~~~~~KK~~",
                       "~~KKK~~~~~~~SSKKKKNNNNNKKKKSS~~~~~~~KKK~~",
                       "~~~KK~~~~~~SSSSSKKKKKKKKKSSSSS~~~~~~KK~~~",
                       "~~~KKK~~~~SSS~~~~~KKKKK~~~~~SSS~~~~KKK~~~",
                       "~~~~KKK~~SSS~~~~~~~KKK~~~~~~~SSS~~KKK~~~~",
                       "~~~~~KKSSSS~~~~~~~~KKK~~~~~~~~SSSSKK~~~~~",
                       "~~~~~KKKSS~~~~~~~~~KKK~~~~~~~~~SSKKK~~~~~",
                       "~~~~~~KKKS~~~~~~~~~KKK~~~~~~~~~SKKK~~~~~~",
                       "~~~~~~~KKKK~~~~~~~~KKK~~~~~~~~KKKK~~~~~~~",
                       "~~~~~~~~KKKK~~~~~~~KKK~~~~~~~KKKK~~~~~~~~",
                       "~~~~~~~~~~KKKK~~~~~KKK~~~~~KKKK~~~~~~~~~~",
                       "~~~~~~~~~~~KKKKKKKKKKKKKKKKKKK~~~~~~~~~~~",
                       "~~~~~~~~~~~~~KKKKKKKKKKKKKKK~~~~~~~~~~~~~",
                       "~~~~~~~~~~~~~~~~~KKKKKKK~~~~~~~~~~~~~~~~~",
                       "~~~~~~~~~~~~~~~~~~~KKK~~~~~~~~~~~~~~~~~~~")

                .aisle("~~~~~~~~~~~~~~~~~~~~K~~~~~~~~~~~~~~~~~~~~",
                       "~~~~~~~~~~~~~~~~~~~SKS~~~~~~~~~~~~~~~~~~~",
                       "~~~~~~~~~~~~~~~~~~~SKS~~~~~~~~~~~~~~~~~~~",
                       "~~~~~~~~~~~~~~~~~~~SKS~~~~~~~~~~~~~~~~~~~",
                       "~~~~~~~~~~~~~~~~~~~SKS~~~~~~~~~~~~~~~~~~~",
                       "~~~~~~~~~~~~~~~~~~~~~~~~~~~~~~~~~~~~~~~~~",
                       "~~~~~~~~~~~~~~~~~~~~~~~~~~~~~~~~~~~~~~~~~",
                       "~~~~~~~~~~~~~~~~~~~~~~~~~~~~~~~~~~~~~~~~~",
                       "~~~~~~~~~~~~~~~~~~~~~~~~~~~~~~~~~~~~~~~~~",
                       "~~~~~~~~~~~~~~~~~~~~~~~~~~~~~~~~~~~~~~~~~",
                       "~~~~~~~~~~~~~~~~~~~~~~~~~~~~~~~~~~~~~~~~~",
                       "~~~~~~~~~~~~~~~~~~~~J~~~~~~~~~~~~~~~~~~~~",
                       "~~~~~~~~~~~~~~~~~~~KJK~~~~~~~~~~~~~~~~~~~",
                       "~~~~~~~~~~~~~~~~~~JKKKJ~~~~~~~~~~~~~~~~~~",
                       "~~~~~~~~~~~~~~~~~~~NNN~~~~~~~~~~~~~~~~~~~",
                       "~~~~~~~~~~~~~~~~~~~NNN~~~~~~~~~~~~~~~~~~~",
                       "~~~~~~~~~~~~~~~~~~~SSS~~~~~~~~~~~~~~~~~~~",
                       "~~~~~~~~~~~~~~~~~~SNNNS~~~~~~~~~~~~~~~~~~",
                       "~~~~~~~~~~~~~~~~~SNNNNNS~~~~~~~~~~~~~~~~~",
                       "~SSSS~~~~~~~~~NNSNNNNNNNSNN~~~~~~~~~SSSS~",
                       "KKKKK~~~~~~~SSNNSNNNNNNNSNNSS~~~~~~~KKKKK",
                       "~SSSS~~~~~~~~~NNSNNNNNNNSNN~~~~~~~~~SSSS~",
                       "~~~~~~~~~~~~~~~~~SNNNNNS~~~~~~~~~~~~~~~~~",
                       "~~~~~~~~~~~~~~~~~~SNNNS~~~~~~~~~~~~~~~~~~",
                       "~~~~~~~~~~~~~~~~~~~SSS~~~~~~~~~~~~~~~~~~~",
                       "~~~~~~~~~~~~~~~~~~~NNN~~~~~~~~~~~~~~~~~~~",
                       "~~~~~~~~~~~~~~~~~~~NNN~~~~~~~~~~~~~~~~~~~",
                       "~~~~~~~~~~~~~~~~~~JKKKJ~~~~~~~~~~~~~~~~~~",
                       "~~~~~~~~~~~~~~~~~~~KJK~~~~~~~~~~~~~~~~~~~",
                       "~~~~~~~~~~~~~~~~~~~~J~~~~~~~~~~~~~~~~~~~~",
                       "~~~~~~~~~~~~~~~~~~~~~~~~~~~~~~~~~~~~~~~~~",
                       "~~~~~~~~~~~~~~~~~~~~~~~~~~~~~~~~~~~~~~~~~",
                       "~~~~~~~~~~~~~~~~~~~~~~~~~~~~~~~~~~~~~~~~~",
                       "~~~~~~~~~~~~~~~~~~~~~~~~~~~~~~~~~~~~~~~~~",
                       "~~~~~~~~~~~~~~~~~~~~~~~~~~~~~~~~~~~~~~~~~",
                       "~~~~~~~~~~~~~~~~~~~~~~~~~~~~~~~~~~~~~~~~~",
                       "~~~~~~~~~~~~~~~~~~~SKS~~~~~~~~~~~~~~~~~~~",
                       "~~~~~~~~~~~~~~~~~~~SKS~~~~~~~~~~~~~~~~~~~",
                       "~~~~~~~~~~~~~~~~~~~SKS~~~~~~~~~~~~~~~~~~~",
                       "~~~~~~~~~~~~~~~~~~~SCS~~~~~~~~~~~~~~~~~~~",
                       "~~~~~~~~~~~~~~~~~~~J~J~~~~~~~~~~~~~~~~~~~")

                .aisle("~~~~~~~~~~~~~~~~~~~~~~~~~~~~~~~~~~~~~~~~~", 
                       "~~~~~~~~~~~~~~~~~~~~K~~~~~~~~~~~~~~~~~~~~",
                       "~~~~~~~~~~~~~~~~~~~~K~~~~~~~~~~~~~~~~~~~~",
                       "~~~~~~~~~~~~~~~~~~~SKS~~~~~~~~~~~~~~~~~~~",
                       "~~~~~~~~~~~~~~~~~~~SKS~~~~~~~~~~~~~~~~~~~",
                       "~~~~~~~~~~~~~~~~~~~SKS~~~~~~~~~~~~~~~~~~~",
                       "~~~~~~~~~~~~~~~~~~~SKS~~~~~~~~~~~~~~~~~~~",
                       "~~~~~~~~~~~~~~~~~~~~~~~~~~~~~~~~~~~~~~~~~",
                       "~~~~~~~~~~~~~~~~~~~~~~~~~~~~~~~~~~~~~~~~~",
                       "~~~~~~~~~~~~~~~~~~~~~~~~~~~~~~~~~~~~~~~~~",
                       "~~~~~~~~~~~~~~~~~~~~~~~~~~~~~~~~~~~~~~~~~",
                       "~~~~~~~~~~~~~~~~~~~~~~~~~~~~~~~~~~~~~~~~~",
                       "~~~~~~~~~~~~~~~~~~~~~~~~~~~~~~~~~~~~~~~~~",
                       "~~~~~~~~~~~~~~~~~~JKKKJ~~~~~~~~~~~~~~~~~~",
                       "~~~~~~~~~~~~~~~~~~~~N~~~~~~~~~~~~~~~~~~~~",
                       "~~~~~~~~~~~~~~~~~~~NNN~~~~~~~~~~~~~~~~~~~",
                       "~~~~~~~~~~~~~~~~~~~S~S~~~~~~~~~~~~~~~~~~~",
                       "~~~~~~~~~~~~~~~~~~~NNN~~~~~~~~~~~~~~~~~~~",
                       "~~~~~~~~~~~~~~~~~~SNNNS~~~~~~~~~~~~~~~~~~",
                       "~~~SSSS~~~~~~~~NSNNTTTNNSN~~~~~~~~SSSS~~~",
                       "~KKKKKK~~~~~~SNN~NNTTTNN~NNS~~~~~~KKKKKK~",
                       "~~~SSSS~~~~~~~~NSNNTTTNNSN~~~~~~~~SSSS~~~",
                       "~~~~~~~~~~~~~~~~~~SNNNS~~~~~~~~~~~~~~~~~~",
                       "~~~~~~~~~~~~~~~~~~~NNN~~~~~~~~~~~~~~~~~~~",
                       "~~~~~~~~~~~~~~~~~~~S~S~~~~~~~~~~~~~~~~~~~",
                       "~~~~~~~~~~~~~~~~~~~NNN~~~~~~~~~~~~~~~~~~~",
                       "~~~~~~~~~~~~~~~~~~~~N~~~~~~~~~~~~~~~~~~~~",
                       "~~~~~~~~~~~~~~~~~~JKKKJ~~~~~~~~~~~~~~~~~~",
                       "~~~~~~~~~~~~~~~~~~~~~~~~~~~~~~~~~~~~~~~~~",
                       "~~~~~~~~~~~~~~~~~~~~~~~~~~~~~~~~~~~~~~~~~",
                       "~~~~~~~~~~~~~~~~~~~~~~~~~~~~~~~~~~~~~~~~~",
                       "~~~~~~~~~~~~~~~~~~~~~~~~~~~~~~~~~~~~~~~~~",
                       "~~~~~~~~~~~~~~~~~~~~~~~~~~~~~~~~~~~~~~~~~",
                       "~~~~~~~~~~~~~~~~~~~~~~~~~~~~~~~~~~~~~~~~~",
                       "~~~~~~~~~~~~~~~~~~~SKS~~~~~~~~~~~~~~~~~~~",
                       "~~~~~~~~~~~~~~~~~~~SKS~~~~~~~~~~~~~~~~~~~",
                       "~~~~~~~~~~~~~~~~~~~SKS~~~~~~~~~~~~~~~~~~~",
                       "~~~~~~~~~~~~~~~~~~~SKS~~~~~~~~~~~~~~~~~~~",
                       "~~~~~~~~~~~~~~~~~~~~K~~~~~~~~~~~~~~~~~~~~",
                       "~~~~~~~~~~~~~~~~~~~JKJ~~~~~~~~~~~~~~~~~~~",
                       "~~~~~~~~~~~~~~~~~~~~~~~~~~~~~~~~~~~~~~~~~")

                .aisle("~~~~~~~~~~~~~~~~~~~~~~~~~~~~~~~~~~~~~~~~~",
                       "~~~~~~~~~~~~~~~~~~~~~~~~~~~~~~~~~~~~~~~~~",
                       "~~~~~~~~~~~~~~~~~~~~~~~~~~~~~~~~~~~~~~~~~",
                       "~~~~~~~~~~~~~~~~~~~~K~~~~~~~~~~~~~~~~~~~~",
                       "~~~~~~~~~~~~~~~~~~~~K~~~~~~~~~~~~~~~~~~~~",
                       "~~~~~~~~~~~~~~~~~~~SKS~~~~~~~~~~~~~~~~~~~",
                       "~~~~~~~~~~~~~~~~~~~SKS~~~~~~~~~~~~~~~~~~~",
                       "~~~~~~~~~~~~~~~~~~~SKS~~~~~~~~~~~~~~~~~~~",
                       "~~~~~~~~~~~~~~~~~~~SKS~~~~~~~~~~~~~~~~~~~",
                       "~~~~~~~~~~~~~~~~~~~~~~~~~~~~~~~~~~~~~~~~~",
                       "~~~~~~~~~~~~~~~~~~~~~~~~~~~~~~~~~~~~~~~~~",
                       "~~~~~~~~~~~~~~~~~~~~~~~~~~~~~~~~~~~~~~~~~",
                       "~~~~~~~~~~~~~~~~~~~~~~~~~~~~~~~~~~~~~~~~~",
                       "~~~~~~~~~~~~~~~~~~~J~J~~~~~~~~~~~~~~~~~~~",
                       "~~~~~~~~~~~~~~~~~~~~S~~~~~~~~~~~~~~~~~~~~",
                       "~~~~~~~~~~~~~~~~~~~~N~~~~~~~~~~~~~~~~~~~~",
                       "~~~~~~~~~~~~~~~~~~~S~S~~~~~~~~~~~~~~~~~~~",
                       "~~~~~~~~~~~~~~~~~~~NNN~~~~~~~~~~~~~~~~~~~",
                       "~~~~~~~~~~~~~~~~~~S~~~S~~~~~~~~~~~~~~~~~~",
                       "~~~~~SSSS~~~~~~~SN~NNN~NS~~~~~~~SSSS~~~~~",
                       "~~~KKKKKK~~~~~SN~N~NUN~N~NS~~~~~KKKKKK~~~",
                       "~~~~~SSSS~~~~~~~SN~NNN~NS~~~~~~~SSSS~~~~~",
                       "~~~~~~~~~~~~~~~~~~S~~~S~~~~~~~~~~~~~~~~~~",
                       "~~~~~~~~~~~~~~~~~~~NNN~~~~~~~~~~~~~~~~~~~",
                       "~~~~~~~~~~~~~~~~~~~S~S~~~~~~~~~~~~~~~~~~~",
                       "~~~~~~~~~~~~~~~~~~~~N~~~~~~~~~~~~~~~~~~~~",
                       "~~~~~~~~~~~~~~~~~~~~S~~~~~~~~~~~~~~~~~~~~",
                       "~~~~~~~~~~~~~~~~~~~J~J~~~~~~~~~~~~~~~~~~~",
                       "~~~~~~~~~~~~~~~~~~~~~~~~~~~~~~~~~~~~~~~~~",
                       "~~~~~~~~~~~~~~~~~~~~~~~~~~~~~~~~~~~~~~~~~",
                       "~~~~~~~~~~~~~~~~~~~~~~~~~~~~~~~~~~~~~~~~~",
                       "~~~~~~~~~~~~~~~~~~~~~~~~~~~~~~~~~~~~~~~~~",
                       "~~~~~~~~~~~~~~~~~~~SKS~~~~~~~~~~~~~~~~~~~",
                       "~~~~~~~~~~~~~~~~~~~SKS~~~~~~~~~~~~~~~~~~~",
                       "~~~~~~~~~~~~~~~~~~~SKS~~~~~~~~~~~~~~~~~~~",
                       "~~~~~~~~~~~~~~~~~~~SKS~~~~~~~~~~~~~~~~~~~",
                       "~~~~~~~~~~~~~~~~~~~~K~~~~~~~~~~~~~~~~~~~~",
                       "~~~~~~~~~~~~~~~~~~~~K~~~~~~~~~~~~~~~~~~~~",
                       "~~~~~~~~~~~~~~~~~~~~~~~~~~~~~~~~~~~~~~~~~",
                       "~~~~~~~~~~~~~~~~~~~~~~~~~~~~~~~~~~~~~~~~~",
                       "~~~~~~~~~~~~~~~~~~~~~~~~~~~~~~~~~~~~~~~~~")

                .aisle("~~~~~~~~~~~~~~~~~~~~~~~~~~~~~~~~~~~~~~~~~",
                       "~~~~~~~~~~~~~~~~~~~~~~~~~~~~~~~~~~~~~~~~~",
                       "~~~~~~~~~~~~~~~~~~~~~~~~~~~~~~~~~~~~~~~~~",
                       "~~~~~~~~~~~~~~~~~~~~~~~~~~~~~~~~~~~~~~~~~",
                       "~~~~~~~~~~~~~~~~~~~~~~~~~~~~~~~~~~~~~~~~~",
                       "~~~~~~~~~~~~~~~~~~~~K~~~~~~~~~~~~~~~~~~~~",
                       "~~~~~~~~~~~~~~~~~~~~K~~~~~~~~~~~~~~~~~~~~",
                       "~~~~~~~~~~~~~~~~~~~SKS~~~~~~~~~~~~~~~~~~~",
                       "~~~~~~~~~~~~~~~~~~~SKS~~~~~~~~~~~~~~~~~~~",
                       "~~~~~~~~~~~~~~~~~~~SKS~~~~~~~~~~~~~~~~~~~",
                       "~~~~~~~~~~~~~~~~~~~~~~~~~~~~~~~~~~~~~~~~~",
                       "~~~~~~~~~~~~~~~~~~~~~~~~~~~~~~~~~~~~~~~~~",
                       "~~~~~~~~~~~~~~~~~~~~~~~~~~~~~~~~~~~~~~~~~",
                       "~~~~~~~~~~~~~~~~~~~~~~~~~~~~~~~~~~~~~~~~~",
                       "~~~~~~~~~~~~~~~~~~~~~~~~~~~~~~~~~~~~~~~~~",
                       "~~~~~~~~~~~~~~~~~~~~S~~~~~~~~~~~~~~~~~~~~",
                       "~~~~~~~~~~~~~~~~~~~~N~~~~~~~~~~~~~~~~~~~~",
                       "~~~~~~~~~~~~~~~~~~~NNN~~~~~~~~~~~~~~~~~~~",
                       "~~~~~~~~~~~~~~~~~~S~~~S~~~~~~~~~~~~~~~~~~",
                       "~~~~~~~SSS~~~~~~~N~SDS~N~~~~~~~SSS~~~~~~~",
                       "~~~~~KKKKK~~~~~SNN~DSD~NNS~~~~~KKKKK~~~~~",
                       "~~~~~~~SSS~~~~~~~N~SDS~N~~~~~~~SSS~~~~~~~",
                       "~~~~~~~~~~~~~~~~~~S~~~S~~~~~~~~~~~~~~~~~~",
                       "~~~~~~~~~~~~~~~~~~~NNN~~~~~~~~~~~~~~~~~~~",
                       "~~~~~~~~~~~~~~~~~~~~N~~~~~~~~~~~~~~~~~~~~",
                       "~~~~~~~~~~~~~~~~~~~~S~~~~~~~~~~~~~~~~~~~~",
                       "~~~~~~~~~~~~~~~~~~~~~~~~~~~~~~~~~~~~~~~~~",
                       "~~~~~~~~~~~~~~~~~~~~~~~~~~~~~~~~~~~~~~~~~",
                       "~~~~~~~~~~~~~~~~~~~~~~~~~~~~~~~~~~~~~~~~~",
                       "~~~~~~~~~~~~~~~~~~~~~~~~~~~~~~~~~~~~~~~~~",
                       "~~~~~~~~~~~~~~~~~~~~~~~~~~~~~~~~~~~~~~~~~",
                       "~~~~~~~~~~~~~~~~~~~SKS~~~~~~~~~~~~~~~~~~~",
                       "~~~~~~~~~~~~~~~~~~~SKS~~~~~~~~~~~~~~~~~~~",
                       "~~~~~~~~~~~~~~~~~~~SKS~~~~~~~~~~~~~~~~~~~",
                       "~~~~~~~~~~~~~~~~~~~~K~~~~~~~~~~~~~~~~~~~~",
                       "~~~~~~~~~~~~~~~~~~~~K~~~~~~~~~~~~~~~~~~~~",
                       "~~~~~~~~~~~~~~~~~~~~~~~~~~~~~~~~~~~~~~~~~",
                       "~~~~~~~~~~~~~~~~~~~~~~~~~~~~~~~~~~~~~~~~~",
                       "~~~~~~~~~~~~~~~~~~~~~~~~~~~~~~~~~~~~~~~~~",
                       "~~~~~~~~~~~~~~~~~~~~~~~~~~~~~~~~~~~~~~~~~",
                       "~~~~~~~~~~~~~~~~~~~~~~~~~~~~~~~~~~~~~~~~~")
                
                .aisle("~~~~~~~~~~~~~~~~~~~~~~~~~~~~~~~~~~~~~~~~~",
                       "~~~~~~~~~~~~~~~~~~~~~~~~~~~~~~~~~~~~~~~~~",
                       "~~~~~~~~~~~~~~~~~~~~~~~~~~~~~~~~~~~~~~~~~",
                       "~~~~~~~~~~~~~~~~~~~~~~~~~~~~~~~~~~~~~~~~~",
                       "~~~~~~~~~~~~~~~~~~~~~~~~~~~~~~~~~~~~~~~~~",
                       "~~~~~~~~~~~~~~~~~~~~~~~~~~~~~~~~~~~~~~~~~",
                       "~~~~~~~~~~~~~~~~~~~~~~~~~~~~~~~~~~~~~~~~~",
                       "~~~~~~~~~~~~~~~~~~~~K~~~~~~~~~~~~~~~~~~~~",
                       "~~~~~~~~~~~~~~~~~~~~K~~~~~~~~~~~~~~~~~~~~",
                       "~~~~~~~~~~~~~~~~~~~SKS~~~~~~~~~~~~~~~~~~~",
                       "~~~~~~~~~~~~~~~~~~~SKS~~~~~~~~~~~~~~~~~~~",
                       "~~~~~~~~~~~~~~~~~~~~~~~~~~~~~~~~~~~~~~~~~",
                       "~~~~~~~~~~~~~~~~~~~~~~~~~~~~~~~~~~~~~~~~~",
                       "~~~~~~~~~~~~~~~~~~~~~~~~~~~~~~~~~~~~~~~~~",
                       "~~~~~~~~~~~~~~~~~~~~~~~~~~~~~~~~~~~~~~~~~",
                       "~~~~~~~~~~~~~~~~~~~~~~~~~~~~~~~~~~~~~~~~~",
                       "~~~~~~~~~~~~~~~~~~~~S~~~~~~~~~~~~~~~~~~~~",
                       "~~~~~~~~~~~~~~~~~~~SNS~~~~~~~~~~~~~~~~~~~",
                       "~~~~~~~~~~~~~~~~~~S~~~S~~~~~~~~~~~~~~~~~~",
                       "~~~~~~~~~SS~~~~~~S~~D~~S~~~~~~SS~~~~~~~~~",
                       "~~~~~~~KKKK~~~~~SN~DSD~NS~~~~~KKKK~~~~~~~",
                       "~~~~~~~~~SS~~~~~~S~~D~~S~~~~~~SS~~~~~~~~~",
                       "~~~~~~~~~~~~~~~~~~S~~~S~~~~~~~~~~~~~~~~~~",
                       "~~~~~~~~~~~~~~~~~~~SNS~~~~~~~~~~~~~~~~~~~",
                       "~~~~~~~~~~~~~~~~~~~~S~~~~~~~~~~~~~~~~~~~~",
                       "~~~~~~~~~~~~~~~~~~~~~~~~~~~~~~~~~~~~~~~~~",
                       "~~~~~~~~~~~~~~~~~~~~~~~~~~~~~~~~~~~~~~~~~",
                       "~~~~~~~~~~~~~~~~~~~~~~~~~~~~~~~~~~~~~~~~~",
                       "~~~~~~~~~~~~~~~~~~~~~~~~~~~~~~~~~~~~~~~~~",
                       "~~~~~~~~~~~~~~~~~~~~~~~~~~~~~~~~~~~~~~~~~",
                       "~~~~~~~~~~~~~~~~~~~SKS~~~~~~~~~~~~~~~~~~~",
                       "~~~~~~~~~~~~~~~~~~~SKS~~~~~~~~~~~~~~~~~~~",
                       "~~~~~~~~~~~~~~~~~~~~K~~~~~~~~~~~~~~~~~~~~",
                       "~~~~~~~~~~~~~~~~~~~~K~~~~~~~~~~~~~~~~~~~~",
                       "~~~~~~~~~~~~~~~~~~~~~~~~~~~~~~~~~~~~~~~~~",
                       "~~~~~~~~~~~~~~~~~~~~~~~~~~~~~~~~~~~~~~~~~",
                       "~~~~~~~~~~~~~~~~~~~~~~~~~~~~~~~~~~~~~~~~~",
                       "~~~~~~~~~~~~~~~~~~~~~~~~~~~~~~~~~~~~~~~~~",
                       "~~~~~~~~~~~~~~~~~~~~~~~~~~~~~~~~~~~~~~~~~",
                       "~~~~~~~~~~~~~~~~~~~~~~~~~~~~~~~~~~~~~~~~~",
                       "~~~~~~~~~~~~~~~~~~~~~~~~~~~~~~~~~~~~~~~~~")

                .aisle("~~~~~~~~~~~~~~~~~~~~~~~~~~~~~~~~~~~~~~~~~",
                       "~~~~~~~~~~~~~~~~~~~~~~~~~~~~~~~~~~~~~~~~~",
                       "~~~~~~~~~~~~~~~~~~~~~~~~~~~~~~~~~~~~~~~~~",
                       "~~~~~~~~~~~~~~~~~~~~~~~~~~~~~~~~~~~~~~~~~",
                       "~~~~~~~~~~~~~~~~~~~~~~~~~~~~~~~~~~~~~~~~~",
                       "~~~~~~~~~~~~~~~~~~~~~~~~~~~~~~~~~~~~~~~~~",
                       "~~~~~~~~~~~~~~~~~~~~~~~~~~~~~~~~~~~~~~~~~",
                       "~~~~~~~~~~~~~~~~~~~~~~~~~~~~~~~~~~~~~~~~~",
                       "~~~~~~~~~~~~~~~~~~~~~~~~~~~~~~~~~~~~~~~~~",
                       "~~~~~~~~~~~~~~~~~~~~K~~~~~~~~~~~~~~~~~~~~",
                       "~~~~~~~~~~~~~~~~~~~SKS~~~~~~~~~~~~~~~~~~~",
                       "~~~~~~~~~~~~~~~~~~~SKS~~~~~~~~~~~~~~~~~~~",
                       "~~~~~~~~~~~~~~~~~~~~~~~~~~~~~~~~~~~~~~~~~",
                       "~~~~~~~~~~~~~~~~~~~~~~~~~~~~~~~~~~~~~~~~~",
                       "~~~~~~~~~~~~~~~~~~~~~~~~~~~~~~~~~~~~~~~~~",
                       "~~~~~~~~~~~~~~~~~~~~~~~~~~~~~~~~~~~~~~~~~",
                       "~~~~~~~~~~~~~~~~~~~~S~~~~~~~~~~~~~~~~~~~~",
                       "~~~~~~~~~~~~~~~~~~~SNS~~~~~~~~~~~~~~~~~~~",
                       "~~~~~~~~~~~~~~~~~~S~~~S~~~~~~~~~~~~~~~~~~",
                       "~~~~~~~~~~SS~~~~~S~~D~~S~~~~~SS~~~~~~~~~~",
                       "~~~~~~~~~KKK~~~~SN~DSD~NS~~~~KKK~~~~~~~~~",
                       "~~~~~~~~~~SS~~~~~S~~D~~S~~~~~SS~~~~~~~~~~",
                       "~~~~~~~~~~~~~~~~~~S~~~S~~~~~~~~~~~~~~~~~~",
                       "~~~~~~~~~~~~~~~~~~~SNS~~~~~~~~~~~~~~~~~~~",
                       "~~~~~~~~~~~~~~~~~~~~S~~~~~~~~~~~~~~~~~~~~",
                       "~~~~~~~~~~~~~~~~~~~~~~~~~~~~~~~~~~~~~~~~~",
                       "~~~~~~~~~~~~~~~~~~~~~~~~~~~~~~~~~~~~~~~~~",
                       "~~~~~~~~~~~~~~~~~~~~~~~~~~~~~~~~~~~~~~~~~",
                       "~~~~~~~~~~~~~~~~~~~~~~~~~~~~~~~~~~~~~~~~~",
                       "~~~~~~~~~~~~~~~~~~~SKS~~~~~~~~~~~~~~~~~~~",
                       "~~~~~~~~~~~~~~~~~~~SKS~~~~~~~~~~~~~~~~~~~",
                       "~~~~~~~~~~~~~~~~~~~~K~~~~~~~~~~~~~~~~~~~~",
                       "~~~~~~~~~~~~~~~~~~~~~~~~~~~~~~~~~~~~~~~~~",
                       "~~~~~~~~~~~~~~~~~~~~~~~~~~~~~~~~~~~~~~~~~",
                       "~~~~~~~~~~~~~~~~~~~~~~~~~~~~~~~~~~~~~~~~~",
                       "~~~~~~~~~~~~~~~~~~~~~~~~~~~~~~~~~~~~~~~~~",
                       "~~~~~~~~~~~~~~~~~~~~~~~~~~~~~~~~~~~~~~~~~",
                       "~~~~~~~~~~~~~~~~~~~~~~~~~~~~~~~~~~~~~~~~~",
                       "~~~~~~~~~~~~~~~~~~~~~~~~~~~~~~~~~~~~~~~~~",
                       "~~~~~~~~~~~~~~~~~~~~~~~~~~~~~~~~~~~~~~~~~",
                       "~~~~~~~~~~~~~~~~~~~~~~~~~~~~~~~~~~~~~~~~~")

                .aisle("~~~~~~~~~~~~~~~~~~~~~~~~~~~~~~~~~~~~~~~~~",
                       "~~~~~~~~~~~~~~~~~~~~~~~~~~~~~~~~~~~~~~~~~",
                       "~~~~~~~~~~~~~~~~~~~~~~~~~~~~~~~~~~~~~~~~~",
                       "~~~~~~~~~~~~~~~~~~~~~~~~~~~~~~~~~~~~~~~~~",
                       "~~~~~~~~~~~~~~~~~~~~~~~~~~~~~~~~~~~~~~~~~",
                       "~~~~~~~~~~~~~~~~~~~~~~~~~~~~~~~~~~~~~~~~~",
                       "~~~~~~~~~~~~~~~~~~~~~~~~~~~~~~~~~~~~~~~~~",
                       "~~~~~~~~~~~~~~~~~~~~~~~~~~~~~~~~~~~~~~~~~",
                       "~~~~~~~~~~~~~~~~~~~~~~~~~~~~~~~~~~~~~~~~~",
                       "~~~~~~~~~~~~~~~~~~~~~~~~~~~~~~~~~~~~~~~~~",
                       "~~~~~~~~~~~~~~~~~~~~K~~~~~~~~~~~~~~~~~~~~",
                       "~~~~~~~~~~~~~~~~~~~SKS~~~~~~~~~~~~~~~~~~~",
                       "~~~~~~~~~~~~~~~~~~~SKS~~~~~~~~~~~~~~~~~~~",
                       "~~~~~~~~~~~~~~~~~~~~~~~~~~~~~~~~~~~~~~~~~",
                       "~~~~~~~~~~~~~~~~~~~~~~~~~~~~~~~~~~~~~~~~~",
                       "~~~~~~~~~~~~~~~~~~~~~~~~~~~~~~~~~~~~~~~~~",
                       "~~~~~~~~~~~~~~~~~~~~S~~~~~~~~~~~~~~~~~~~~",
                       "~~~~~~~~~~~~~~~~~~SSNSS~~~~~~~~~~~~~~~~~~",
                       "~~~~~~~~~~~~~~~~~SN~~~NS~~~~~~~~~~~~~~~~~",
                       "~~~~~~~~~~~SS~~~~S~~D~~S~~~~SS~~~~~~~~~~~",
                       "~~~~~~~~~~KKK~~~SN~DSD~NS~~~KKK~~~~~~~~~~",
                       "~~~~~~~~~~~SS~~~~S~~D~~S~~~~SS~~~~~~~~~~~",
                       "~~~~~~~~~~~~~~~~~SN~~~NS~~~~~~~~~~~~~~~~~",
                       "~~~~~~~~~~~~~~~~~~SSNSS~~~~~~~~~~~~~~~~~~",
                       "~~~~~~~~~~~~~~~~~~~~S~~~~~~~~~~~~~~~~~~~~",
                       "~~~~~~~~~~~~~~~~~~~~~~~~~~~~~~~~~~~~~~~~~",
                       "~~~~~~~~~~~~~~~~~~~~~~~~~~~~~~~~~~~~~~~~~",
                       "~~~~~~~~~~~~~~~~~~~~~~~~~~~~~~~~~~~~~~~~~",
                       "~~~~~~~~~~~~~~~~~~~SKS~~~~~~~~~~~~~~~~~~~",
                       "~~~~~~~~~~~~~~~~~~~SKS~~~~~~~~~~~~~~~~~~~",
                       "~~~~~~~~~~~~~~~~~~~~K~~~~~~~~~~~~~~~~~~~~",
                       "~~~~~~~~~~~~~~~~~~~~~~~~~~~~~~~~~~~~~~~~~",
                       "~~~~~~~~~~~~~~~~~~~~~~~~~~~~~~~~~~~~~~~~~",
                       "~~~~~~~~~~~~~~~~~~~~~~~~~~~~~~~~~~~~~~~~~",
                       "~~~~~~~~~~~~~~~~~~~~~~~~~~~~~~~~~~~~~~~~~",
                       "~~~~~~~~~~~~~~~~~~~~~~~~~~~~~~~~~~~~~~~~~",
                       "~~~~~~~~~~~~~~~~~~~~~~~~~~~~~~~~~~~~~~~~~",
                       "~~~~~~~~~~~~~~~~~~~~~~~~~~~~~~~~~~~~~~~~~",
                       "~~~~~~~~~~~~~~~~~~~~~~~~~~~~~~~~~~~~~~~~~",
                       "~~~~~~~~~~~~~~~~~~~~~~~~~~~~~~~~~~~~~~~~~",
                       "~~~~~~~~~~~~~~~~~~~~~~~~~~~~~~~~~~~~~~~~~")

                .aisle("~~~~~~~~~~~~~~~~~~~~~~~~~~~~~~~~~~~~~~~~~",
                       "~~~~~~~~~~~~~~~~~~~~~~~~~~~~~~~~~~~~~~~~~",
                       "~~~~~~~~~~~~~~~~~~~~~~~~~~~~~~~~~~~~~~~~~",
                       "~~~~~~~~~~~~~~~~~~~~~~~~~~~~~~~~~~~~~~~~~",
                       "~~~~~~~~~~~~~~~~~~~~~~~~~~~~~~~~~~~~~~~~~",
                       "~~~~~~~~~~~~~~~~~~~~~~~~~~~~~~~~~~~~~~~~~",
                       "~~~~~~~~~~~~~~~~~~~~~~~~~~~~~~~~~~~~~~~~~",
                       "~~~~~~~~~~~~~~~~~~~~~~~~~~~~~~~~~~~~~~~~~",
                       "~~~~~~~~~~~~~~~~~~~~~~~~~~~~~~~~~~~~~~~~~",
                       "~~~~~~~~~~~~~~~~~~~~~~~~~~~~~~~~~~~~~~~~~",
                       "~~~~~~~~~~~~~~~~~~~~~~~~~~~~~~~~~~~~~~~~~",
                       "~~~~~~~~~~~~~~~~~~~~K~~~~~~~~~~~~~~~~~~~~",
                       "~~~~~~~~~~~~~~~~~~~SKS~~~~~~~~~~~~~~~~~~~",
                       "~~~~~~~~~~~~~~~~~~~SKS~~~~~~~~~~~~~~~~~~~",
                       "~~~~~~~~~~~~~~~~~~~~~~~~~~~~~~~~~~~~~~~~~",
                       "~~~~~~~~~~~~~~~~~~~~~~~~~~~~~~~~~~~~~~~~~",
                       "~~~~~~~~~~~~~~~~~~~~~~~~~~~~~~~~~~~~~~~~~",
                       "~~~~~~~~~~~~~~~~~~~~S~~~~~~~~~~~~~~~~~~~~",
                       "~~~~~~~~~~~~~~~~~~S~~~S~~~~~~~~~~~~~~~~~~",
                       "~~~~~~~~~~~~SS~~~~~~D~~~~~~SS~~~~~~~~~~~~",
                       "~~~~~~~~~~~KKK~~~S~DSD~S~~~KKK~~~~~~~~~~~",
                       "~~~~~~~~~~~~SS~~~~~~D~~~~~~SS~~~~~~~~~~~~",
                       "~~~~~~~~~~~~~~~~~~S~~~S~~~~~~~~~~~~~~~~~~",
                       "~~~~~~~~~~~~~~~~~~~~S~~~~~~~~~~~~~~~~~~~~",
                       "~~~~~~~~~~~~~~~~~~~~~~~~~~~~~~~~~~~~~~~~~",
                       "~~~~~~~~~~~~~~~~~~~~~~~~~~~~~~~~~~~~~~~~~",
                       "~~~~~~~~~~~~~~~~~~~~~~~~~~~~~~~~~~~~~~~~~",
                       "~~~~~~~~~~~~~~~~~~~SKS~~~~~~~~~~~~~~~~~~~",
                       "~~~~~~~~~~~~~~~~~~~SKS~~~~~~~~~~~~~~~~~~~",
                       "~~~~~~~~~~~~~~~~~~~~K~~~~~~~~~~~~~~~~~~~~",
                       "~~~~~~~~~~~~~~~~~~~~~~~~~~~~~~~~~~~~~~~~~",
                       "~~~~~~~~~~~~~~~~~~~~~~~~~~~~~~~~~~~~~~~~~",
                       "~~~~~~~~~~~~~~~~~~~~~~~~~~~~~~~~~~~~~~~~~",
                       "~~~~~~~~~~~~~~~~~~~~~~~~~~~~~~~~~~~~~~~~~",
                       "~~~~~~~~~~~~~~~~~~~~~~~~~~~~~~~~~~~~~~~~~",
                       "~~~~~~~~~~~~~~~~~~~~~~~~~~~~~~~~~~~~~~~~~",
                       "~~~~~~~~~~~~~~~~~~~~~~~~~~~~~~~~~~~~~~~~~",
                       "~~~~~~~~~~~~~~~~~~~~~~~~~~~~~~~~~~~~~~~~~",
                       "~~~~~~~~~~~~~~~~~~~~~~~~~~~~~~~~~~~~~~~~~",
                       "~~~~~~~~~~~~~~~~~~~~~~~~~~~~~~~~~~~~~~~~~",
                       "~~~~~~~~~~~~~~~~~~~~~~~~~~~~~~~~~~~~~~~~~")                    

                .aisle("~~~~~~~~~~~~~~~~~~~~~~~~~~~~~~~~~~~~~~~~~",
                       "~~~~~~~~~~~~~~~~~~~~~~~~~~~~~~~~~~~~~~~~~",
                       "~~~~~~~~~~~~~~~~~~~~~~~~~~~~~~~~~~~~~~~~~",
                       "~~~~~~~~~~~~~~~~~~~~~~~~~~~~~~~~~~~~~~~~~",
                       "~~~~~~~~~~~~~~~~~~~~~~~~~~~~~~~~~~~~~~~~~",
                       "~~~~~~~~~~~~~~~~~~~~~~~~~~~~~~~~~~~~~~~~~",
                       "~~~~~~~~~~~~~~~~~~~~~~~~~~~~~~~~~~~~~~~~~",
                       "~~~~~~~~~~~~~~~~~~~~~~~~~~~~~~~~~~~~~~~~~",
                       "~~~~~~~~~~~~~~~~~~~~~~~~~~~~~~~~~~~~~~~~~",
                       "~~~~~~~~~~~~~~~~~~~~~~~~~~~~~~~~~~~~~~~~~",
                       "~~~~~~~~~~~~~~~~~~~~~~~~~~~~~~~~~~~~~~~~~",
                       "~~~~~~~~~~~~~~~~~~~~~~~~~~~~~~~~~~~~~~~~~",
                       "~~~~~~~~~~~~~~~~~~~~K~~~~~~~~~~~~~~~~~~~~",
                       "~~~~~~~~~~~~~~~~~~~SKS~~~~~~~~~~~~~~~~~~~",
                       "~~~~~~~~~~~~~~~~~~~~~~~~~~~~~~~~~~~~~~~~~",
                       "~~~~~~~~~~~~~~~~~~~~~~~~~~~~~~~~~~~~~~~~~",
                       "~~~~~~~~~~~~~~~~~~~~~~~~~~~~~~~~~~~~~~~~~",
                       "~~~~~~~~~~~~~~~~~~~~S~~~~~~~~~~~~~~~~~~~~",
                       "~~~~~~~~~~~~~~~~~~S~~~S~~~~~~~~~~~~~~~~~~",
                       "~~~~~~~~~~~~~S~~~~~~D~~~~~~S~~~~~~~~~~~~~",
                       "~~~~~~~~~~~~KK~~~S~DSD~S~~~KK~~~~~~~~~~~~",
                       "~~~~~~~~~~~~~S~~~~~~D~~~~~~S~~~~~~~~~~~~~",
                       "~~~~~~~~~~~~~~~~~~S~~~S~~~~~~~~~~~~~~~~~~",
                       "~~~~~~~~~~~~~~~~~~~~S~~~~~~~~~~~~~~~~~~~~",
                       "~~~~~~~~~~~~~~~~~~~~~~~~~~~~~~~~~~~~~~~~~",
                       "~~~~~~~~~~~~~~~~~~~~~~~~~~~~~~~~~~~~~~~~~",
                       "~~~~~~~~~~~~~~~~~~~~~~~~~~~~~~~~~~~~~~~~~",
                       "~~~~~~~~~~~~~~~~~~~SKS~~~~~~~~~~~~~~~~~~~",
                       "~~~~~~~~~~~~~~~~~~~~K~~~~~~~~~~~~~~~~~~~~",
                       "~~~~~~~~~~~~~~~~~~~~~~~~~~~~~~~~~~~~~~~~~",
                       "~~~~~~~~~~~~~~~~~~~~~~~~~~~~~~~~~~~~~~~~~",
                       "~~~~~~~~~~~~~~~~~~~~~~~~~~~~~~~~~~~~~~~~~",
                       "~~~~~~~~~~~~~~~~~~~~~~~~~~~~~~~~~~~~~~~~~",
                       "~~~~~~~~~~~~~~~~~~~~~~~~~~~~~~~~~~~~~~~~~",
                       "~~~~~~~~~~~~~~~~~~~~~~~~~~~~~~~~~~~~~~~~~",
                       "~~~~~~~~~~~~~~~~~~~~~~~~~~~~~~~~~~~~~~~~~",
                       "~~~~~~~~~~~~~~~~~~~~~~~~~~~~~~~~~~~~~~~~~",
                       "~~~~~~~~~~~~~~~~~~~~~~~~~~~~~~~~~~~~~~~~~",
                       "~~~~~~~~~~~~~~~~~~~~~~~~~~~~~~~~~~~~~~~~~",
                       "~~~~~~~~~~~~~~~~~~~~~~~~~~~~~~~~~~~~~~~~~",
                       "~~~~~~~~~~~~~~~~~~~~~~~~~~~~~~~~~~~~~~~~~") 

                .aisle("~~~~~~~~~~~~~~~~~~~~~~~~~~~~~~~~~~~~~~~~~",
                       "~~~~~~~~~~~~~~~~~~~~~~~~~~~~~~~~~~~~~~~~~",
                       "~~~~~~~~~~~~~~~~~~~~~~~~~~~~~~~~~~~~~~~~~",
                       "~~~~~~~~~~~~~~~~~~~~~~~~~~~~~~~~~~~~~~~~~",
                       "~~~~~~~~~~~~~~~~~~~~~~~~~~~~~~~~~~~~~~~~~",
                       "~~~~~~~~~~~~~~~~~~~~~~~~~~~~~~~~~~~~~~~~~",
                       "~~~~~~~~~~~~~~~~~~~~~~~~~~~~~~~~~~~~~~~~~",
                       "~~~~~~~~~~~~~~~~~~~~~~~~~~~~~~~~~~~~~~~~~",
                       "~~~~~~~~~~~~~~~~~~~~~~~~~~~~~~~~~~~~~~~~~",
                       "~~~~~~~~~~~~~~~~~~~~~~~~~~~~~~~~~~~~~~~~~",
                       "~~~~~~~~~~~~~~~~~~~~~~~~~~~~~~~~~~~~~~~~~",
                       "~~~~~~~~~~~~~~~~~~~~~~~~~~~~~~~~~~~~~~~~~",
                       "~~~~~~~~~~~~~~~~~~~~~~~~~~~~~~~~~~~~~~~~~",
                       "~~~~~~~~~~~~~~~~~~~SKS~~~~~~~~~~~~~~~~~~~",
                       "~~~~~~~~~~~~~~~~~~~SKS~~~~~~~~~~~~~~~~~~~",
                       "~~~~~~~~~~~~~~~~~~~~~~~~~~~~~~~~~~~~~~~~~",
                       "~~~~~~~~~~~~~~~~~~~~~~~~~~~~~~~~~~~~~~~~~",
                       "~~~~~~~~~~~~~~~~~~~~S~~~~~~~~~~~~~~~~~~~~",
                       "~~~~~~~~~~~~~~~~~~S~~~S~~~~~~~~~~~~~~~~~~",
                       "~~~~~~~~~~~~~SS~~~~~D~~~~~SS~~~~~~~~~~~~~",
                       "~~~~~~~~~~~~~KK~~S~DSD~S~~KK~~~~~~~~~~~~~",
                       "~~~~~~~~~~~~~SS~~~~~D~~~~~SS~~~~~~~~~~~~~",
                       "~~~~~~~~~~~~~~~~~~S~~~S~~~~~~~~~~~~~~~~~~",
                       "~~~~~~~~~~~~~~~~~~~~S~~~~~~~~~~~~~~~~~~~~",
                       "~~~~~~~~~~~~~~~~~~~~~~~~~~~~~~~~~~~~~~~~~",
                       "~~~~~~~~~~~~~~~~~~~~~~~~~~~~~~~~~~~~~~~~~",
                       "~~~~~~~~~~~~~~~~~~~SKS~~~~~~~~~~~~~~~~~~~",
                       "~~~~~~~~~~~~~~~~~~~SKS~~~~~~~~~~~~~~~~~~~",
                       "~~~~~~~~~~~~~~~~~~~~~~~~~~~~~~~~~~~~~~~~~",
                       "~~~~~~~~~~~~~~~~~~~~~~~~~~~~~~~~~~~~~~~~~",
                       "~~~~~~~~~~~~~~~~~~~~~~~~~~~~~~~~~~~~~~~~~",
                       "~~~~~~~~~~~~~~~~~~~~~~~~~~~~~~~~~~~~~~~~~",
                       "~~~~~~~~~~~~~~~~~~~~~~~~~~~~~~~~~~~~~~~~~",
                       "~~~~~~~~~~~~~~~~~~~~~~~~~~~~~~~~~~~~~~~~~",
                       "~~~~~~~~~~~~~~~~~~~~~~~~~~~~~~~~~~~~~~~~~",
                       "~~~~~~~~~~~~~~~~~~~~~~~~~~~~~~~~~~~~~~~~~",
                       "~~~~~~~~~~~~~~~~~~~~~~~~~~~~~~~~~~~~~~~~~",
                       "~~~~~~~~~~~~~~~~~~~~~~~~~~~~~~~~~~~~~~~~~",
                       "~~~~~~~~~~~~~~~~~~~~~~~~~~~~~~~~~~~~~~~~~",
                       "~~~~~~~~~~~~~~~~~~~~~~~~~~~~~~~~~~~~~~~~~",
                       "~~~~~~~~~~~~~~~~~~~~~~~~~~~~~~~~~~~~~~~~~") 

                .aisle("~~~~~~~~~~~~~~~~~~~~~~~~~~~~~~~~~~~~~~~~~",
                       "~~~~~~~~~~~~~~~~~~~~~~~~~~~~~~~~~~~~~~~~~",
                       "~~~~~~~~~~~~~~~~~~~~~~~~~~~~~~~~~~~~~~~~~",
                       "~~~~~~~~~~~~~~~~~~~~~~~~~~~~~~~~~~~~~~~~~",
                       "~~~~~~~~~~~~~~~~~~~~~~~~~~~~~~~~~~~~~~~~~",
                       "~~~~~~~~~~~~~~~~~~~~~~~~~~~~~~~~~~~~~~~~~",
                       "~~~~~~~~~~~~~~~~~~~~~~~~~~~~~~~~~~~~~~~~~",
                       "~~~~~~~~~~~~~~~~~~~~~~~~~~~~~~~~~~~~~~~~~",
                       "~~~~~~~~~~~~~~~~~~~~~~~~~~~~~~~~~~~~~~~~~",
                       "~~~~~~~~~~~~~~~~~~~~~~~~~~~~~~~~~~~~~~~~~",
                       "~~~~~~~~~~~~~~~~~~~~~~~~~~~~~~~~~~~~~~~~~",
                       "~~~~~~~~~~~~~~~~~~~~~~~~~~~~~~~~~~~~~~~~~",
                       "~~~~~~~~~~~~~~~~~~~~~~~~~~~~~~~~~~~~~~~~~",
                       "~~~~~~~~~~~~~~~~~~~~K~~~~~~~~~~~~~~~~~~~~",
                       "~~~~~~~~~~~~~~~~~~~SKS~~~~~~~~~~~~~~~~~~~",
                       "~~~~~~~~~~~~~~~~~~~~~~~~~~~~~~~~~~~~~~~~~",
                       "~~~~~~~~~~~~~~~~~~~~~~~~~~~~~~~~~~~~~~~~~",
                       "~~~~~~~~~~~~~~~~~~~~S~~~~~~~~~~~~~~~~~~~~",
                       "~~~~~~~~~~~~~~~~~~S~~~S~~~~~~~~~~~~~~~~~~",
                       "~~~~~~~~~~~~~~S~~~~~D~~~~~S~~~~~~~~~~~~~~",
                       "~~~~~~~~~~~~~KK~~S~DSD~S~~KK~~~~~~~~~~~~~",
                       "~~~~~~~~~~~~~~S~~~~~D~~~~~S~~~~~~~~~~~~~~",
                       "~~~~~~~~~~~~~~~~~~S~~~S~~~~~~~~~~~~~~~~~~",
                       "~~~~~~~~~~~~~~~~~~~~S~~~~~~~~~~~~~~~~~~~~",
                       "~~~~~~~~~~~~~~~~~~~~~~~~~~~~~~~~~~~~~~~~~",
                       "~~~~~~~~~~~~~~~~~~~~~~~~~~~~~~~~~~~~~~~~~",
                       "~~~~~~~~~~~~~~~~~~~SKS~~~~~~~~~~~~~~~~~~~",
                       "~~~~~~~~~~~~~~~~~~~~K~~~~~~~~~~~~~~~~~~~~",
                       "~~~~~~~~~~~~~~~~~~~~~~~~~~~~~~~~~~~~~~~~~",
                       "~~~~~~~~~~~~~~~~~~~~~~~~~~~~~~~~~~~~~~~~~",
                       "~~~~~~~~~~~~~~~~~~~~~~~~~~~~~~~~~~~~~~~~~",
                       "~~~~~~~~~~~~~~~~~~~~~~~~~~~~~~~~~~~~~~~~~",
                       "~~~~~~~~~~~~~~~~~~~~~~~~~~~~~~~~~~~~~~~~~",
                       "~~~~~~~~~~~~~~~~~~~~~~~~~~~~~~~~~~~~~~~~~",
                       "~~~~~~~~~~~~~~~~~~~~~~~~~~~~~~~~~~~~~~~~~",
                       "~~~~~~~~~~~~~~~~~~~~~~~~~~~~~~~~~~~~~~~~~",
                       "~~~~~~~~~~~~~~~~~~~~~~~~~~~~~~~~~~~~~~~~~",
                       "~~~~~~~~~~~~~~~~~~~~~~~~~~~~~~~~~~~~~~~~~",
                       "~~~~~~~~~~~~~~~~~~~~~~~~~~~~~~~~~~~~~~~~~",
                       "~~~~~~~~~~~~~~~~~~~~~~~~~~~~~~~~~~~~~~~~~",
                       "~~~~~~~~~~~~~~~~~~~~~~~~~~~~~~~~~~~~~~~~~")

                .aisle("~~~~~~~~~~~~~~~~~~~~~~~~~~~~~~~~~~~~~~~~~",
                       "~~~~~~~~~~~~~~~~~~~~~~~~~~~~~~~~~~~~~~~~~",
                       "~~~~~~~~~~~~~~~~~~~~~~~~~~~~~~~~~~~~~~~~~",
                       "~~~~~~~~~~~~~~~~~~~~~~~~~~~~~~~~~~~~~~~~~",
                       "~~~~~~~~~~~~~~~~~~~~~~~~~~~~~~~~~~~~~~~~~",
                       "~~~~~~~~~~~~~~~~~~~~~~~~~~~~~~~~~~~~~~~~~",
                       "~~~~~~~~~~~~~~~~~~~~~~~~~~~~~~~~~~~~~~~~~",
                       "~~~~~~~~~~~~~~~~~~~~~~~~~~~~~~~~~~~~~~~~~",
                       "~~~~~~~~~~~~~~~~~~~~~~~~~~~~~~~~~~~~~~~~~",
                       "~~~~~~~~~~~~~~~~~~~~~~~~~~~~~~~~~~~~~~~~~",
                       "~~~~~~~~~~~~~~~~~~~~~~~~~~~~~~~~~~~~~~~~~",
                       "~~~~~~~~~~~~~~~~~~~~~~~~~~~~~~~~~~~~~~~~~",
                       "~~~~~~~~~~~~~~~~~~~~~~~~~~~~~~~~~~~~~~~~~",
                       "~~~~~~~~~~~~~~~~~~~~~~~~~~~~~~~~~~~~~~~~~",
                       "~~~~~~~~~~~~~~~~~~~SKS~~~~~~~~~~~~~~~~~~~",
                       "~~~~~~~~~~~~~~~~~~~SKS~~~~~~~~~~~~~~~~~~~",
                       "~~~~~~~~~~~~~~~~~~~~~~~~~~~~~~~~~~~~~~~~~",
                       "~~~~~~~~~~~~~~~~~~~~S~~~~~~~~~~~~~~~~~~~~",
                       "~~~~~~~~~~~~~~~~~~S~~~S~~~~~~~~~~~~~~~~~~",
                       "~~~~~~~~~~~~~~SS~~~~D~~~~SS~~~~~~~~~~~~~~",
                       "~~~~~~~~~~~~~~KK~S~DSD~S~KK~~~~~~~~~~~~~~",
                       "~~~~~~~~~~~~~~SS~~~~D~~~~SS~~~~~~~~~~~~~~",
                       "~~~~~~~~~~~~~~~~~~S~~~S~~~~~~~~~~~~~~~~~~",
                       "~~~~~~~~~~~~~~~~~~~~S~~~~~~~~~~~~~~~~~~~~",
                       "~~~~~~~~~~~~~~~~~~~~~~~~~~~~~~~~~~~~~~~~~",
                       "~~~~~~~~~~~~~~~~~~~SKS~~~~~~~~~~~~~~~~~~~",
                       "~~~~~~~~~~~~~~~~~~~SKS~~~~~~~~~~~~~~~~~~~",
                       "~~~~~~~~~~~~~~~~~~~~~~~~~~~~~~~~~~~~~~~~~",
                       "~~~~~~~~~~~~~~~~~~~~~~~~~~~~~~~~~~~~~~~~~",
                       "~~~~~~~~~~~~~~~~~~~~~~~~~~~~~~~~~~~~~~~~~",
                       "~~~~~~~~~~~~~~~~~~~~~~~~~~~~~~~~~~~~~~~~~",
                       "~~~~~~~~~~~~~~~~~~~~~~~~~~~~~~~~~~~~~~~~~",
                       "~~~~~~~~~~~~~~~~~~~~~~~~~~~~~~~~~~~~~~~~~",
                       "~~~~~~~~~~~~~~~~~~~~~~~~~~~~~~~~~~~~~~~~~",
                       "~~~~~~~~~~~~~~~~~~~~~~~~~~~~~~~~~~~~~~~~~",
                       "~~~~~~~~~~~~~~~~~~~~~~~~~~~~~~~~~~~~~~~~~",
                       "~~~~~~~~~~~~~~~~~~~~~~~~~~~~~~~~~~~~~~~~~",
                       "~~~~~~~~~~~~~~~~~~~~~~~~~~~~~~~~~~~~~~~~~",
                       "~~~~~~~~~~~~~~~~~~~~~~~~~~~~~~~~~~~~~~~~~",
                       "~~~~~~~~~~~~~~~~~~~~~~~~~~~~~~~~~~~~~~~~~",
                       "~~~~~~~~~~~~~~~~~~~~~~~~~~~~~~~~~~~~~~~~~")

                .aisle("~~~~~~~~~~~~~~~~~~~~~~~~~~~~~~~~~~~~~~~~~",
                       "~~~~~~~~~~~~~~~~~~~~~~~~~~~~~~~~~~~~~~~~~",
                       "~~~~~~~~~~~~~~~~~~~~~~~~~~~~~~~~~~~~~~~~~",
                       "~~~~~~~~~~~~~~~~~~~~~~~~~~~~~~~~~~~~~~~~~",
                       "~~~~~~~~~~~~~~~~~~~~~~~~~~~~~~~~~~~~~~~~~",
                       "~~~~~~~~~~~~~~~~~~~~~~~~~~~~~~~~~~~~~~~~~",
                       "~~~~~~~~~~~~~~~~~~~~~~~~~~~~~~~~~~~~~~~~~",
                       "~~~~~~~~~~~~~~~~~~~~~~~~~~~~~~~~~~~~~~~~~",
                       "~~~~~~~~~~~~~~~~~~~~~~~~~~~~~~~~~~~~~~~~~",
                       "~~~~~~~~~~~~~~~~~~~~~~~~~~~~~~~~~~~~~~~~~",
                       "~~~~~~~~~~~~~~~~~~~~~~~~~~~~~~~~~~~~~~~~~",
                       "~~~~~~~~~~~~~~~~~~~~~~~~~~~~~~~~~~~~~~~~~",
                       "~~~~~~~~~~~~~~~~~~~~~~~~~~~~~~~~~~~~~~~~~",
                       "~~~~~~~~~~~~~~~~~~~~~~~~~~~~~~~~~~~~~~~~~",
                       "~~~~~~~~~~~~~~~~~~~~K~~~~~~~~~~~~~~~~~~~~",
                       "~~~~~~~~~~~~~~~~~~~SKS~~~~~~~~~~~~~~~~~~~",
                       "~~~~~~~~~~~~~~~~~~~~~~~~~~~~~~~~~~~~~~~~~",
                       "~~~~~~~~~~~~~~~~~~~~S~~~~~~~~~~~~~~~~~~~~",
                       "~~~~~~~~~~~~~~~~~~S~~~S~~~~~~~~~~~~~~~~~~",
                       "~~~~~~~~~~~~~~~S~~~~D~~~~S~~~~~~~~~~~~~~~",
                       "~~~~~~~~~~~~~~KK~S~DSD~S~KK~~~~~~~~~~~~~~",
                       "~~~~~~~~~~~~~~~S~~~~D~~~~S~~~~~~~~~~~~~~~",
                       "~~~~~~~~~~~~~~~~~~S~~~S~~~~~~~~~~~~~~~~~~",
                       "~~~~~~~~~~~~~~~~~~~~S~~~~~~~~~~~~~~~~~~~~",
                       "~~~~~~~~~~~~~~~~~~~~~~~~~~~~~~~~~~~~~~~~~",
                       "~~~~~~~~~~~~~~~~~~~SKS~~~~~~~~~~~~~~~~~~~",
                       "~~~~~~~~~~~~~~~~~~~~K~~~~~~~~~~~~~~~~~~~~",
                       "~~~~~~~~~~~~~~~~~~~~~~~~~~~~~~~~~~~~~~~~~",
                       "~~~~~~~~~~~~~~~~~~~~~~~~~~~~~~~~~~~~~~~~~",
                       "~~~~~~~~~~~~~~~~~~~~~~~~~~~~~~~~~~~~~~~~~",
                       "~~~~~~~~~~~~~~~~~~~~~~~~~~~~~~~~~~~~~~~~~",
                       "~~~~~~~~~~~~~~~~~~~~~~~~~~~~~~~~~~~~~~~~~",
                       "~~~~~~~~~~~~~~~~~~~~~~~~~~~~~~~~~~~~~~~~~",
                       "~~~~~~~~~~~~~~~~~~~~~~~~~~~~~~~~~~~~~~~~~",
                       "~~~~~~~~~~~~~~~~~~~~~~~~~~~~~~~~~~~~~~~~~",
                       "~~~~~~~~~~~~~~~~~~~~~~~~~~~~~~~~~~~~~~~~~",
                       "~~~~~~~~~~~~~~~~~~~~~~~~~~~~~~~~~~~~~~~~~",
                       "~~~~~~~~~~~~~~~~~~~~~~~~~~~~~~~~~~~~~~~~~",
                       "~~~~~~~~~~~~~~~~~~~~~~~~~~~~~~~~~~~~~~~~~",
                       "~~~~~~~~~~~~~~~~~~~~~~~~~~~~~~~~~~~~~~~~~",
                       "~~~~~~~~~~~~~~~~~~~~~~~~~~~~~~~~~~~~~~~~~")

                .aisle("~~~~~~~~~~~~~~~~~~~~~~~~~~~~~~~~~~~~~~~~~",
                       "~~~~~~~~~~~~~~~~~~~~~~~~~~~~~~~~~~~~~~~~~",
                       "~~~~~~~~~~~~~~~~~~~~~~~~~~~~~~~~~~~~~~~~~",
                       "~~~~~~~~~~~~~~~~~~~~~~~~~~~~~~~~~~~~~~~~~",
                       "~~~~~~~~~~~~~~~~~~~~~~~~~~~~~~~~~~~~~~~~~",
                       "~~~~~~~~~~~~~~~~~~~~~~~~~~~~~~~~~~~~~~~~~",
                       "~~~~~~~~~~~~~~~~~~~~~~~~~~~~~~~~~~~~~~~~~",
                       "~~~~~~~~~~~~~~~~~~~~~~~~~~~~~~~~~~~~~~~~~",
                       "~~~~~~~~~~~~~~~~~~~~~~~~~~~~~~~~~~~~~~~~~",
                       "~~~~~~~~~~~~~~~~~~~~~~~~~~~~~~~~~~~~~~~~~",
                       "~~~~~~~~~~~~~~~~~~~~~~~~~~~~~~~~~~~~~~~~~",
                       "~~~~~~~~~~~~~~~~~~~~~~~~~~~~~~~~~~~~~~~~~",
                       "~~~~~~~~~~~~~~~~~~~~~~~~~~~~~~~~~~~~~~~~~",
                       "~~~~~~~~~~~~~~~~~~~~~~~~~~~~~~~~~~~~~~~~~",
                       "~~~~~~~~~~~~~~~~~~~~~~~~~~~~~~~~~~~~~~~~~",
                       "~~~~~~~~~~~~~~~~~~~SKS~~~~~~~~~~~~~~~~~~~",
                       "~~~~~~~~~~~~~~~~~~~SKS~~~~~~~~~~~~~~~~~~~",
                       "~~~~~~~~~~~~~~~~~KKNNNKK~~~~~~~~~~~~~~~~~",
                       "~~~~~~~~~~~~~~~~~KN~~~NK~~~~~~~~~~~~~~~~~",
                       "~~~~~~~~~~~~~~~SSN~~D~~NSS~~~~~~~~~~~~~~~",
                       "~~~~~~~~~~~~~~~KKN~DSD~NKK~~~~~~~~~~~~~~~",
                       "~~~~~~~~~~~~~~~SSN~~D~~NSS~~~~~~~~~~~~~~~",
                       "~~~~~~~~~~~~~~~~~KN~~~NK~~~~~~~~~~~~~~~~~",
                       "~~~~~~~~~~~~~~~~~KKNNNKK~~~~~~~~~~~~~~~~~",
                       "~~~~~~~~~~~~~~~~~~~SKS~~~~~~~~~~~~~~~~~~~",
                       "~~~~~~~~~~~~~~~~~~~SKS~~~~~~~~~~~~~~~~~~~",
                       "~~~~~~~~~~~~~~~~~~~~~~~~~~~~~~~~~~~~~~~~~",
                       "~~~~~~~~~~~~~~~~~~~~~~~~~~~~~~~~~~~~~~~~~",
                       "~~~~~~~~~~~~~~~~~~~~~~~~~~~~~~~~~~~~~~~~~",
                       "~~~~~~~~~~~~~~~~~~~~~~~~~~~~~~~~~~~~~~~~~",
                       "~~~~~~~~~~~~~~~~~~~~~~~~~~~~~~~~~~~~~~~~~",
                       "~~~~~~~~~~~~~~~~~~~~~~~~~~~~~~~~~~~~~~~~~",
                       "~~~~~~~~~~~~~~~~~~~~~~~~~~~~~~~~~~~~~~~~~",
                       "~~~~~~~~~~~~~~~~~~~~~~~~~~~~~~~~~~~~~~~~~",
                       "~~~~~~~~~~~~~~~~~~~~~~~~~~~~~~~~~~~~~~~~~",
                       "~~~~~~~~~~~~~~~~~~~~~~~~~~~~~~~~~~~~~~~~~",
                       "~~~~~~~~~~~~~~~~~~~~~~~~~~~~~~~~~~~~~~~~~",
                       "~~~~~~~~~~~~~~~~~~~~~~~~~~~~~~~~~~~~~~~~~",
                       "~~~~~~~~~~~~~~~~~~~~~~~~~~~~~~~~~~~~~~~~~",
                       "~~~~~~~~~~~~~~~~~~~~~~~~~~~~~~~~~~~~~~~~~",
                       "~~~~~~~~~~~~~~~~~~~~~~~~~~~~~~~~~~~~~~~~~")

                .aisle("~~~~~~~~~~~~~~~~~~~~~~~~~~~~~~~~~~~~~~~~~",
                       "~~~~~~~~~~~~~~~~~~~~~~~~~~~~~~~~~~~~~~~~~",
                       "~~~~~~~~~~~~~~~~~~~~~~~~~~~~~~~~~~~~~~~~~",
                       "~~~~~~~~~~~~~~~~~~~~~~~~~~~~~~~~~~~~~~~~~",
                       "~~~~~~~~~~~~~~~~~~~~~~~~~~~~~~~~~~~~~~~~~",
                       "~~~~~~~~~~~~~~~~~~~~~~~~~~~~~~~~~~~~~~~~~",
                       "~~~~~~~~~~~~~~~~~~~~~~~~~~~~~~~~~~~~~~~~~",
                       "~~~~~~~~~~~~~~~~~~~~~~~~~~~~~~~~~~~~~~~~~",
                       "~~~~~~~~~~~~~~~~~~~~~~~~~~~~~~~~~~~~~~~~~",
                       "~~~~~~~~~~~~~~~~~~~~~~~~~~~~~~~~~~~~~~~~~",
                       "~~~~~~~~~~~~~~~~~~~~~~~~~~~~~~~~~~~~~~~~~",
                       "~~~~~~~~~~~~~~~~~~~~~~~~~~~~~~~~~~~~~~~~~",
                       "~~~~~~~~~~~~~~~~~~~~~~~~~~~~~~~~~~~~~~~~~",
                       "~~~~~~~~~~~~~~~~~~~~~~~~~~~~~~~~~~~~~~~~~",
                       "~~~~~~~~~~~~~~~~~~~~~~~~~~~~~~~~~~~~~~~~~",
                       "~~~~~~~~~~~~~~~~~~~~K~~~~~~~~~~~~~~~~~~~~",
                       "~~~~~~~~~~~~~~~~~~~SKS~~~~~~~~~~~~~~~~~~~",
                       "~~~~~~~~~~~~~~~~~~~KKK~~~~~~~~~~~~~~~~~~~",
                       "~~~~~~~~~~~~~~~~~~S~~~S~~~~~~~~~~~~~~~~~~",
                       "~~~~~~~~~~~~~~~~SK~~D~~KS~~~~~~~~~~~~~~~~",
                       "~~~~~~~~~~~~~~~KKK~DSD~KKK~~~~~~~~~~~~~~~",
                       "~~~~~~~~~~~~~~~~SK~~D~~KS~~~~~~~~~~~~~~~~",
                       "~~~~~~~~~~~~~~~~~~S~~~S~~~~~~~~~~~~~~~~~~",
                       "~~~~~~~~~~~~~~~~~~~KKK~~~~~~~~~~~~~~~~~~~",
                       "~~~~~~~~~~~~~~~~~~~SKS~~~~~~~~~~~~~~~~~~~",
                       "~~~~~~~~~~~~~~~~~~~~K~~~~~~~~~~~~~~~~~~~~",
                       "~~~~~~~~~~~~~~~~~~~~~~~~~~~~~~~~~~~~~~~~~",
                       "~~~~~~~~~~~~~~~~~~~~~~~~~~~~~~~~~~~~~~~~~",
                       "~~~~~~~~~~~~~~~~~~~~~~~~~~~~~~~~~~~~~~~~~",
                       "~~~~~~~~~~~~~~~~~~~~~~~~~~~~~~~~~~~~~~~~~",
                       "~~~~~~~~~~~~~~~~~~~~~~~~~~~~~~~~~~~~~~~~~",
                       "~~~~~~~~~~~~~~~~~~~~~~~~~~~~~~~~~~~~~~~~~",
                       "~~~~~~~~~~~~~~~~~~~~~~~~~~~~~~~~~~~~~~~~~",
                       "~~~~~~~~~~~~~~~~~~~~~~~~~~~~~~~~~~~~~~~~~",
                       "~~~~~~~~~~~~~~~~~~~~~~~~~~~~~~~~~~~~~~~~~",
                       "~~~~~~~~~~~~~~~~~~~~~~~~~~~~~~~~~~~~~~~~~",
                       "~~~~~~~~~~~~~~~~~~~~~~~~~~~~~~~~~~~~~~~~~",
                       "~~~~~~~~~~~~~~~~~~~~~~~~~~~~~~~~~~~~~~~~~",
                       "~~~~~~~~~~~~~~~~~~~~~~~~~~~~~~~~~~~~~~~~~",
                       "~~~~~~~~~~~~~~~~~~~~~~~~~~~~~~~~~~~~~~~~~",
                       "~~~~~~~~~~~~~~~~~~~~~~~~~~~~~~~~~~~~~~~~~")

                .aisle("~~~~~~~~~~~~~~~~~~~~~~~~~~~~~~~~~~~~~~~~~",
                       "~~~~~~~~~~~~~~~~~~~~~~~~~~~~~~~~~~~~~~~~~",
                       "~~~~~~~~~~~~~~~~~~~~~~~~~~~~~~~~~~~~~~~~~",
                       "~~~~~~~~~~~~~~~~~~~~~~~~~~~~~~~~~~~~~~~~~",
                       "~~~~~~~~~~~~~~~~~~~~~~~~~~~~~~~~~~~~~~~~~",
                       "~~~~~~~~~~~~~~~~~~~~~~~~~~~~~~~~~~~~~~~~~",
                       "~~~~~~~~~~~~~~~~~~~~~~~~~~~~~~~~~~~~~~~~~",
                       "~~~~~~~~~~~~~~~~~~~~~~~~~~~~~~~~~~~~~~~~~",
                       "~~~~~~~~~~~~~~~~~~~~~~~~~~~~~~~~~~~~~~~~~",
                       "~~~~~~~~~~~~~~~~~~~~~~~~~~~~~~~~~~~~~~~~~",
                       "~~~~~~~~~~~~~~~~~~~~~~~~~~~~~~~~~~~~~~~~~",
                       "~~~~~~~~~~~~~~~~~~~~~~~~~~~~~~~~~~~~~~~~~",
                       "~~~~~~~~~~~~~~~~~~~~~~~~~~~~~~~~~~~~~~~~~",
                       "~~~~~~~~~~~~~~~~~~~~~~~~~~~~~~~~~~~~~~~~~",
                       "~~~~~~~~~~~~~~~~~~~~~~~~~~~~~~~~~~~~~~~~~",
                       "~~~~~~~~~~~~~~~~~~~~~~~~~~~~~~~~~~~~~~~~~",
                       "~~~~~~~~~~~~~~~~~~~SKS~~~~~~~~~~~~~~~~~~~",
                       "~~~~~~~~~~~~~~~~~~~S~S~~~~~~~~~~~~~~~~~~~",
                       "~~~~~~~~~~~~~~~~~~S~~~S~~~~~~~~~~~~~~~~~~",
                       "~~~~~~~~~~~~~~~~SS~~D~~SS~~~~~~~~~~~~~~~~",
                       "~~~~~~~~~~~~~~~~K~~DSD~~K~~~~~~~~~~~~~~~~",
                       "~~~~~~~~~~~~~~~~SS~~D~~SS~~~~~~~~~~~~~~~~",
                       "~~~~~~~~~~~~~~~~~~S~~~S~~~~~~~~~~~~~~~~~~",
                       "~~~~~~~~~~~~~~~~~~~S~S~~~~~~~~~~~~~~~~~~~",
                       "~~~~~~~~~~~~~~~~~~~SKS~~~~~~~~~~~~~~~~~~~",
                       "~~~~~~~~~~~~~~~~~~~~~~~~~~~~~~~~~~~~~~~~~",
                       "~~~~~~~~~~~~~~~~~~~~~~~~~~~~~~~~~~~~~~~~~",
                       "~~~~~~~~~~~~~~~~~~~~~~~~~~~~~~~~~~~~~~~~~",
                       "~~~~~~~~~~~~~~~~~~~~~~~~~~~~~~~~~~~~~~~~~",
                       "~~~~~~~~~~~~~~~~~~~~~~~~~~~~~~~~~~~~~~~~~",
                       "~~~~~~~~~~~~~~~~~~~~~~~~~~~~~~~~~~~~~~~~~",
                       "~~~~~~~~~~~~~~~~~~~~~~~~~~~~~~~~~~~~~~~~~",
                       "~~~~~~~~~~~~~~~~~~~~~~~~~~~~~~~~~~~~~~~~~",
                       "~~~~~~~~~~~~~~~~~~~~~~~~~~~~~~~~~~~~~~~~~",
                       "~~~~~~~~~~~~~~~~~~~~~~~~~~~~~~~~~~~~~~~~~",
                       "~~~~~~~~~~~~~~~~~~~~~~~~~~~~~~~~~~~~~~~~~",
                       "~~~~~~~~~~~~~~~~~~~~~~~~~~~~~~~~~~~~~~~~~",
                       "~~~~~~~~~~~~~~~~~~~~~~~~~~~~~~~~~~~~~~~~~",
                       "~~~~~~~~~~~~~~~~~~~~~~~~~~~~~~~~~~~~~~~~~",
                       "~~~~~~~~~~~~~~~~~~~~~~~~~~~~~~~~~~~~~~~~~",
                       "~~~~~~~~~~~~~~~~~~~~~~~~~~~~~~~~~~~~~~~~~")

                .aisle("~~~~~~~~~~~~~~~~~~~~~~~~~~~~~~~~~~~~~~~~~",
                       "~~~~~~~~~~~~~~~~~~~~~~~~~~~~~~~~~~~~~~~~~",
                       "~~~~~~~~~~~~~~~~~~~~~~~~~~~~~~~~~~~~~~~~~",
                       "~~~~~~~~~~~~~~~~~~~~~~~~~~~~~~~~~~~~~~~~~",
                       "~~~~~~~~~~~~~~~~~~~~~~~~~~~~~~~~~~~~~~~~~",
                       "~~~~~~~~~~~~~~~~~~~~~~~~~~~~~~~~~~~~~~~~~",
                       "~~~~~~~~~~~~~~~~~~~~~~~~~~~~~~~~~~~~~~~~~",
                       "~~~~~~~~~~~~~~~~~~~~~~~~~~~~~~~~~~~~~~~~~",
                       "~~~~~~~~~~~~~~~~~~~~~~~~~~~~~~~~~~~~~~~~~",
                       "~~~~~~~~~~~~~~~~~~~~~~~~~~~~~~~~~~~~~~~~~",
                       "~~~~~~~~~~~~~~~~~~~~~~~~~~~~~~~~~~~~~~~~~",
                       "~~~~~~~~~~~~~~~~~~~~~~~~~~~~~~~~~~~~~~~~~",
                       "~~~~~~~~~~~~~~~~~~~~~~~~~~~~~~~~~~~~~~~~~",
                       "~~~~~~~~~~~~~~~~~~~~~~~~~~~~~~~~~~~~~~~~~",
                       "~~~~~~~~~~~~~~~~~~~~~~~~~~~~~~~~~~~~~~~~~",
                       "~~~~~~~~~~~~~~~~~~~~~~~~~~~~~~~~~~~~~~~~~",
                       "~~~~~~~~~~~~~~~~~~~SKS~~~~~~~~~~~~~~~~~~~",
                       "~~~~~~~~~~~~~~~~~~~S~S~~~~~~~~~~~~~~~~~~~",
                       "~~~~~~~~~~~~~~~~~~S~~~S~~~~~~~~~~~~~~~~~~",
                       "~~~~~~~~~~~~~~~~SS~~D~~SS~~~~~~~~~~~~~~~~",
                       "~~~~~~~~~~~~~~~~K~~DSD~~K~~~~~~~~~~~~~~~~",
                       "~~~~~~~~~~~~~~~~SS~~D~~SS~~~~~~~~~~~~~~~~",
                       "~~~~~~~~~~~~~~~~~~S~~~S~~~~~~~~~~~~~~~~~~",
                       "~~~~~~~~~~~~~~~~~~~S~S~~~~~~~~~~~~~~~~~~~",
                       "~~~~~~~~~~~~~~~~~~~SKS~~~~~~~~~~~~~~~~~~~",
                       "~~~~~~~~~~~~~~~~~~~~~~~~~~~~~~~~~~~~~~~~~",
                       "~~~~~~~~~~~~~~~~~~~~~~~~~~~~~~~~~~~~~~~~~",
                       "~~~~~~~~~~~~~~~~~~~~~~~~~~~~~~~~~~~~~~~~~",
                       "~~~~~~~~~~~~~~~~~~~~~~~~~~~~~~~~~~~~~~~~~",
                       "~~~~~~~~~~~~~~~~~~~~~~~~~~~~~~~~~~~~~~~~~",
                       "~~~~~~~~~~~~~~~~~~~~~~~~~~~~~~~~~~~~~~~~~",
                       "~~~~~~~~~~~~~~~~~~~~~~~~~~~~~~~~~~~~~~~~~",
                       "~~~~~~~~~~~~~~~~~~~~~~~~~~~~~~~~~~~~~~~~~",
                       "~~~~~~~~~~~~~~~~~~~~~~~~~~~~~~~~~~~~~~~~~",
                       "~~~~~~~~~~~~~~~~~~~~~~~~~~~~~~~~~~~~~~~~~",
                       "~~~~~~~~~~~~~~~~~~~~~~~~~~~~~~~~~~~~~~~~~",
                       "~~~~~~~~~~~~~~~~~~~~~~~~~~~~~~~~~~~~~~~~~",
                       "~~~~~~~~~~~~~~~~~~~~~~~~~~~~~~~~~~~~~~~~~",
                       "~~~~~~~~~~~~~~~~~~~~~~~~~~~~~~~~~~~~~~~~~",
                       "~~~~~~~~~~~~~~~~~~~~~~~~~~~~~~~~~~~~~~~~~",
                       "~~~~~~~~~~~~~~~~~~~~~~~~~~~~~~~~~~~~~~~~~")

                .aisle("~~~~~~~~~~~~~~~~~~~~~~~~~~~~~~~~~~~~~~~~~",
                       "~~~~~~~~~~~~~~~~~~~~~~~~~~~~~~~~~~~~~~~~~",
                       "~~~~~~~~~~~~~~~~~~~~~~~~~~~~~~~~~~~~~~~~~",
                       "~~~~~~~~~~~~~~~~~~~~~~~~~~~~~~~~~~~~~~~~~",
                       "~~~~~~~~~~~~~~~~~~~~~~~~~~~~~~~~~~~~~~~~~",
                       "~~~~~~~~~~~~~~~~~~~~~~~~~~~~~~~~~~~~~~~~~",
                       "~~~~~~~~~~~~~~~~~~~~~~~~~~~~~~~~~~~~~~~~~",
                       "~~~~~~~~~~~~~~~~~~~~~~~~~~~~~~~~~~~~~~~~~",
                       "~~~~~~~~~~~~~~~~~~~~~~~~~~~~~~~~~~~~~~~~~",
                       "~~~~~~~~~~~~~~~~~~~~~~~~~~~~~~~~~~~~~~~~~",
                       "~~~~~~~~~~~~~~~~~~~~~~~~~~~~~~~~~~~~~~~~~",
                       "~~~~~~~~~~~~~~~~~~~~~~~~~~~~~~~~~~~~~~~~~",
                       "~~~~~~~~~~~~~~~~~~~~~~~~~~~~~~~~~~~~~~~~~",
                       "~~~~~~~~~~~~~~~~~~~~~~~~~~~~~~~~~~~~~~~~~",
                       "~~~~~~~~~~~~~~~~~~~~~~~~~~~~~~~~~~~~~~~~~",
                       "~~~~~~~~~~~~~~~~~~~~~~~~~~~~~~~~~~~~~~~~~",
                       "~~~~~~~~~~~~~~~~~~~~K~~~~~~~~~~~~~~~~~~~~",
                       "~~~~~~~~~~~~~~~~~~~S~S~~~~~~~~~~~~~~~~~~~",
                       "~~~~~~~~~~~~~~~~~~S~~~S~~~~~~~~~~~~~~~~~~",
                       "~~~~~~~~~~~~~~~~~S~~D~~S~~~~~~~~~~~~~~~~~",
                       "~~~~~~~~~~~~~~~~K~~DSD~~K~~~~~~~~~~~~~~~~",
                       "~~~~~~~~~~~~~~~~~S~~D~~S~~~~~~~~~~~~~~~~~",
                       "~~~~~~~~~~~~~~~~~~S~~~S~~~~~~~~~~~~~~~~~~",
                       "~~~~~~~~~~~~~~~~~~~S~S~~~~~~~~~~~~~~~~~~~",
                       "~~~~~~~~~~~~~~~~~~~~K~~~~~~~~~~~~~~~~~~~~",
                       "~~~~~~~~~~~~~~~~~~~~~~~~~~~~~~~~~~~~~~~~~",
                       "~~~~~~~~~~~~~~~~~~~~~~~~~~~~~~~~~~~~~~~~~",
                       "~~~~~~~~~~~~~~~~~~~~~~~~~~~~~~~~~~~~~~~~~",
                       "~~~~~~~~~~~~~~~~~~~~~~~~~~~~~~~~~~~~~~~~~",
                       "~~~~~~~~~~~~~~~~~~~~~~~~~~~~~~~~~~~~~~~~~",
                       "~~~~~~~~~~~~~~~~~~~~~~~~~~~~~~~~~~~~~~~~~",
                       "~~~~~~~~~~~~~~~~~~~~~~~~~~~~~~~~~~~~~~~~~",
                       "~~~~~~~~~~~~~~~~~~~~~~~~~~~~~~~~~~~~~~~~~",
                       "~~~~~~~~~~~~~~~~~~~~~~~~~~~~~~~~~~~~~~~~~",
                       "~~~~~~~~~~~~~~~~~~~~~~~~~~~~~~~~~~~~~~~~~",
                       "~~~~~~~~~~~~~~~~~~~~~~~~~~~~~~~~~~~~~~~~~",
                       "~~~~~~~~~~~~~~~~~~~~~~~~~~~~~~~~~~~~~~~~~",
                       "~~~~~~~~~~~~~~~~~~~~~~~~~~~~~~~~~~~~~~~~~",
                       "~~~~~~~~~~~~~~~~~~~~~~~~~~~~~~~~~~~~~~~~~",
                       "~~~~~~~~~~~~~~~~~~~~~~~~~~~~~~~~~~~~~~~~~",
                       "~~~~~~~~~~~~~~~~~~~~~~~~~~~~~~~~~~~~~~~~~")

                .aisle("~~~~~~~~~~~~~~~~~~~~~~~~~~~~~~~~~~~~~~~~~",
                       "~~~~~~~~~~~~~~~~~~~~~~~~~~~~~~~~~~~~~~~~~",
                       "~~~~~~~~~~~~~~~~~~~~~~~~~~~~~~~~~~~~~~~~~",
                       "~~~~~~~~~~~~~~~~~~~~~~~~~~~~~~~~~~~~~~~~~",
                       "~~~~~~~~~~~~~~~~~~~~~~~~~~~~~~~~~~~~~~~~~",
                       "~~~~~~~~~~~~~~~~~~~~~~~~~~~~~~~~~~~~~~~~~",
                       "~~~~~~~~~~~~~~~~~~~~~~~~~~~~~~~~~~~~~~~~~",
                       "~~~~~~~~~~~~~~~~~~~~~~~~~~~~~~~~~~~~~~~~~",
                       "~~~~~~~~~~~~~~~~~~~~~~~~~~~~~~~~~~~~~~~~~",
                       "~~~~~~~~~~~~~~~~~~~~~~~~~~~~~~~~~~~~~~~~~",
                       "~~~~~~~~~~~~~~~~~~~~~~~~~~~~~~~~~~~~~~~~~",
                       "~~~~~~~~~~~~~~~~~~~~~~~~~~~~~~~~~~~~~~~~~",
                       "~~~~~~~~~~~~~~~~~~~~~~~~~~~~~~~~~~~~~~~~~",
                       "~~~~~~~~~~~~~~~~~~~~~~~~~~~~~~~~~~~~~~~~~",
                       "~~~~~~~~~~~~~~~~~~~~~~~~~~~~~~~~~~~~~~~~~",
                       "~~~~~~~~~~~~~~~~~~~~~~~~~~~~~~~~~~~~~~~~~",
                       "~~~~~~~~~~~~~~~~~~~~K~~~~~~~~~~~~~~~~~~~~",
                       "~~~~~~~~~~~~~~~~~~~S~S~~~~~~~~~~~~~~~~~~~",
                       "~~~~~~~~~~~~~~~~~~S~~~S~~~~~~~~~~~~~~~~~~",
                       "~~~~~~~~~~~~~~~~~S~~D~~S~~~~~~~~~~~~~~~~~",
                       "~~~~~~~~~~~~~~~~K~~DSD~~K~~~~~~~~~~~~~~~~",
                       "~~~~~~~~~~~~~~~~~S~~D~~S~~~~~~~~~~~~~~~~~",
                       "~~~~~~~~~~~~~~~~~~S~~~S~~~~~~~~~~~~~~~~~~",
                       "~~~~~~~~~~~~~~~~~~~S~S~~~~~~~~~~~~~~~~~~~",
                       "~~~~~~~~~~~~~~~~~~~~K~~~~~~~~~~~~~~~~~~~~",
                       "~~~~~~~~~~~~~~~~~~~~~~~~~~~~~~~~~~~~~~~~~",
                       "~~~~~~~~~~~~~~~~~~~~~~~~~~~~~~~~~~~~~~~~~",
                       "~~~~~~~~~~~~~~~~~~~~~~~~~~~~~~~~~~~~~~~~~",
                       "~~~~~~~~~~~~~~~~~~~~~~~~~~~~~~~~~~~~~~~~~",
                       "~~~~~~~~~~~~~~~~~~~~~~~~~~~~~~~~~~~~~~~~~",
                       "~~~~~~~~~~~~~~~~~~~~~~~~~~~~~~~~~~~~~~~~~",
                       "~~~~~~~~~~~~~~~~~~~~~~~~~~~~~~~~~~~~~~~~~",
                       "~~~~~~~~~~~~~~~~~~~~~~~~~~~~~~~~~~~~~~~~~",
                       "~~~~~~~~~~~~~~~~~~~~~~~~~~~~~~~~~~~~~~~~~",
                       "~~~~~~~~~~~~~~~~~~~~~~~~~~~~~~~~~~~~~~~~~",
                       "~~~~~~~~~~~~~~~~~~~~~~~~~~~~~~~~~~~~~~~~~",
                       "~~~~~~~~~~~~~~~~~~~~~~~~~~~~~~~~~~~~~~~~~",
                       "~~~~~~~~~~~~~~~~~~~~~~~~~~~~~~~~~~~~~~~~~",
                       "~~~~~~~~~~~~~~~~~~~~~~~~~~~~~~~~~~~~~~~~~",
                       "~~~~~~~~~~~~~~~~~~~~~~~~~~~~~~~~~~~~~~~~~",
                       "~~~~~~~~~~~~~~~~~~~~~~~~~~~~~~~~~~~~~~~~~")

                .aisle("~~~~~~~~~~~~~~~~~~~~~~~~~~~~~~~~~~~~~~~~~",
                       "~~~~~~~~~~~~~~~~~~~~~~~~~~~~~~~~~~~~~~~~~",
                       "~~~~~~~~~~~~~~~~~~~~~~~~~~~~~~~~~~~~~~~~~",
                       "~~~~~~~~~~~~~~~~~~~~~~~~~~~~~~~~~~~~~~~~~",
                       "~~~~~~~~~~~~~~~~~~~~~~~~~~~~~~~~~~~~~~~~~",
                       "~~~~~~~~~~~~~~~~~~~~~~~~~~~~~~~~~~~~~~~~~",
                       "~~~~~~~~~~~~~~~~~~~~~~~~~~~~~~~~~~~~~~~~~",
                       "~~~~~~~~~~~~~~~~~~~~~~~~~~~~~~~~~~~~~~~~~",
                       "~~~~~~~~~~~~~~~~~~~~~~~~~~~~~~~~~~~~~~~~~",
                       "~~~~~~~~~~~~~~~~~~~~~~~~~~~~~~~~~~~~~~~~~",
                       "~~~~~~~~~~~~~~~~~~~~~~~~~~~~~~~~~~~~~~~~~",
                       "~~~~~~~~~~~~~~~~~~~~~~~~~~~~~~~~~~~~~~~~~",
                       "~~~~~~~~~~~~~~~~~~~~~~~~~~~~~~~~~~~~~~~~~",
                       "~~~~~~~~~~~~~~~~~~~~~~~~~~~~~~~~~~~~~~~~~",
                       "~~~~~~~~~~~~~~~~~~~~~~~~~~~~~~~~~~~~~~~~~",
                       "~~~~~~~~~~~~~~~~~~~~~~~~~~~~~~~~~~~~~~~~~",
                       "~~~~~~~~~~~~~~~~~~~~~~~~~~~~~~~~~~~~~~~~~",
                       "~~~~~~~~~~~~~~~~~~~~~~~~~~~~~~~~~~~~~~~~~",
                       "~~~~~~~~~~~~~~~~~~S~~~S~~~~~~~~~~~~~~~~~~",
                       "~~~~~~~~~~~~~~~~~~~~D~~~~~~~~~~~~~~~~~~~~",
                       "~~~~~~~~~~~~~~~~~~~DSD~~~~~~~~~~~~~~~~~~~",
                       "~~~~~~~~~~~~~~~~~~~~D~~~~~~~~~~~~~~~~~~~~",
                       "~~~~~~~~~~~~~~~~~~S~~~S~~~~~~~~~~~~~~~~~~",
                       "~~~~~~~~~~~~~~~~~~~~~~~~~~~~~~~~~~~~~~~~~",
                       "~~~~~~~~~~~~~~~~~~~~~~~~~~~~~~~~~~~~~~~~~",
                       "~~~~~~~~~~~~~~~~~~~~~~~~~~~~~~~~~~~~~~~~~",
                       "~~~~~~~~~~~~~~~~~~~~~~~~~~~~~~~~~~~~~~~~~",
                       "~~~~~~~~~~~~~~~~~~~~~~~~~~~~~~~~~~~~~~~~~",
                       "~~~~~~~~~~~~~~~~~~~~~~~~~~~~~~~~~~~~~~~~~",
                       "~~~~~~~~~~~~~~~~~~~~~~~~~~~~~~~~~~~~~~~~~",
                       "~~~~~~~~~~~~~~~~~~~~~~~~~~~~~~~~~~~~~~~~~",
                       "~~~~~~~~~~~~~~~~~~~~~~~~~~~~~~~~~~~~~~~~~",
                       "~~~~~~~~~~~~~~~~~~~~~~~~~~~~~~~~~~~~~~~~~",
                       "~~~~~~~~~~~~~~~~~~~~~~~~~~~~~~~~~~~~~~~~~",
                       "~~~~~~~~~~~~~~~~~~~~~~~~~~~~~~~~~~~~~~~~~",
                       "~~~~~~~~~~~~~~~~~~~~~~~~~~~~~~~~~~~~~~~~~",
                       "~~~~~~~~~~~~~~~~~~~~~~~~~~~~~~~~~~~~~~~~~",
                       "~~~~~~~~~~~~~~~~~~~~~~~~~~~~~~~~~~~~~~~~~",
                       "~~~~~~~~~~~~~~~~~~~~~~~~~~~~~~~~~~~~~~~~~",
                       "~~~~~~~~~~~~~~~~~~~~~~~~~~~~~~~~~~~~~~~~~",
                       "~~~~~~~~~~~~~~~~~~~~~~~~~~~~~~~~~~~~~~~~~")

                .aisle("~~~~~~~~~~~~~~~~~~~~~~~~~~~~~~~~~~~~~~~~~",
                       "~~~~~~~~~~~~~~~~~~~~~~~~~~~~~~~~~~~~~~~~~",
                       "~~~~~~~~~~~~~~~~~~~~~~~~~~~~~~~~~~~~~~~~~",
                       "~~~~~~~~~~~~~~~~~~~~~~~~~~~~~~~~~~~~~~~~~",
                       "~~~~~~~~~~~~~~~~~~~~~~~~~~~~~~~~~~~~~~~~~",
                       "~~~~~~~~~~~~~~~~~~~~~~~~~~~~~~~~~~~~~~~~~",
                       "~~~~~~~~~~~~~~~~~~~~~~~~~~~~~~~~~~~~~~~~~",
                       "~~~~~~~~~~~~~~~~~~~~~~~~~~~~~~~~~~~~~~~~~",
                       "~~~~~~~~~~~~~~~~~~~~~~~~~~~~~~~~~~~~~~~~~",
                       "~~~~~~~~~~~~~~~~~~~~~~~~~~~~~~~~~~~~~~~~~",
                       "~~~~~~~~~~~~~~~~~~~~~~~~~~~~~~~~~~~~~~~~~",
                       "~~~~~~~~~~~~~~~~~~~~~~~~~~~~~~~~~~~~~~~~~",
                       "~~~~~~~~~~~~~~~~~~~~~~~~~~~~~~~~~~~~~~~~~",
                       "~~~~~~~~~~~~~~~~~~~~~~~~~~~~~~~~~~~~~~~~~",
                       "~~~~~~~~~~~~~~~~~~~~~~~~~~~~~~~~~~~~~~~~~",
                       "~~~~~~~~~~~~~~~~~~~~~~~~~~~~~~~~~~~~~~~~~",
                       "~~~~~~~~~~~~~~~~~~~~~~~~~~~~~~~~~~~~~~~~~",
                       "~~~~~~~~~~~~~~~~~~~~~~~~~~~~~~~~~~~~~~~~~",
                       "~~~~~~~~~~~~~~~~~~S~~~S~~~~~~~~~~~~~~~~~~",
                       "~~~~~~~~~~~~~~~~~~~~D~~~~~~~~~~~~~~~~~~~~",
                       "~~~~~~~~~~~~~~~~~~~DSD~~~~~~~~~~~~~~~~~~~",
                       "~~~~~~~~~~~~~~~~~~~~D~~~~~~~~~~~~~~~~~~~~",
                       "~~~~~~~~~~~~~~~~~~S~~~S~~~~~~~~~~~~~~~~~~",
                       "~~~~~~~~~~~~~~~~~~~~~~~~~~~~~~~~~~~~~~~~~",
                       "~~~~~~~~~~~~~~~~~~~~~~~~~~~~~~~~~~~~~~~~~",
                       "~~~~~~~~~~~~~~~~~~~~~~~~~~~~~~~~~~~~~~~~~",
                       "~~~~~~~~~~~~~~~~~~~~~~~~~~~~~~~~~~~~~~~~~",
                       "~~~~~~~~~~~~~~~~~~~~~~~~~~~~~~~~~~~~~~~~~",
                       "~~~~~~~~~~~~~~~~~~~~~~~~~~~~~~~~~~~~~~~~~",
                       "~~~~~~~~~~~~~~~~~~~~~~~~~~~~~~~~~~~~~~~~~",
                       "~~~~~~~~~~~~~~~~~~~~~~~~~~~~~~~~~~~~~~~~~",
                       "~~~~~~~~~~~~~~~~~~~~~~~~~~~~~~~~~~~~~~~~~",
                       "~~~~~~~~~~~~~~~~~~~~~~~~~~~~~~~~~~~~~~~~~",
                       "~~~~~~~~~~~~~~~~~~~~~~~~~~~~~~~~~~~~~~~~~",
                       "~~~~~~~~~~~~~~~~~~~~~~~~~~~~~~~~~~~~~~~~~",
                       "~~~~~~~~~~~~~~~~~~~~~~~~~~~~~~~~~~~~~~~~~",
                       "~~~~~~~~~~~~~~~~~~~~~~~~~~~~~~~~~~~~~~~~~",
                       "~~~~~~~~~~~~~~~~~~~~~~~~~~~~~~~~~~~~~~~~~",
                       "~~~~~~~~~~~~~~~~~~~~~~~~~~~~~~~~~~~~~~~~~",
                       "~~~~~~~~~~~~~~~~~~~~~~~~~~~~~~~~~~~~~~~~~",
                       "~~~~~~~~~~~~~~~~~~~~~~~~~~~~~~~~~~~~~~~~~")

                .aisle("~~~~~~~~~~~~~~~~~~~~~~~~~~~~~~~~~~~~~~~~~",
                       "~~~~~~~~~~~~~~~~~~~~~~~~~~~~~~~~~~~~~~~~~",
                       "~~~~~~~~~~~~~~~~~~~~~~~~~~~~~~~~~~~~~~~~~",
                       "~~~~~~~~~~~~~~~~~~~~~~~~~~~~~~~~~~~~~~~~~",
                       "~~~~~~~~~~~~~~~~~~~~~~~~~~~~~~~~~~~~~~~~~",
                       "~~~~~~~~~~~~~~~~~~~~~~~~~~~~~~~~~~~~~~~~~",
                       "~~~~~~~~~~~~~~~~~~~~~~~~~~~~~~~~~~~~~~~~~",
                       "~~~~~~~~~~~~~~~~~~~~~~~~~~~~~~~~~~~~~~~~~",
                       "~~~~~~~~~~~~~~~~~~~~~~~~~~~~~~~~~~~~~~~~~",
                       "~~~~~~~~~~~~~~~~~~~~~~~~~~~~~~~~~~~~~~~~~",
                       "~~~~~~~~~~~~~~~~~~~~~~~~~~~~~~~~~~~~~~~~~",
                       "~~~~~~~~~~~~~~~~~~~~~~~~~~~~~~~~~~~~~~~~~",
                       "~~~~~~~~~~~~~~~~~~~~~~~~~~~~~~~~~~~~~~~~~",
                       "~~~~~~~~~~~~~~~~~~~~~~~~~~~~~~~~~~~~~~~~~",
                       "~~~~~~~~~~~~~~~~~~~~~~~~~~~~~~~~~~~~~~~~~",
                       "~~~~~~~~~~~~~~~~~~~~~~~~~~~~~~~~~~~~~~~~~",
                       "~~~~~~~~~~~~~~~~~~~~~~~~~~~~~~~~~~~~~~~~~",
                       "~~~~~~~~~~~~~~~~~~~~~~~~~~~~~~~~~~~~~~~~~",
                       "~~~~~~~~~~~~~~~~~~S~~~S~~~~~~~~~~~~~~~~~~",
                       "~~~~~~~~~~~~~~~~~~~~D~~~~~~~~~~~~~~~~~~~~",
                       "~~~~~~~~~~~~~~~~~~~DSD~~~~~~~~~~~~~~~~~~~",
                       "~~~~~~~~~~~~~~~~~~~~D~~~~~~~~~~~~~~~~~~~~",
                       "~~~~~~~~~~~~~~~~~~S~~~S~~~~~~~~~~~~~~~~~~",
                       "~~~~~~~~~~~~~~~~~~~~~~~~~~~~~~~~~~~~~~~~~",
                       "~~~~~~~~~~~~~~~~~~~~~~~~~~~~~~~~~~~~~~~~~",
                       "~~~~~~~~~~~~~~~~~~~~~~~~~~~~~~~~~~~~~~~~~",
                       "~~~~~~~~~~~~~~~~~~~~~~~~~~~~~~~~~~~~~~~~~",
                       "~~~~~~~~~~~~~~~~~~~~~~~~~~~~~~~~~~~~~~~~~",
                       "~~~~~~~~~~~~~~~~~~~~~~~~~~~~~~~~~~~~~~~~~",
                       "~~~~~~~~~~~~~~~~~~~~~~~~~~~~~~~~~~~~~~~~~",
                       "~~~~~~~~~~~~~~~~~~~~~~~~~~~~~~~~~~~~~~~~~",
                       "~~~~~~~~~~~~~~~~~~~~~~~~~~~~~~~~~~~~~~~~~",
                       "~~~~~~~~~~~~~~~~~~~~~~~~~~~~~~~~~~~~~~~~~",
                       "~~~~~~~~~~~~~~~~~~~~~~~~~~~~~~~~~~~~~~~~~",
                       "~~~~~~~~~~~~~~~~~~~~~~~~~~~~~~~~~~~~~~~~~",
                       "~~~~~~~~~~~~~~~~~~~~~~~~~~~~~~~~~~~~~~~~~",
                       "~~~~~~~~~~~~~~~~~~~~~~~~~~~~~~~~~~~~~~~~~",
                       "~~~~~~~~~~~~~~~~~~~~~~~~~~~~~~~~~~~~~~~~~",
                       "~~~~~~~~~~~~~~~~~~~~~~~~~~~~~~~~~~~~~~~~~",
                       "~~~~~~~~~~~~~~~~~~~~~~~~~~~~~~~~~~~~~~~~~",
                       "~~~~~~~~~~~~~~~~~~~~~~~~~~~~~~~~~~~~~~~~~")

                .aisle("~~~~~~~~~~~~~~~~~~~~~~~~~~~~~~~~~~~~~~~~~",
                       "~~~~~~~~~~~~~~~~~~~~~~~~~~~~~~~~~~~~~~~~~",
                       "~~~~~~~~~~~~~~~~~~~~~~~~~~~~~~~~~~~~~~~~~",
                       "~~~~~~~~~~~~~~~~~~~~~~~~~~~~~~~~~~~~~~~~~",
                       "~~~~~~~~~~~~~~~~~~~~~~~~~~~~~~~~~~~~~~~~~",
                       "~~~~~~~~~~~~~~~~~~~~~~~~~~~~~~~~~~~~~~~~~",
                       "~~~~~~~~~~~~~~~~~~~~~~~~~~~~~~~~~~~~~~~~~",
                       "~~~~~~~~~~~~~~~~~~~~~~~~~~~~~~~~~~~~~~~~~",
                       "~~~~~~~~~~~~~~~~~~~~~~~~~~~~~~~~~~~~~~~~~",
                       "~~~~~~~~~~~~~~~~~~~~~~~~~~~~~~~~~~~~~~~~~",
                       "~~~~~~~~~~~~~~~~~~~~~~~~~~~~~~~~~~~~~~~~~",
                       "~~~~~~~~~~~~~~~~~~~~~~~~~~~~~~~~~~~~~~~~~",
                       "~~~~~~~~~~~~~~~~~~~~~~~~~~~~~~~~~~~~~~~~~",
                       "~~~~~~~~~~~~~~~~~~~~~~~~~~~~~~~~~~~~~~~~~",
                       "~~~~~~~~~~~~~~~~~~~~~~~~~~~~~~~~~~~~~~~~~",
                       "~~~~~~~~~~~~~~~~~~~~~~~~~~~~~~~~~~~~~~~~~",
                       "~~~~~~~~~~~~~~~~~~~~~~~~~~~~~~~~~~~~~~~~~",
                       "~~~~~~~~~~~~~~~~~~~SSS~~~~~~~~~~~~~~~~~~~",
                       "~~~~~~~~~~~~~~~~~~S~~~S~~~~~~~~~~~~~~~~~~",
                       "~~~~~~~~~~~~~~~~~S~SDS~S~~~~~~~~~~~~~~~~~",
                       "~~~~~~~~~~~~~~~~~S~DSD~S~~~~~~~~~~~~~~~~~",
                       "~~~~~~~~~~~~~~~~~S~SDS~S~~~~~~~~~~~~~~~~~",
                       "~~~~~~~~~~~~~~~~~~S~~~S~~~~~~~~~~~~~~~~~~",
                       "~~~~~~~~~~~~~~~~~~~SSS~~~~~~~~~~~~~~~~~~~",
                       "~~~~~~~~~~~~~~~~~~~~~~~~~~~~~~~~~~~~~~~~~",
                       "~~~~~~~~~~~~~~~~~~~~~~~~~~~~~~~~~~~~~~~~~",
                       "~~~~~~~~~~~~~~~~~~~~~~~~~~~~~~~~~~~~~~~~~",
                       "~~~~~~~~~~~~~~~~~~~~~~~~~~~~~~~~~~~~~~~~~",
                       "~~~~~~~~~~~~~~~~~~~~~~~~~~~~~~~~~~~~~~~~~",
                       "~~~~~~~~~~~~~~~~~~~~~~~~~~~~~~~~~~~~~~~~~",
                       "~~~~~~~~~~~~~~~~~~~~~~~~~~~~~~~~~~~~~~~~~",
                       "~~~~~~~~~~~~~~~~~~~~~~~~~~~~~~~~~~~~~~~~~",
                       "~~~~~~~~~~~~~~~~~~~~~~~~~~~~~~~~~~~~~~~~~",
                       "~~~~~~~~~~~~~~~~~~~~~~~~~~~~~~~~~~~~~~~~~",
                       "~~~~~~~~~~~~~~~~~~~~~~~~~~~~~~~~~~~~~~~~~",
                       "~~~~~~~~~~~~~~~~~~~~~~~~~~~~~~~~~~~~~~~~~",
                       "~~~~~~~~~~~~~~~~~~~~~~~~~~~~~~~~~~~~~~~~~",
                       "~~~~~~~~~~~~~~~~~~~~~~~~~~~~~~~~~~~~~~~~~",
                       "~~~~~~~~~~~~~~~~~~~~~~~~~~~~~~~~~~~~~~~~~",
                       "~~~~~~~~~~~~~~~~~~~~~~~~~~~~~~~~~~~~~~~~~",
                       "~~~~~~~~~~~~~~~~~~~~~~~~~~~~~~~~~~~~~~~~~")

                .aisle("~~~~~~~~~~~~~~~~~~~~~~~~~~~~~~~~~~~~~~~~~",
                       "~~~~~~~~~~~~~~~~~~~~~~~~~~~~~~~~~~~~~~~~~",
                       "~~~~~~~~~~~~~~~~~~~~~~~~~~~~~~~~~~~~~~~~~",
                       "~~~~~~~~~~~~~~~~~~~~~~~~~~~~~~~~~~~~~~~~~",
                       "~~~~~~~~~~~~~~~~~~~~~~~~~~~~~~~~~~~~~~~~~",
                       "~~~~~~~~~~~~~~~~~~~~~~~~~~~~~~~~~~~~~~~~~",
                       "~~~~~~~~~~~~~~~~~~~~~~~~~~~~~~~~~~~~~~~~~",
                       "~~~~~~~~~~~~~~~~~~~~~~~~~~~~~~~~~~~~~~~~~",
                       "~~~~~~~~~~~~~~~~~~~~~~~~~~~~~~~~~~~~~~~~~",
                       "~~~~~~~~~~~~~~~~~~~~~~~~~~~~~~~~~~~~~~~~~",
                       "~~~~~~~~~~~~~~~~~~~~~~~~~~~~~~~~~~~~~~~~~",
                       "~~~~~~~~~~~~~~~~~~~~~~~~~~~~~~~~~~~~~~~~~",
                       "~~~~~~~~~~~~~~~~~~~~~~~~~~~~~~~~~~~~~~~~~",
                       "~~~~~~~~~~~~~~~~~~~~~~~~~~~~~~~~~~~~~~~~~",
                       "~~~~~~~~~~~~~~~~~~~~~~~~~~~~~~~~~~~~~~~~~",
                       "~~~~~~~~~~~~~~~~~~~~~~~~~~~~~~~~~~~~~~~~~",
                       "~~~~~~~~~~~~~~~~~~~~~~~~~~~~~~~~~~~~~~~~~",
                       "~~~~~~~~~~~~~~~~~~~~~~~~~~~~~~~~~~~~~~~~~",
                       "~~~~~~~~~~~~~~~~~~~~~~~~~~~~~~~~~~~~~~~~~",
                       "~~~~~~~~~~~~~~~~~~~SDS~~~~~~~~~~~~~~~~~~~",
                       "~~~~~~~~~~~~~~~~~~~DSD~~~~~~~~~~~~~~~~~~~",
                       "~~~~~~~~~~~~~~~~~~~SDS~~~~~~~~~~~~~~~~~~~",
                       "~~~~~~~~~~~~~~~~~~~~~~~~~~~~~~~~~~~~~~~~~",
                       "~~~~~~~~~~~~~~~~~~~~~~~~~~~~~~~~~~~~~~~~~",
                       "~~~~~~~~~~~~~~~~~~~~~~~~~~~~~~~~~~~~~~~~~",
                       "~~~~~~~~~~~~~~~~~~~~~~~~~~~~~~~~~~~~~~~~~",
                       "~~~~~~~~~~~~~~~~~~~~~~~~~~~~~~~~~~~~~~~~~",
                       "~~~~~~~~~~~~~~~~~~~~~~~~~~~~~~~~~~~~~~~~~",
                       "~~~~~~~~~~~~~~~~~~~~~~~~~~~~~~~~~~~~~~~~~",
                       "~~~~~~~~~~~~~~~~~~~~~~~~~~~~~~~~~~~~~~~~~",
                       "~~~~~~~~~~~~~~~~~~~~~~~~~~~~~~~~~~~~~~~~~",
                       "~~~~~~~~~~~~~~~~~~~~~~~~~~~~~~~~~~~~~~~~~",
                       "~~~~~~~~~~~~~~~~~~~~~~~~~~~~~~~~~~~~~~~~~",
                       "~~~~~~~~~~~~~~~~~~~~~~~~~~~~~~~~~~~~~~~~~",
                       "~~~~~~~~~~~~~~~~~~~~~~~~~~~~~~~~~~~~~~~~~",
                       "~~~~~~~~~~~~~~~~~~~~~~~~~~~~~~~~~~~~~~~~~",
                       "~~~~~~~~~~~~~~~~~~~~~~~~~~~~~~~~~~~~~~~~~",
                       "~~~~~~~~~~~~~~~~~~~~~~~~~~~~~~~~~~~~~~~~~",
                       "~~~~~~~~~~~~~~~~~~~~~~~~~~~~~~~~~~~~~~~~~",
                       "~~~~~~~~~~~~~~~~~~~~~~~~~~~~~~~~~~~~~~~~~",
                       "~~~~~~~~~~~~~~~~~~~~~~~~~~~~~~~~~~~~~~~~~")

                .aisle("~~~~~~~~~~~~~~~~~~~~~~~~~~~~~~~~~~~~~~~~~",
                       "~~~~~~~~~~~~~~~~~~~~~~~~~~~~~~~~~~~~~~~~~",
                       "~~~~~~~~~~~~~~~~~~~~~~~~~~~~~~~~~~~~~~~~~",
                       "~~~~~~~~~~~~~~~~~~~~~~~~~~~~~~~~~~~~~~~~~",
                       "~~~~~~~~~~~~~~~~~~~~~~~~~~~~~~~~~~~~~~~~~",
                       "~~~~~~~~~~~~~~~~~~~~~~~~~~~~~~~~~~~~~~~~~",
                       "~~~~~~~~~~~~~~~~~~~~~~~~~~~~~~~~~~~~~~~~~",
                       "~~~~~~~~~~~~~~~~~~~~~~~~~~~~~~~~~~~~~~~~~",
                       "~~~~~~~~~~~~~~~~~~~~~~~~~~~~~~~~~~~~~~~~~",
                       "~~~~~~~~~~~~~~~~~~~~~~~~~~~~~~~~~~~~~~~~~",
                       "~~~~~~~~~~~~~~~~~~~~~~~~~~~~~~~~~~~~~~~~~",
                       "~~~~~~~~~~~~~~~~~~~~~~~~~~~~~~~~~~~~~~~~~",
                       "~~~~~~~~~~~~~~~~~~~~~~~~~~~~~~~~~~~~~~~~~",
                       "~~~~~~~~~~~~~~~~~~~~~~~~~~~~~~~~~~~~~~~~~",
                       "~~~~~~~~~~~~~~~~~~~~~~~~~~~~~~~~~~~~~~~~~",
                       "~~~~~~~~~~~~~~~~~~~~~~~~~~~~~~~~~~~~~~~~~",
                       "~~~~~~~~~~~~~~~~~~~~~~~~~~~~~~~~~~~~~~~~~",
                       "~~~~~~~~~~~~~~~~~~~~~~~~~~~~~~~~~~~~~~~~~",
                       "~~~~~~~~~~~~~~~~~~~~~~~~~~~~~~~~~~~~~~~~~",
                       "~~~~~~~~~~~~~~~~~~~SDS~~~~~~~~~~~~~~~~~~~",
                       "~~~~~~~~~~~~~~~~~~~DSD~~~~~~~~~~~~~~~~~~~",
                       "~~~~~~~~~~~~~~~~~~~SDS~~~~~~~~~~~~~~~~~~~",
                       "~~~~~~~~~~~~~~~~~~~~~~~~~~~~~~~~~~~~~~~~~",
                       "~~~~~~~~~~~~~~~~~~~~~~~~~~~~~~~~~~~~~~~~~",
                       "~~~~~~~~~~~~~~~~~~~~~~~~~~~~~~~~~~~~~~~~~",
                       "~~~~~~~~~~~~~~~~~~~~~~~~~~~~~~~~~~~~~~~~~",
                       "~~~~~~~~~~~~~~~~~~~~~~~~~~~~~~~~~~~~~~~~~",
                       "~~~~~~~~~~~~~~~~~~~~~~~~~~~~~~~~~~~~~~~~~",
                       "~~~~~~~~~~~~~~~~~~~~~~~~~~~~~~~~~~~~~~~~~",
                       "~~~~~~~~~~~~~~~~~~~~~~~~~~~~~~~~~~~~~~~~~",
                       "~~~~~~~~~~~~~~~~~~~~~~~~~~~~~~~~~~~~~~~~~",
                       "~~~~~~~~~~~~~~~~~~~~~~~~~~~~~~~~~~~~~~~~~",
                       "~~~~~~~~~~~~~~~~~~~~~~~~~~~~~~~~~~~~~~~~~",
                       "~~~~~~~~~~~~~~~~~~~~~~~~~~~~~~~~~~~~~~~~~",
                       "~~~~~~~~~~~~~~~~~~~~~~~~~~~~~~~~~~~~~~~~~",
                       "~~~~~~~~~~~~~~~~~~~~~~~~~~~~~~~~~~~~~~~~~",
                       "~~~~~~~~~~~~~~~~~~~~~~~~~~~~~~~~~~~~~~~~~",
                       "~~~~~~~~~~~~~~~~~~~~~~~~~~~~~~~~~~~~~~~~~",
                       "~~~~~~~~~~~~~~~~~~~~~~~~~~~~~~~~~~~~~~~~~",
                       "~~~~~~~~~~~~~~~~~~~~~~~~~~~~~~~~~~~~~~~~~",
                       "~~~~~~~~~~~~~~~~~~~~~~~~~~~~~~~~~~~~~~~~~")

                .aisle("~~~~~~~~~~~~~~~~~~~~~~~~~~~~~~~~~~~~~~~~~",
                       "~~~~~~~~~~~~~~~~~~~~~~~~~~~~~~~~~~~~~~~~~",
                       "~~~~~~~~~~~~~~~~~~~~~~~~~~~~~~~~~~~~~~~~~",
                       "~~~~~~~~~~~~~~~~~~~~~~~~~~~~~~~~~~~~~~~~~",
                       "~~~~~~~~~~~~~~~~~~~~~~~~~~~~~~~~~~~~~~~~~",
                       "~~~~~~~~~~~~~~~~~~~~~~~~~~~~~~~~~~~~~~~~~",
                       "~~~~~~~~~~~~~~~~~~~~~~~~~~~~~~~~~~~~~~~~~",
                       "~~~~~~~~~~~~~~~~~~~~~~~~~~~~~~~~~~~~~~~~~",
                       "~~~~~~~~~~~~~~~~~~~~~~~~~~~~~~~~~~~~~~~~~",
                       "~~~~~~~~~~~~~~~~~~~~~~~~~~~~~~~~~~~~~~~~~",
                       "~~~~~~~~~~~~~~~~~~~~~~~~~~~~~~~~~~~~~~~~~",
                       "~~~~~~~~~~~~~~~~~~~~~~~~~~~~~~~~~~~~~~~~~",
                       "~~~~~~~~~~~~~~~~~~~~~~~~~~~~~~~~~~~~~~~~~",
                       "~~~~~~~~~~~~~~~~~~~~~~~~~~~~~~~~~~~~~~~~~",
                       "~~~~~~~~~~~~~~~~~~~~~~~~~~~~~~~~~~~~~~~~~",
                       "~~~~~~~~~~~~~~~~~~~~~~~~~~~~~~~~~~~~~~~~~",
                       "~~~~~~~~~~~~~~~~~~~~~~~~~~~~~~~~~~~~~~~~~",
                       "~~~~~~~~~~~~~~~~~~~~~~~~~~~~~~~~~~~~~~~~~",
                       "~~~~~~~~~~~~~~~~~~~~~~~~~~~~~~~~~~~~~~~~~",
                       "~~~~~~~~~~~~~~~~~~~SDS~~~~~~~~~~~~~~~~~~~",
                       "~~~~~~~~~~~~~~~~~~~DSD~~~~~~~~~~~~~~~~~~~",
                       "~~~~~~~~~~~~~~~~~~~SDS~~~~~~~~~~~~~~~~~~~",
                       "~~~~~~~~~~~~~~~~~~~~~~~~~~~~~~~~~~~~~~~~~",
                       "~~~~~~~~~~~~~~~~~~~~~~~~~~~~~~~~~~~~~~~~~",
                       "~~~~~~~~~~~~~~~~~~~~~~~~~~~~~~~~~~~~~~~~~",
                       "~~~~~~~~~~~~~~~~~~~~~~~~~~~~~~~~~~~~~~~~~",
                       "~~~~~~~~~~~~~~~~~~~~~~~~~~~~~~~~~~~~~~~~~",
                       "~~~~~~~~~~~~~~~~~~~~~~~~~~~~~~~~~~~~~~~~~",
                       "~~~~~~~~~~~~~~~~~~~~~~~~~~~~~~~~~~~~~~~~~",
                       "~~~~~~~~~~~~~~~~~~~~~~~~~~~~~~~~~~~~~~~~~",
                       "~~~~~~~~~~~~~~~~~~~~~~~~~~~~~~~~~~~~~~~~~",
                       "~~~~~~~~~~~~~~~~~~~~~~~~~~~~~~~~~~~~~~~~~",
                       "~~~~~~~~~~~~~~~~~~~~~~~~~~~~~~~~~~~~~~~~~",
                       "~~~~~~~~~~~~~~~~~~~~~~~~~~~~~~~~~~~~~~~~~",
                       "~~~~~~~~~~~~~~~~~~~~~~~~~~~~~~~~~~~~~~~~~",
                       "~~~~~~~~~~~~~~~~~~~~~~~~~~~~~~~~~~~~~~~~~",
                       "~~~~~~~~~~~~~~~~~~~~~~~~~~~~~~~~~~~~~~~~~",
                       "~~~~~~~~~~~~~~~~~~~~~~~~~~~~~~~~~~~~~~~~~",
                       "~~~~~~~~~~~~~~~~~~~~~~~~~~~~~~~~~~~~~~~~~",
                       "~~~~~~~~~~~~~~~~~~~~~~~~~~~~~~~~~~~~~~~~~",
                       "~~~~~~~~~~~~~~~~~~~~~~~~~~~~~~~~~~~~~~~~~")

                .aisle("~~~~~~~~~~~~~~~~~~~~~~~~~~~~~~~~~~~~~~~~~",
                       "~~~~~~~~~~~~~~~~~~~~~~~~~~~~~~~~~~~~~~~~~",
                       "~~~~~~~~~~~~~~~~~~~~~~~~~~~~~~~~~~~~~~~~~",
                       "~~~~~~~~~~~~~~~~~~~~~~~~~~~~~~~~~~~~~~~~~",
                       "~~~~~~~~~~~~~~~~~~~~~~~~~~~~~~~~~~~~~~~~~",
                       "~~~~~~~~~~~~~~~~~~~~~~~~~~~~~~~~~~~~~~~~~",
                       "~~~~~~~~~~~~~~~~~~~~~~~~~~~~~~~~~~~~~~~~~",
                       "~~~~~~~~~~~~~~~~~~~~~~~~~~~~~~~~~~~~~~~~~",
                       "~~~~~~~~~~~~~~~~~~~~~~~~~~~~~~~~~~~~~~~~~",
                       "~~~~~~~~~~~~~~~~~~~~~~~~~~~~~~~~~~~~~~~~~",
                       "~~~~~~~~~~~~~~~~~~~~~~~~~~~~~~~~~~~~~~~~~",
                       "~~~~~~~~~~~~~~~~~~~~~~~~~~~~~~~~~~~~~~~~~",
                       "~~~~~~~~~~~~~~~~~~~~~~~~~~~~~~~~~~~~~~~~~",
                       "~~~~~~~~~~~~~~~~~~~~~~~~~~~~~~~~~~~~~~~~~",
                       "~~~~~~~~~~~~~~~~~~~~~~~~~~~~~~~~~~~~~~~~~",
                       "~~~~~~~~~~~~~~~~~~~~~~~~~~~~~~~~~~~~~~~~~",
                       "~~~~~~~~~~~~~~~~~~~~~~~~~~~~~~~~~~~~~~~~~",
                       "~~~~~~~~~~~~~~~~~~~~~~~~~~~~~~~~~~~~~~~~~",
                       "~~~~~~~~~~~~~~~~~~~~~~~~~~~~~~~~~~~~~~~~~",
                       "~~~~~~~~~~~~~~~~~~~SDS~~~~~~~~~~~~~~~~~~~",
                       "~~~~~~~~~~~~~~~~~~~DSD~~~~~~~~~~~~~~~~~~~",
                       "~~~~~~~~~~~~~~~~~~~SDS~~~~~~~~~~~~~~~~~~~",
                       "~~~~~~~~~~~~~~~~~~~~~~~~~~~~~~~~~~~~~~~~~",
                       "~~~~~~~~~~~~~~~~~~~~~~~~~~~~~~~~~~~~~~~~~",
                       "~~~~~~~~~~~~~~~~~~~~~~~~~~~~~~~~~~~~~~~~~",
                       "~~~~~~~~~~~~~~~~~~~~~~~~~~~~~~~~~~~~~~~~~",
                       "~~~~~~~~~~~~~~~~~~~~~~~~~~~~~~~~~~~~~~~~~",
                       "~~~~~~~~~~~~~~~~~~~~~~~~~~~~~~~~~~~~~~~~~",
                       "~~~~~~~~~~~~~~~~~~~~~~~~~~~~~~~~~~~~~~~~~",
                       "~~~~~~~~~~~~~~~~~~~~~~~~~~~~~~~~~~~~~~~~~",
                       "~~~~~~~~~~~~~~~~~~~~~~~~~~~~~~~~~~~~~~~~~",
                       "~~~~~~~~~~~~~~~~~~~~~~~~~~~~~~~~~~~~~~~~~",
                       "~~~~~~~~~~~~~~~~~~~~~~~~~~~~~~~~~~~~~~~~~",
                       "~~~~~~~~~~~~~~~~~~~~~~~~~~~~~~~~~~~~~~~~~",
                       "~~~~~~~~~~~~~~~~~~~~~~~~~~~~~~~~~~~~~~~~~",
                       "~~~~~~~~~~~~~~~~~~~~~~~~~~~~~~~~~~~~~~~~~",
                       "~~~~~~~~~~~~~~~~~~~~~~~~~~~~~~~~~~~~~~~~~",
                       "~~~~~~~~~~~~~~~~~~~~~~~~~~~~~~~~~~~~~~~~~",
                       "~~~~~~~~~~~~~~~~~~~~~~~~~~~~~~~~~~~~~~~~~",
                       "~~~~~~~~~~~~~~~~~~~~~~~~~~~~~~~~~~~~~~~~~",
                       "~~~~~~~~~~~~~~~~~~~~~~~~~~~~~~~~~~~~~~~~~")

                .aisle("~~~~~~~~~~~~~~~~~~~~~~~~~~~~~~~~~~~~~~~~~",
                       "~~~~~~~~~~~~~~~~~~~~~~~~~~~~~~~~~~~~~~~~~",
                       "~~~~~~~~~~~~~~~~~~~~~~~~~~~~~~~~~~~~~~~~~",
                       "~~~~~~~~~~~~~~~~~~~~~~~~~~~~~~~~~~~~~~~~~",
                       "~~~~~~~~~~~~~~~~~~~~~~~~~~~~~~~~~~~~~~~~~",
                       "~~~~~~~~~~~~~~~~~~~~~~~~~~~~~~~~~~~~~~~~~",
                       "~~~~~~~~~~~~~~~~~~~~~~~~~~~~~~~~~~~~~~~~~",
                       "~~~~~~~~~~~~~~~~~~~~~~~~~~~~~~~~~~~~~~~~~",
                       "~~~~~~~~~~~~~~~~~~~~~~~~~~~~~~~~~~~~~~~~~",
                       "~~~~~~~~~~~~~~~~~~~~~~~~~~~~~~~~~~~~~~~~~",
                       "~~~~~~~~~~~~~~~~~~~~~~~~~~~~~~~~~~~~~~~~~",
                       "~~~~~~~~~~~~~~~~~~~~~~~~~~~~~~~~~~~~~~~~~",
                       "~~~~~~~~~~~~~~~~~~~~~~~~~~~~~~~~~~~~~~~~~",
                       "~~~~~~~~~~~~~~~~~~~~~~~~~~~~~~~~~~~~~~~~~",
                       "~~~~~~~~~~~~~~~~~~~~~~~~~~~~~~~~~~~~~~~~~",
                       "~~~~~~~~~~~~~~~~~~~~~~~~~~~~~~~~~~~~~~~~~",
                       "~~~~~~~~~~~~~~~~~~~~~~~~~~~~~~~~~~~~~~~~~",
                       "~~~~~~~~~~~~~~~~~~~~~~~~~~~~~~~~~~~~~~~~~",
                       "~~~~~~~~~~~~~~~~~~~~~~~~~~~~~~~~~~~~~~~~~",
                       "~~~~~~~~~~~~~~~~~~~SDS~~~~~~~~~~~~~~~~~~~",
                       "~~~~~~~~~~~~~~~~~~~DSD~~~~~~~~~~~~~~~~~~~",
                       "~~~~~~~~~~~~~~~~~~~SDS~~~~~~~~~~~~~~~~~~~",
                       "~~~~~~~~~~~~~~~~~~~~~~~~~~~~~~~~~~~~~~~~~",
                       "~~~~~~~~~~~~~~~~~~~~~~~~~~~~~~~~~~~~~~~~~",
                       "~~~~~~~~~~~~~~~~~~~~~~~~~~~~~~~~~~~~~~~~~",
                       "~~~~~~~~~~~~~~~~~~~~~~~~~~~~~~~~~~~~~~~~~",
                       "~~~~~~~~~~~~~~~~~~~~~~~~~~~~~~~~~~~~~~~~~",
                       "~~~~~~~~~~~~~~~~~~~~~~~~~~~~~~~~~~~~~~~~~",
                       "~~~~~~~~~~~~~~~~~~~~~~~~~~~~~~~~~~~~~~~~~",
                       "~~~~~~~~~~~~~~~~~~~~~~~~~~~~~~~~~~~~~~~~~",
                       "~~~~~~~~~~~~~~~~~~~~~~~~~~~~~~~~~~~~~~~~~",
                       "~~~~~~~~~~~~~~~~~~~~~~~~~~~~~~~~~~~~~~~~~",
                       "~~~~~~~~~~~~~~~~~~~~~~~~~~~~~~~~~~~~~~~~~",
                       "~~~~~~~~~~~~~~~~~~~~~~~~~~~~~~~~~~~~~~~~~",
                       "~~~~~~~~~~~~~~~~~~~~~~~~~~~~~~~~~~~~~~~~~",
                       "~~~~~~~~~~~~~~~~~~~~~~~~~~~~~~~~~~~~~~~~~",
                       "~~~~~~~~~~~~~~~~~~~~~~~~~~~~~~~~~~~~~~~~~",
                       "~~~~~~~~~~~~~~~~~~~~~~~~~~~~~~~~~~~~~~~~~",
                       "~~~~~~~~~~~~~~~~~~~~~~~~~~~~~~~~~~~~~~~~~",
                       "~~~~~~~~~~~~~~~~~~~~~~~~~~~~~~~~~~~~~~~~~",
                       "~~~~~~~~~~~~~~~~~~~~~~~~~~~~~~~~~~~~~~~~~")

                .aisle("~~~~~~~~~~~~~~~~~~~~~~~~~~~~~~~~~~~~~~~~~",
                       "~~~~~~~~~~~~~~~~~~~~~~~~~~~~~~~~~~~~~~~~~",
                       "~~~~~~~~~~~~~~~~~~~~~~~~~~~~~~~~~~~~~~~~~",
                       "~~~~~~~~~~~~~~~~~~~~~~~~~~~~~~~~~~~~~~~~~",
                       "~~~~~~~~~~~~~~~~~~~~~~~~~~~~~~~~~~~~~~~~~",
                       "~~~~~~~~~~~~~~~~~~~~~~~~~~~~~~~~~~~~~~~~~",
                       "~~~~~~~~~~~~~~~~~~~~~~~~~~~~~~~~~~~~~~~~~",
                       "~~~~~~~~~~~~~~~~~~~~~~~~~~~~~~~~~~~~~~~~~",
                       "~~~~~~~~~~~~~~~~~~~~~~~~~~~~~~~~~~~~~~~~~",
                       "~~~~~~~~~~~~~~~~~~~~~~~~~~~~~~~~~~~~~~~~~",
                       "~~~~~~~~~~~~~~~~~~~~~~~~~~~~~~~~~~~~~~~~~",
                       "~~~~~~~~~~~~~~~~~~~~~~~~~~~~~~~~~~~~~~~~~",
                       "~~~~~~~~~~~~~~~~~~~~~~~~~~~~~~~~~~~~~~~~~",
                       "~~~~~~~~~~~~~~~~~~~~~~~~~~~~~~~~~~~~~~~~~",
                       "~~~~~~~~~~~~~~~~~~~~~~~~~~~~~~~~~~~~~~~~~",
                       "~~~~~~~~~~~~~~~~~~~~~~~~~~~~~~~~~~~~~~~~~",
                       "~~~~~~~~~~~~~~~~~~~~~~~~~~~~~~~~~~~~~~~~~",
                       "~~~~~~~~~~~~~~~~~~~~~~~~~~~~~~~~~~~~~~~~~",
                       "~~~~~~~~~~~~~~~~~~~~~~~~~~~~~~~~~~~~~~~~~",
                       "~~~~~~~~~~~~~~~~~~~SDS~~~~~~~~~~~~~~~~~~~",
                       "~~~~~~~~~~~~~~~~~~~DSD~~~~~~~~~~~~~~~~~~~",
                       "~~~~~~~~~~~~~~~~~~~SDS~~~~~~~~~~~~~~~~~~~",
                       "~~~~~~~~~~~~~~~~~~~~~~~~~~~~~~~~~~~~~~~~~",
                       "~~~~~~~~~~~~~~~~~~~~~~~~~~~~~~~~~~~~~~~~~",
                       "~~~~~~~~~~~~~~~~~~~~~~~~~~~~~~~~~~~~~~~~~",
                       "~~~~~~~~~~~~~~~~~~~~~~~~~~~~~~~~~~~~~~~~~",
                       "~~~~~~~~~~~~~~~~~~~~~~~~~~~~~~~~~~~~~~~~~",
                       "~~~~~~~~~~~~~~~~~~~~~~~~~~~~~~~~~~~~~~~~~",
                       "~~~~~~~~~~~~~~~~~~~~~~~~~~~~~~~~~~~~~~~~~",
                       "~~~~~~~~~~~~~~~~~~~~~~~~~~~~~~~~~~~~~~~~~",
                       "~~~~~~~~~~~~~~~~~~~~~~~~~~~~~~~~~~~~~~~~~",
                       "~~~~~~~~~~~~~~~~~~~~~~~~~~~~~~~~~~~~~~~~~",
                       "~~~~~~~~~~~~~~~~~~~~~~~~~~~~~~~~~~~~~~~~~",
                       "~~~~~~~~~~~~~~~~~~~~~~~~~~~~~~~~~~~~~~~~~",
                       "~~~~~~~~~~~~~~~~~~~~~~~~~~~~~~~~~~~~~~~~~",
                       "~~~~~~~~~~~~~~~~~~~~~~~~~~~~~~~~~~~~~~~~~",
                       "~~~~~~~~~~~~~~~~~~~~~~~~~~~~~~~~~~~~~~~~~",
                       "~~~~~~~~~~~~~~~~~~~~~~~~~~~~~~~~~~~~~~~~~",
                       "~~~~~~~~~~~~~~~~~~~~~~~~~~~~~~~~~~~~~~~~~",
                       "~~~~~~~~~~~~~~~~~~~~~~~~~~~~~~~~~~~~~~~~~",
                       "~~~~~~~~~~~~~~~~~~~~~~~~~~~~~~~~~~~~~~~~~")

                .aisle("~~~~~~~~~~~~~~~~~~~~~~~~~~~~~~~~~~~~~~~~~",
                       "~~~~~~~~~~~~~~~~~~~~~~~~~~~~~~~~~~~~~~~~~",
                       "~~~~~~~~~~~~~~~~~~~~~~~~~~~~~~~~~~~~~~~~~",
                       "~~~~~~~~~~~~~~~~~~~~~~~~~~~~~~~~~~~~~~~~~",
                       "~~~~~~~~~~~~~~~~~~~~~~~~~~~~~~~~~~~~~~~~~",
                       "~~~~~~~~~~~~~~~~~~~~~~~~~~~~~~~~~~~~~~~~~",
                       "~~~~~~~~~~~~~~~~~~~~~~~~~~~~~~~~~~~~~~~~~",
                       "~~~~~~~~~~~~~~~~~~~~~~~~~~~~~~~~~~~~~~~~~",
                       "~~~~~~~~~~~~~~~~~~~~~~~~~~~~~~~~~~~~~~~~~",
                       "~~~~~~~~~~~~~~~~~~~~~~~~~~~~~~~~~~~~~~~~~",
                       "~~~~~~~~~~~~~~~~~~~~~~~~~~~~~~~~~~~~~~~~~",
                       "~~~~~~~~~~~~~~~~~~~~~~~~~~~~~~~~~~~~~~~~~",
                       "~~~~~~~~~~~~~~~~~~~~~~~~~~~~~~~~~~~~~~~~~",
                       "~~~~~~~~~~~~~~~~~~~~~~~~~~~~~~~~~~~~~~~~~",
                       "~~~~~~~~~~~~~~~~~~~~~~~~~~~~~~~~~~~~~~~~~",
                       "~~~~~~~~~~~~~~~~~~~~~~~~~~~~~~~~~~~~~~~~~",
                       "~~~~~~~~~~~~~~~~~~~~~~~~~~~~~~~~~~~~~~~~~",
                       "~~~~~~~~~~~~~~~~~~~~~~~~~~~~~~~~~~~~~~~~~",
                       "~~~~~~~~~~~~~~~~~~~~~~~~~~~~~~~~~~~~~~~~~",
                       "~~~~~~~~~~~~~~~~~~~SDS~~~~~~~~~~~~~~~~~~~",
                       "~~~~~~~~~~~~~~~~~~~DSD~~~~~~~~~~~~~~~~~~~",
                       "~~~~~~~~~~~~~~~~~~~SDS~~~~~~~~~~~~~~~~~~~",
                       "~~~~~~~~~~~~~~~~~~~~~~~~~~~~~~~~~~~~~~~~~",
                       "~~~~~~~~~~~~~~~~~~~~~~~~~~~~~~~~~~~~~~~~~",
                       "~~~~~~~~~~~~~~~~~~~~~~~~~~~~~~~~~~~~~~~~~",
                       "~~~~~~~~~~~~~~~~~~~~~~~~~~~~~~~~~~~~~~~~~",
                       "~~~~~~~~~~~~~~~~~~~~~~~~~~~~~~~~~~~~~~~~~",
                       "~~~~~~~~~~~~~~~~~~~~~~~~~~~~~~~~~~~~~~~~~",
                       "~~~~~~~~~~~~~~~~~~~~~~~~~~~~~~~~~~~~~~~~~",
                       "~~~~~~~~~~~~~~~~~~~~~~~~~~~~~~~~~~~~~~~~~",
                       "~~~~~~~~~~~~~~~~~~~~~~~~~~~~~~~~~~~~~~~~~",
                       "~~~~~~~~~~~~~~~~~~~~~~~~~~~~~~~~~~~~~~~~~",
                       "~~~~~~~~~~~~~~~~~~~~~~~~~~~~~~~~~~~~~~~~~",
                       "~~~~~~~~~~~~~~~~~~~~~~~~~~~~~~~~~~~~~~~~~",
                       "~~~~~~~~~~~~~~~~~~~~~~~~~~~~~~~~~~~~~~~~~",
                       "~~~~~~~~~~~~~~~~~~~~~~~~~~~~~~~~~~~~~~~~~",
                       "~~~~~~~~~~~~~~~~~~~~~~~~~~~~~~~~~~~~~~~~~",
                       "~~~~~~~~~~~~~~~~~~~~~~~~~~~~~~~~~~~~~~~~~",
                       "~~~~~~~~~~~~~~~~~~~~~~~~~~~~~~~~~~~~~~~~~",
                       "~~~~~~~~~~~~~~~~~~~~~~~~~~~~~~~~~~~~~~~~~",
                       "~~~~~~~~~~~~~~~~~~~~~~~~~~~~~~~~~~~~~~~~~")

                .aisle("~~~~~~~~~~~~~~~~~~~~~~~~~~~~~~~~~~~~~~~~~",
                       "~~~~~~~~~~~~~~~~~~~~~~~~~~~~~~~~~~~~~~~~~",
                       "~~~~~~~~~~~~~~~~~~~~~~~~~~~~~~~~~~~~~~~~~",
                       "~~~~~~~~~~~~~~~~~~~~~~~~~~~~~~~~~~~~~~~~~",
                       "~~~~~~~~~~~~~~~~~~~~~~~~~~~~~~~~~~~~~~~~~",
                       "~~~~~~~~~~~~~~~~~~~~~~~~~~~~~~~~~~~~~~~~~",
                       "~~~~~~~~~~~~~~~~~~~~~~~~~~~~~~~~~~~~~~~~~",
                       "~~~~~~~~~~~~~~~~~~~~~~~~~~~~~~~~~~~~~~~~~",
                       "~~~~~~~~~~~~~~~~~~~~~~~~~~~~~~~~~~~~~~~~~",
                       "~~~~~~~~~~~~~~~~~~~~~~~~~~~~~~~~~~~~~~~~~",
                       "~~~~~~~~~~~~~~~~~~~~~~~~~~~~~~~~~~~~~~~~~",
                       "~~~~~~~~~~~~~~~~~~~~~~~~~~~~~~~~~~~~~~~~~",
                       "~~~~~~~~~~~~~~~~~~~~~~~~~~~~~~~~~~~~~~~~~",
                       "~~~~~~~~~~~~~~~~~~~~~~~~~~~~~~~~~~~~~~~~~",
                       "~~~~~~~~~~~~~~~~~~~~~~~~~~~~~~~~~~~~~~~~~",
                       "~~~~~~~~~~~~~~~~~~~~~~~~~~~~~~~~~~~~~~~~~",
                       "~~~~~~~~~~~~~~~~~~~~~~~~~~~~~~~~~~~~~~~~~",
                       "~~~~~~~~~~~~~~~~~~~~~~~~~~~~~~~~~~~~~~~~~",
                       "~~~~~~~~~~~~~~~~~~~~~~~~~~~~~~~~~~~~~~~~~",
                       "~~~~~~~~~~~~~~~~~~~SDS~~~~~~~~~~~~~~~~~~~",
                       "~~~~~~~~~~~~~~~~~~~DSD~~~~~~~~~~~~~~~~~~~",
                       "~~~~~~~~~~~~~~~~~~~SDS~~~~~~~~~~~~~~~~~~~",
                       "~~~~~~~~~~~~~~~~~~~~~~~~~~~~~~~~~~~~~~~~~",
                       "~~~~~~~~~~~~~~~~~~~~~~~~~~~~~~~~~~~~~~~~~",
                       "~~~~~~~~~~~~~~~~~~~~~~~~~~~~~~~~~~~~~~~~~",
                       "~~~~~~~~~~~~~~~~~~~~~~~~~~~~~~~~~~~~~~~~~",
                       "~~~~~~~~~~~~~~~~~~~~~~~~~~~~~~~~~~~~~~~~~",
                       "~~~~~~~~~~~~~~~~~~~~~~~~~~~~~~~~~~~~~~~~~",
                       "~~~~~~~~~~~~~~~~~~~~~~~~~~~~~~~~~~~~~~~~~",
                       "~~~~~~~~~~~~~~~~~~~~~~~~~~~~~~~~~~~~~~~~~",
                       "~~~~~~~~~~~~~~~~~~~~~~~~~~~~~~~~~~~~~~~~~",
                       "~~~~~~~~~~~~~~~~~~~~~~~~~~~~~~~~~~~~~~~~~",
                       "~~~~~~~~~~~~~~~~~~~~~~~~~~~~~~~~~~~~~~~~~",
                       "~~~~~~~~~~~~~~~~~~~~~~~~~~~~~~~~~~~~~~~~~",
                       "~~~~~~~~~~~~~~~~~~~~~~~~~~~~~~~~~~~~~~~~~",
                       "~~~~~~~~~~~~~~~~~~~~~~~~~~~~~~~~~~~~~~~~~",
                       "~~~~~~~~~~~~~~~~~~~~~~~~~~~~~~~~~~~~~~~~~",
                       "~~~~~~~~~~~~~~~~~~~~~~~~~~~~~~~~~~~~~~~~~",
                       "~~~~~~~~~~~~~~~~~~~~~~~~~~~~~~~~~~~~~~~~~",
                       "~~~~~~~~~~~~~~~~~~~~~~~~~~~~~~~~~~~~~~~~~",
                       "~~~~~~~~~~~~~~~~~~~~~~~~~~~~~~~~~~~~~~~~~")

                .aisle("~~~~~~~~~~~~~~~~~~~~~~~~~~~~~~~~~~~~~~~~~",
                       "~~~~~~~~~~~~~~~~~~~~~~~~~~~~~~~~~~~~~~~~~",
                       "~~~~~~~~~~~~~~~~~~~~~~~~~~~~~~~~~~~~~~~~~",
                       "~~~~~~~~~~~~~~~~~~~~~~~~~~~~~~~~~~~~~~~~~",
                       "~~~~~~~~~~~~~~~~~~~~~~~~~~~~~~~~~~~~~~~~~",
                       "~~~~~~~~~~~~~~~~~~~~~~~~~~~~~~~~~~~~~~~~~",
                       "~~~~~~~~~~~~~~~~~~~~~~~~~~~~~~~~~~~~~~~~~",
                       "~~~~~~~~~~~~~~~~~~~~~~~~~~~~~~~~~~~~~~~~~",
                       "~~~~~~~~~~~~~~~~~~~~~~~~~~~~~~~~~~~~~~~~~",
                       "~~~~~~~~~~~~~~~~~~~~~~~~~~~~~~~~~~~~~~~~~",
                       "~~~~~~~~~~~~~~~~~~~~~~~~~~~~~~~~~~~~~~~~~",
                       "~~~~~~~~~~~~~~~~~~~~~~~~~~~~~~~~~~~~~~~~~",
                       "~~~~~~~~~~~~~~~~~~~~~~~~~~~~~~~~~~~~~~~~~",
                       "~~~~~~~~~~~~~~~~~~~~~~~~~~~~~~~~~~~~~~~~~",
                       "~~~~~~~~~~~~~~~~~~~~~~~~~~~~~~~~~~~~~~~~~",
                       "~~~~~~~~~~~~~~~~~~~~~~~~~~~~~~~~~~~~~~~~~",
                       "~~~~~~~~~~~~~~~~~~~~~~~~~~~~~~~~~~~~~~~~~",
                       "~~~~~~~~~~~~~~~~~~~~~~~~~~~~~~~~~~~~~~~~~",
                       "~~~~~~~~~~~~~~~~~~~~~~~~~~~~~~~~~~~~~~~~~",
                       "~~~~~~~~~~~~~~~~~~~SDS~~~~~~~~~~~~~~~~~~~",
                       "~~~~~~~~~~~~~~~~~~~DSD~~~~~~~~~~~~~~~~~~~",
                       "~~~~~~~~~~~~~~~~~~~SDS~~~~~~~~~~~~~~~~~~~",
                       "~~~~~~~~~~~~~~~~~~~~~~~~~~~~~~~~~~~~~~~~~",
                       "~~~~~~~~~~~~~~~~~~~~~~~~~~~~~~~~~~~~~~~~~",
                       "~~~~~~~~~~~~~~~~~~~~~~~~~~~~~~~~~~~~~~~~~",
                       "~~~~~~~~~~~~~~~~~~~~~~~~~~~~~~~~~~~~~~~~~",
                       "~~~~~~~~~~~~~~~~~~~~~~~~~~~~~~~~~~~~~~~~~",
                       "~~~~~~~~~~~~~~~~~~~~~~~~~~~~~~~~~~~~~~~~~",
                       "~~~~~~~~~~~~~~~~~~~~~~~~~~~~~~~~~~~~~~~~~",
                       "~~~~~~~~~~~~~~~~~~~~~~~~~~~~~~~~~~~~~~~~~",
                       "~~~~~~~~~~~~~~~~~~~~~~~~~~~~~~~~~~~~~~~~~",
                       "~~~~~~~~~~~~~~~~~~~~~~~~~~~~~~~~~~~~~~~~~",
                       "~~~~~~~~~~~~~~~~~~~~~~~~~~~~~~~~~~~~~~~~~",
                       "~~~~~~~~~~~~~~~~~~~~~~~~~~~~~~~~~~~~~~~~~",
                       "~~~~~~~~~~~~~~~~~~~~~~~~~~~~~~~~~~~~~~~~~",
                       "~~~~~~~~~~~~~~~~~~~~~~~~~~~~~~~~~~~~~~~~~",
                       "~~~~~~~~~~~~~~~~~~~~~~~~~~~~~~~~~~~~~~~~~",
                       "~~~~~~~~~~~~~~~~~~~~~~~~~~~~~~~~~~~~~~~~~",
                       "~~~~~~~~~~~~~~~~~~~~~~~~~~~~~~~~~~~~~~~~~",
                       "~~~~~~~~~~~~~~~~~~~~~~~~~~~~~~~~~~~~~~~~~",
                       "~~~~~~~~~~~~~~~~~~~~~~~~~~~~~~~~~~~~~~~~~")

                .aisle("~~~~~~~~~~~~~~~~~~~~~~~~~~~~~~~~~~~~~~~~~",
                       "~~~~~~~~~~~~~~~~~~~~~~~~~~~~~~~~~~~~~~~~~",
                       "~~~~~~~~~~~~~~~~~~~~~~~~~~~~~~~~~~~~~~~~~",
                       "~~~~~~~~~~~~~~~~~~~~~~~~~~~~~~~~~~~~~~~~~",
                       "~~~~~~~~~~~~~~~~~~~~~~~~~~~~~~~~~~~~~~~~~",
                       "~~~~~~~~~~~~~~~~~~~~~~~~~~~~~~~~~~~~~~~~~",
                       "~~~~~~~~~~~~~~~~~~~~~~~~~~~~~~~~~~~~~~~~~",
                       "~~~~~~~~~~~~~~~~~~~~~~~~~~~~~~~~~~~~~~~~~",
                       "~~~~~~~~~~~~~~~~~~~~~~~~~~~~~~~~~~~~~~~~~",
                       "~~~~~~~~~~~~~~~~~~~~~~~~~~~~~~~~~~~~~~~~~",
                       "~~~~~~~~~~~~~~~~~~~~~~~~~~~~~~~~~~~~~~~~~",
                       "~~~~~~~~~~~~~~~~~~~~~~~~~~~~~~~~~~~~~~~~~",
                       "~~~~~~~~~~~~~~~~~~~~~~~~~~~~~~~~~~~~~~~~~",
                       "~~~~~~~~~~~~~~~~~~~~~~~~~~~~~~~~~~~~~~~~~",
                       "~~~~~~~~~~~~~~~~~~~~~~~~~~~~~~~~~~~~~~~~~",
                       "~~~~~~~~~~~~~~~~~~~~~~~~~~~~~~~~~~~~~~~~~",
                       "~~~~~~~~~~~~~~~~~~~~~~~~~~~~~~~~~~~~~~~~~",
                       "~~~~~~~~~~~~~~~~~~~~~~~~~~~~~~~~~~~~~~~~~",
                       "~~~~~~~~~~~~~~~~~~~~~~~~~~~~~~~~~~~~~~~~~",
                       "~~~~~~~~~~~~~~~~~~~SDS~~~~~~~~~~~~~~~~~~~",
                       "~~~~~~~~~~~~~~~~~~~DSD~~~~~~~~~~~~~~~~~~~",
                       "~~~~~~~~~~~~~~~~~~~SDS~~~~~~~~~~~~~~~~~~~",
                       "~~~~~~~~~~~~~~~~~~~~~~~~~~~~~~~~~~~~~~~~~",
                       "~~~~~~~~~~~~~~~~~~~~~~~~~~~~~~~~~~~~~~~~~",
                       "~~~~~~~~~~~~~~~~~~~~~~~~~~~~~~~~~~~~~~~~~",
                       "~~~~~~~~~~~~~~~~~~~~~~~~~~~~~~~~~~~~~~~~~",
                       "~~~~~~~~~~~~~~~~~~~~~~~~~~~~~~~~~~~~~~~~~",
                       "~~~~~~~~~~~~~~~~~~~~~~~~~~~~~~~~~~~~~~~~~",
                       "~~~~~~~~~~~~~~~~~~~~~~~~~~~~~~~~~~~~~~~~~",
                       "~~~~~~~~~~~~~~~~~~~~~~~~~~~~~~~~~~~~~~~~~",
                       "~~~~~~~~~~~~~~~~~~~~~~~~~~~~~~~~~~~~~~~~~",
                       "~~~~~~~~~~~~~~~~~~~~~~~~~~~~~~~~~~~~~~~~~",
                       "~~~~~~~~~~~~~~~~~~~~~~~~~~~~~~~~~~~~~~~~~",
                       "~~~~~~~~~~~~~~~~~~~~~~~~~~~~~~~~~~~~~~~~~",
                       "~~~~~~~~~~~~~~~~~~~~~~~~~~~~~~~~~~~~~~~~~",
                       "~~~~~~~~~~~~~~~~~~~~~~~~~~~~~~~~~~~~~~~~~",
                       "~~~~~~~~~~~~~~~~~~~~~~~~~~~~~~~~~~~~~~~~~",
                       "~~~~~~~~~~~~~~~~~~~~~~~~~~~~~~~~~~~~~~~~~",
                       "~~~~~~~~~~~~~~~~~~~~~~~~~~~~~~~~~~~~~~~~~",
                       "~~~~~~~~~~~~~~~~~~~~~~~~~~~~~~~~~~~~~~~~~",
                       "~~~~~~~~~~~~~~~~~~~~~~~~~~~~~~~~~~~~~~~~~")

                .aisle("~~~~~~~~~~~~~~~~~~~~~~~~~~~~~~~~~~~~~~~~~",
                       "~~~~~~~~~~~~~~~~~~~~~~~~~~~~~~~~~~~~~~~~~",
                       "~~~~~~~~~~~~~~~~~~~~~~~~~~~~~~~~~~~~~~~~~",
                       "~~~~~~~~~~~~~~~~~~~~~~~~~~~~~~~~~~~~~~~~~",
                       "~~~~~~~~~~~~~~~~~~~~~~~~~~~~~~~~~~~~~~~~~",
                       "~~~~~~~~~~~~~~~~~~~~~~~~~~~~~~~~~~~~~~~~~",
                       "~~~~~~~~~~~~~~~~~~~~~~~~~~~~~~~~~~~~~~~~~",
                       "~~~~~~~~~~~~~~~~~~~~~~~~~~~~~~~~~~~~~~~~~",
                       "~~~~~~~~~~~~~~~~~~~~~~~~~~~~~~~~~~~~~~~~~",
                       "~~~~~~~~~~~~~~~~~~~~~~~~~~~~~~~~~~~~~~~~~",
                       "~~~~~~~~~~~~~~~~~~~~~~~~~~~~~~~~~~~~~~~~~",
                       "~~~~~~~~~~~~~~~~~~~~~~~~~~~~~~~~~~~~~~~~~",
                       "~~~~~~~~~~~~~~~~~~~~~~~~~~~~~~~~~~~~~~~~~",
                       "~~~~~~~~~~~~~~~~~~~~~~~~~~~~~~~~~~~~~~~~~",
                       "~~~~~~~~~~~~~~~~~~~~~~~~~~~~~~~~~~~~~~~~~",
                       "~~~~~~~~~~~~~~~~~~~~~~~~~~~~~~~~~~~~~~~~~",
                       "~~~~~~~~~~~~~~~~~~~~~~~~~~~~~~~~~~~~~~~~~",
                       "~~~~~~~~~~~~~~~~~~~~~~~~~~~~~~~~~~~~~~~~~",
                       "~~~~~~~~~~~~~~~~~~~~~~~~~~~~~~~~~~~~~~~~~",
                       "~~~~~~~~~~~~~~~~~~~SDS~~~~~~~~~~~~~~~~~~~",
                       "~~~~~~~~~~~~~~~~~~~DSD~~~~~~~~~~~~~~~~~~~",
                       "~~~~~~~~~~~~~~~~~~~SDS~~~~~~~~~~~~~~~~~~~",
                       "~~~~~~~~~~~~~~~~~~~~~~~~~~~~~~~~~~~~~~~~~",
                       "~~~~~~~~~~~~~~~~~~~~~~~~~~~~~~~~~~~~~~~~~",
                       "~~~~~~~~~~~~~~~~~~~~~~~~~~~~~~~~~~~~~~~~~",
                       "~~~~~~~~~~~~~~~~~~~~~~~~~~~~~~~~~~~~~~~~~",
                       "~~~~~~~~~~~~~~~~~~~~~~~~~~~~~~~~~~~~~~~~~",
                       "~~~~~~~~~~~~~~~~~~~~~~~~~~~~~~~~~~~~~~~~~",
                       "~~~~~~~~~~~~~~~~~~~~~~~~~~~~~~~~~~~~~~~~~",
                       "~~~~~~~~~~~~~~~~~~~~~~~~~~~~~~~~~~~~~~~~~",
                       "~~~~~~~~~~~~~~~~~~~~~~~~~~~~~~~~~~~~~~~~~",
                       "~~~~~~~~~~~~~~~~~~~~~~~~~~~~~~~~~~~~~~~~~",
                       "~~~~~~~~~~~~~~~~~~~~~~~~~~~~~~~~~~~~~~~~~",
                       "~~~~~~~~~~~~~~~~~~~~~~~~~~~~~~~~~~~~~~~~~",
                       "~~~~~~~~~~~~~~~~~~~~~~~~~~~~~~~~~~~~~~~~~",
                       "~~~~~~~~~~~~~~~~~~~~~~~~~~~~~~~~~~~~~~~~~",
                       "~~~~~~~~~~~~~~~~~~~~~~~~~~~~~~~~~~~~~~~~~",
                       "~~~~~~~~~~~~~~~~~~~~~~~~~~~~~~~~~~~~~~~~~",
                       "~~~~~~~~~~~~~~~~~~~~~~~~~~~~~~~~~~~~~~~~~",
                       "~~~~~~~~~~~~~~~~~~~~~~~~~~~~~~~~~~~~~~~~~",
                       "~~~~~~~~~~~~~~~~~~~~~~~~~~~~~~~~~~~~~~~~~")

                .aisle("~~~~~~~~~~~~~~~~~~~~~~~~~~~~~~~~~~~~~~~~~",
                       "~~~~~~~~~~~~~~~~~~~~~~~~~~~~~~~~~~~~~~~~~",
                       "~~~~~~~~~~~~~~~~~~~~~~~~~~~~~~~~~~~~~~~~~",
                       "~~~~~~~~~~~~~~~~~~~~~~~~~~~~~~~~~~~~~~~~~",
                       "~~~~~~~~~~~~~~~~~~~~~~~~~~~~~~~~~~~~~~~~~",
                       "~~~~~~~~~~~~~~~~~~~~~~~~~~~~~~~~~~~~~~~~~",
                       "~~~~~~~~~~~~~~~~~~~~~~~~~~~~~~~~~~~~~~~~~",
                       "~~~~~~~~~~~~~~~~~~~~~~~~~~~~~~~~~~~~~~~~~",
                       "~~~~~~~~~~~~~~~~~~~~~~~~~~~~~~~~~~~~~~~~~",
                       "~~~~~~~~~~~~~~~~~~~~~~~~~~~~~~~~~~~~~~~~~",
                       "~~~~~~~~~~~~~~~~~~~~~~~~~~~~~~~~~~~~~~~~~",
                       "~~~~~~~~~~~~~~~~~~~~~~~~~~~~~~~~~~~~~~~~~",
                       "~~~~~~~~~~~~~~~~~~~~~~~~~~~~~~~~~~~~~~~~~",
                       "~~~~~~~~~~~~~~~~~~~~~~~~~~~~~~~~~~~~~~~~~",
                       "~~~~~~~~~~~~~~~~~~~~~~~~~~~~~~~~~~~~~~~~~",
                       "~~~~~~~~~~~~~~~~~~~~~~~~~~~~~~~~~~~~~~~~~",
